Workbook
Name Gift: Skatteberegning!$G$8
Name Skatteordning: #REF!
Name TABLE: Skatteberegning!$C$2:$C$2
Name TABLE_10: Skatteberegning!$C$35:$C$35
Name TABLE_11: Skatteberegning!$C$36:$C$36
Name TABLE_12: Skatteberegning!#REF!
Name TABLE_13: Skatteberegning!$C$38:$C$38
Name TABLE_14: Skatteberegning!$C$40:$C$40
Name TABLE_15: Skatteberegning!#REF!
Name TABLE_16: Skatteberegning!$C$41:$C$41
Name TABLE_17: Skatteberegning!$C$42:$C$42
Name TABLE_18: Skatteberegning!$C$43:$C$43
Name TABLE_19: Skatteberegning!$C$44:$C$44
Name TABLE_2: Skatteberegning!$C$8:$C$8
Name TABLE_20: Skatteberegning!$C$47:$C$47
Name TABLE_21: Skatteberegning!$C$48:$C$48
Name TABLE_22: Skatteberegning!$C$49:$C$49
Name TABLE_23: Skatteberegning!$C$50:$C$50
Name TABLE_24: Skatteberegning!$C$51:$C$51
Name TABLE_25: Skatteberegning!$C$52:$C$52
Name TABLE_26: Skatteberegning!$C$53:$C$53
Name TABLE_27: Skatteberegning!$C$54:$C$54
Name TABLE_28: Skatteberegning!$C$57:$C$57
Name TABLE_29: Skatteberegning!$C$58:$C$58
Name TABLE_3: Skatteberegning!$C$9:$C$9
Name TABLE_30: Skatteberegning!$C$60:$C$60
Name TABLE_31: Skatteberegning!$C$61:$C$61
Name TABLE_32: Skatteberegning!$C$62:$C$62
Name TABLE_33: Skatteberegning!$C$63:$C$63
Name TABLE_34: Skatteberegning!$C$67:$C$67
Name TABLE_35: Skatteberegning!$C$68:$C$68
Name TABLE_36: Skatteberegning!$C$69:$C$69
Name TABLE_37: Skatteberegning!$C$70:$C$70
Name TABLE_38: Skatteberegning!$C$73:$C$73
Name TABLE_39: Skatteberegning!$C$74:$C$74
Name TABLE_4: Skatteberegning!$C$11:$C$11
Name TABLE_40: Skatteberegning!$C$76:$C$76
Name TABLE_41: Skatteberegning!$C$77:$C$77
Name TABLE_42: Skatteberegning!$C$81:$C$81
Name TABLE_43: Skatteberegning!#REF!
Name TABLE_44: Skatteberegning!#REF!
Name TABLE_45: Skatteberegning!$C$82:$C$82
Name TABLE_46: Skatteberegning!$C$83:$C$83
Name TABLE_47: Skatteberegning!$C$85:$C$85
Name TABLE_48: Skatteberegning!$C$86:$C$86
Name TABLE_49: Skatteberegning!$C$87:$C$87
Name TABLE_5: Skatteberegning!$C$13:$C$13
Name TABLE_50: Skatteberegning!$C$88:$C$88
Name TABLE_51: Skatteberegning!$C$89:$C$89
Name TABLE_52: Skatteberegning!$C$90:$C$90
Name TABLE_53: Skatteberegning!#REF!
Name TABLE_54: Skatteberegning!#REF!
Name TABLE_55: Skatteberegning!#REF!
Name TABLE_56: Skatteberegning!$C$102:$C$102
Name TABLE_57: Skatteberegning!$C$103:$C$103
Name TABLE_58: Skatteberegning!$C$109:$C$109
Name TABLE_59: Skatteberegning!$C$110:$C$110
Name TABLE_6: Skatteberegning!$C$18:$C$18
Name TABLE_60: Skatteberegning!$C$112:$C$112
Name TABLE_61: Skatteberegning!$C$122:$C$122

Sheet Budget
A1: Indkomst m.m.
A2: Løn, brutto/år | B2: =12*(35000+45000) -> 960000
A3: Skat/år | B3: =Skatteberegning!E151 -> 325146.59
A4: Børneydelse/år | B4: =12*1064 -> 12768
A5: Disponibel indkomst/måned | B5: =(B2-B3+B4)/12 -> 53968.451
A7: Faste udgifter
A8: Realkreditlån | B8: =SUM(Realkredit!H47:H50)/12 -> 11072.353
A9: Ejerudgifter (villa) | B9: 5250
A10: El, vand og varme (villa) | B10: 2500
A11: Vedligeholdelse af ejendom | B11: 4000
A12: Fagforening og a-kasse (Marianne) | B12: 1100
A13: Forsikringer (indbo, biler) | B13: 1000
A14: Billån (VW Touran) | B14: =Billån!B8 -> 1971.2145
A15: Brændstof og øvrige biludgifter | B15: 2500
A16: Sport og fritid | B16: 1000
A17: Telefon/internet/streaming | B17: 800
A20: Rådighedsbeløb/måned | B20: =B5-(SUM(B8:B19)) -> 22774.883

Sheet Skatteberegning
C1: 45291 | I1: Kommuneskatteprocenter | O1: Satser | R1: TRUE | S1: ja
C2: Skatteberegning 2024 | R2: FALSE | S2: nej
C3: Regnearket implementerer hovedreglerne i indkomstbeskatningen. Brug af dette regneark sker på eget ansvar. Der ydes ikke erstatning, såfremt brugen af regnearket giver anledning til, at der lides et tab. | I3: 2024 | O3: 2024
I4: Kommune | J4: Skatte | K4: Kirke | L4: Nedslag | M4: Grundskyld | O4: Arbejdsmarkedsbidragsprocent AMB § 1 | P4: 8
J5: pct. | K5: pct. | L5: pct. | M5: prm. | O5: Bundskatprocent PSL § 6, stk. 2 | P5: 12.06
C6: 1. Forskellige oplysninger | O6: Sundhedsbidragsprocent PSL § 8 | P6: 0
E7: Herbert | F7: Marianne | I7: intet sommerhus | M7: 0 | O7: Topskatprocent PSL § 7, stk. 1 | P7: 15
C8: Gift ? | E8: ja | G8: =IF(E8=S1,TRUE,FALSE) -> TRUE | I8: Albertslund | J8: 25.6 | K8: 0.8 | L8: 0.59 | M8: 9.1 | O8: Topskatgrænse PSL § 7, stk. 2 | P8: 588900
C9: Under 18 år hele indkomståret ? | E9: nej | F9: nej | I9: Allerød | J9: 25.3 | K9: 0.58 | L9: 0.29 | M9: 8 | O9: Skatteloftprocent PSL § 19, stk. 1 | P9: 52.07
C10: Mere end 15 år til folkepensionsalderen ? | E10: ja | F10: ja | I10: Assens | J10: 26.1 | K10: 0.98 | L10: 1.09 | M10: 11.2 | O10: Skatteloftprocent positiv nettokapitalindkomst PSL § 19, stk. 2 | P10: 42
C11: Medlem af Folkekirken ? | E11: nej | F11: nej | I11: Ballerup | J11: 25.5 | K11: 0.72 | L11: 0.49 | M11: 8.3 | O11: Personfradrag unge PSL § 10, stk. 2 | P11: 39800
I12: Billund | J12: 24 | K12: 0.89 | L12: 0 | M12: 7.2 | O12: Personfradrag PSL § 10, stk. 1 | P12: 49700
C13: Bopælskommune pr. 5. september 2023 | E13: Hillerød | I13: Bornholm | J13: 26.2 | K13: 0.93 | L13: 1.19 | M13: 10.7 | O13: Maksimalt kapitalpensionsfradrag PBL § 16, stk. 1 | P13: 0
C14: Kommuneskatteprocent | E14: =VLOOKUP(E13,I8:M105,2,FALSE) -> 25.6 | I14: Brøndby | J14: 24.3 | K14: 0.8 | L14: 0 | M14: 4.9 | O14: Bundfradrag positiv nettokapitalindkomst PSL § 7, stk. 1 | P14: 50500
C15: Kirkeskatteprocent | E15: =VLOOKUP(E13,I8:M105,3,FALSE) -> 0.69 | I15: Brønderslev | J15: 26.3 | K15: 1.08 | L15: 1.29 | M15: 17.1 | O15: Aktieskatprocent under grænse PSL § 8 a, stk. 1 | P15: 27
C16: Grundskyldspromille | E16: =VLOOKUP(E13,I7:M105,5,FALSE) -> 6.6 | I16: Dragør | J16: 24.8 | K16: 0.61 | L16: 0 | M16: 8.1 | O16: Aktieskatprocent over grænse PSL § 8 a, stk. 2 | P16: 42
I17: Egedal | J17: 25.7 | K17: 0.76 | L17: 0.69 | M17: 8.8 | O17: Grænse aktieskat PSL § 8 a, stk. 1 og 2 | P17: 61000
C18: Ejendomsværdi af enfamiliehus | I18: Esbjerg | J18: 25.8 | K18: 0.81 | L18: 0.79 | M18: 9.9 | O18: Bundgrænse lønmodtagerfradrag LL § 9, stk. 1 | P18: 7000
C19: Ejendomsværdi af ejerlejlighed | I19: Faaborg-Midtfyn | J19: 26.1 | K19: 1.05 | L19: 1.09 | M19: 8.5 | O19: Beskæftigelsesfradragsprocent LL § 9 J, stk. 2 | P19: 10.65
C20: Hus/ejerlejlighed erhvervet senest 1. juli 1998 ? | E20: nej | I20: Fanø | J20: 25.77 | K20: 1.14 | L20: 0.76 | M20: 12.5 | O20: Maksimalt beskæftigelsesfradrag LL § 9 J, stk. 2 | P20: 45100
C21: Grundværdi hus/ejerlejlighed | I21: Favrskov | J21: 25.7 | K21: 0.96 | L21: 0.69 | M21: 10.6 | O21: Ejendomsværdiskatteprocent under grænse | P21: 0.51
C22: Ejendomsværdi af sommerhus | I22: Faxe | J22: 25.8 | K22: 1.08 | L22: 0.79 | M22: 8 | O22: Ejendomsværdiskatteprocent over grænse | P22: 1.4
C23: Beliggenhed sommerhus | E23: Albertslund | I23: Fredensborg | J23: 25.3 | K23: 0.62 | L23: 0.29 | M23: 8.3 | O23: Grænse ejendomsværdiskat | P23: 9200000
C24: Grundskyldspromille | E24: =VLOOKUP(E23,I7:M105,5,FALSE) -> 9.1 | I24: Fredericia | J24: 25.5 | K24: 0.88 | L24: 0.49 | M24: 13 | O24: Nedslag ejendomsværdiskat ESL § 23, stk. 1 | P24: 0.1
C25: Grundværdi sommerhus | I25: Frederiksberg | J25: 24.57 | K25: 0.5 | L25: 0 | M25: 3.1 | O25: Nedslag ejendomsværdiskat ESL § 24, stk. 1 | P25: 0.21
C26: Sommerhus erhvervet senest 1. juli 1998 ? | E26: nej | I26: Frederikshavn | J26: 26.2 | K26: 1.03 | L26: 1.19 | M26: 13.4 | O26: Maksimalt nedslag efter ESL § 24, stk. 1 | P26: 1200
C27: Bidrag og præmie til arbejdsgiveradministreret pension med løbende udbetalinger og ratepension | F27: =F32*0.12 -> 64800 | I27: Frederikssund | J27: 25.8 | K27: 0.96 | L27: 0.79 | M27: 12 | O27: Nedslagsprocent negativ nettokapitalindkomst, PSL § 11, stk. 2 | P27: 8
I28: Furesø | J28: 24.88 | K28: 0.65 | L28: 0 | M28: 7 | O28: Bundfradrag udligningsskat, PSL § 7 a, stk. 4 | P28: 457500
C29: 2. Indkomst og fradrag | I29: Gentofte | J29: 24.34 | K29: 0.4 | L29: 0 | M29: 5.1 | O29: Udligningsskatteprocent, PSL § 7 a, stk. 5 | P29: 0
E30: Skatteyder | F30: =IF(E8=S1,"Ægtefælle","ugift") -> Ægtefælle | I30: Gladsaxe | J30: 23.6 | K30: 0.75 | L30: 0 | M30: 5.9 | O30: Overførbart bundfradrag udligningsskat, PSL § 7 a, stk. 6 | P30: 152600
C31: Personlig indkomst | I31: Glostrup | J31: 24.6 | K31: 0.8 | L31: 0 | M31: 6.5 | O31: Bundgrænse jobfradrag LL § 9 K, stk. 1 | P31: 216100
C32: Løn, honorarer mv. (før fradrag af AMB) | E32: =12*35000 -> 420000 | F32: =12*45000 -> 540000 | I32: Greve | J32: 24.52 | K32: 0.73 | L32: 0 | M32: 5.5 | O32: Jobfradragsprocent LL § 9 K, stk. 2 | P32: 4.5
C33: - reduceres med Arbejdsmarkedsbidrag (AMB) | E33: =E32*P4/100 -> 33600 | F33: =F32*P4/100 -> 43200 | I33: Gribskov | J33: 25.4 | K33: 0.85 | L33: 0.39 | M33: 11.1 | O33: Maksimalt jobfradrag LL § 9 K, stk. 2 | P33: 2800
C34: Personlig indkomst fra selvstændig virksomhed | I34: Guldborgsund | J34: 25.8 | K34: 1.16 | L34: 0.79 | M34: 15.9 | O34: Maksimalt ekstra pensionsfradrag LL § 9 L | P34: 80600
C35: - reduceres med Arbejdsmarkedsbidrag (AMB) | E35: =MAX(0,E34*P4/100) -> 0 | I35: Haderslev | J35: 26.3 | K35: 0.95 | L35: 1.29 | M35: 12.7
C36: Dagpenge mv., SU og anden personlig indkomst, hvoraf der ikke skal betales AMB | I36: Halsnæs | J36: 25.7 | K36: 0.85 | L36: 0.69 | M36: 10.9
C37: Udbetalt pension mv., hvoraf der skal betales udligningsskat | I37: Hedensted | J37: 25.52 | K37: 0.98 | L37: 0.51 | M37: 7.9
C38: Bidrag og præmie til privattegnet pension med løbende udbetalinger og ratepension | I38: Helsingør | J38: 25.52 | K38: 0.63 | L38: 0.51 | M38: 9.5
I39: Herlev | J39: 23.7 | K39: 0.75 | L39: 0 | M39: 5.4
C40: Personlig indkomst i alt | E40: =E32-E33+E34-E35+E36+E37-E38 -> 386400 | F40: =F32-F33+F36+F37-F38 -> 496800 | I40: Herning | J40: 25.4 | K40: 0.99 | L40: 0.39 | M40: 9.9
...

Sheet Realkredit
B1: Beregning af ÅOP på annuitetslån:
B2: Lånets størrelse, Hovedstol | F2: 3000000
B3: Kurs (indtast også ved kurs 100) | F3: 100
B4: Evt. omk.ved låneoptagelse i kr
B5: Til udbetaling / nettoprovenuet | F5: =(F2*(F3/100))-F4 -> 3000000 | G5: Ved krav om bestemt låneprovenue - så vælg målsøgning og find hovedstolen
B6: Nominel rente pr. år i % | F6: 0.01
B7: Antal år (Lånets samlede løbetid) | F7: 30.25
B8: Terminer pr. år | F8: 4
B9: Antal afdragsfrie år
B10: Skattesats i % | F10: 0.256
B11: Antal terminer i alt | F11: =F7*F8 -> 121
B12: Antal afdragsfrie terminer | F12: =F9*F8 -> 0
B13: Nominel rente pr. termin | F13: =F6/F8 -> 0.0025
B14: Nominel rente pr. termin efter skat | F14: =F13*(1-F10) -> 0.00186
B15: Ydelse pr. termin (rentebetaling) | F15: =IF(F12<>0,-F2*F13,"") | G15: I den afdragsfrie periode
B16: Ydelse (rente og afdrag) før skat (uden gebyr) pr. termin | F16: =(PMT(F13,(F11-F12),F2)) -> -28762.907 | G16: Efter afdragsfri periode
B17: Gebyr pr. termin i %-del af restgælden | G17: Ikke fradragsberettiget
B18: Gebyr pr. termin i %-del af restgælden | F18: =0.68%/4 -> 0.0017 | G18: Fradragsberettiget
B19: Gebyr pr. termin i %-del af hovedstolen | D19: =IF(Skatteordning=2,0,IF(Skatteordning=3,C19,0)) -> #REF! | G19: Ikke fradragsberettiget
B20: Gebyr pr. termin i %-del af hovedstolen | G20: Fradragsberettiget
B22: Effektiv rente per termin | F22: =IRR(H30:H390,2%) -> 0.0042 | G22: Før skat
B23: ÅOP | F23: =((1+F22)^F8)-1 -> 0.016906137 | G23: Før skat
B24: Effektiv rente per termin | F24: =IRR(L30:L390,2%) -> 0.0031248 | G24: Efter skat
B25: ÅOP | F25: =((1+F24)^F8)-1 -> 0.012557908 | G25: Efter skat
B28: =CONCATENATE("Amortisationstabel annuitetslån: (",F11," terminer)") -> Amortisationstabel annuitetslån: (121 terminer)
B29: Termin | C29: Restgæld primo | D29: Rente før skat | E29: Afdrag | F29: Løbende gebyr før skat | G29: Ydelse før skat uden gebyr | H29: Ydelse før skat incl. gebyr | I29: Rente efter skat | J29: Løbende gebyr efter skat | K29: Ydelse efter skat uden gebyr | L29: Ydelse efter skat incl gebyr | M29: Restgæld ultimo | N29: Totalerne er i række 388
H30: =-F5 -> -3000000 | L30: =-F5 -> -3000000
A31: 1 | B31: =IF(A31<=$F$11,A31,"") -> 1 | C31: =IF(B31<=$F$11,F2,"") -> 3000000 | D31: =IF(B31<=$F$11,(C31*$F$13),"") -> 7500 | E31: =IF(B31<=$F$12,0,IF(B31<=$F$11,(-$F$16-D31),"")) -> 21262.907 | F31: =IF(B31<=$F$11,(($F$20*$F$2)+($F$19*$F$2)+(C31*$F$18)+($F$17*C31)),"") -> 5100 | G31: =IF(B31<=$F$11,(D31+E31),"") -> 28762.907 | H31: =IF(B31<=$F$11,(F31+G31),"") -> 33862.907 | I31: =IF(B31<=$F$11,D31*(1-$F$10),"") -> 5580 | J31: =IF(B31<=$F$11,(($F$20*$F$2*(1-$F$10))+($F$19*$F$2)+((C31*$F$18)*(1-$F$10))+(($F$17*C31))),"") -> 3794.4 | K31: =IF(B31<=$F$11,(E31+I31),"") -> 26842.907 | L31: =IF(B31<=$F$11,(J31+K31),"") -> 30637.307 | M31: =IF(B31<=$F$11,(C31-E31),IF(B31>$F$11,"",0)) -> 2978737.1
A32: =A31+1 -> 2 | B32: =IF(A32<=$F$11,A32,"") -> 2 | C32: =IF(M31=0,"",M31) -> 2978737.1 | D32: =IF(B32<=$F$11,(C32*$F$13),"") -> 7446.8427 | E32: =IF(B32<=$F$12,0,IF(B32<=$F$11,(-$F$16-D32),"")) -> 21316.064 | F32: =IF(B32<=$F$11,(($F$20*$F$2)+($F$19*$F$2)+(C32*$F$18)+($F$17*C32)),"") -> 5063.8531 | G32: =IF(B32<=$F$11,(D32+E32),"") -> 28762.907 | H32: =IF(B32<=$F$11,(F32+G32),"") -> 33826.76 | I32: =IF(B32<=$F$11,(C32*$F$13)*(1-$F$10),"") -> 5540.451 | J32: =IF(B32<=$F$11,(($F$20*$F$2*(1-$F$10))+($F$19*$F$2)+((C32*$F$18)*(1-$F$10))+(($F$17*C32))),"") -> 3767.5067 | K32: =IF(B32<=$F$11,(E32+I32),"") -> 26856.515 | L32: =IF(B32<=$F$11,(J32+K32),"") -> 30624.022 | M32: =IF(B32<=$F$11,(C32-E32),IF(B32>$F$11,"",0)) -> 2957421
A33: =A32+1 -> 3 | B33: =IF(A33<=$F$11,A33,"") -> 3 | C33: =IF(M32=0,"",M32) -> 2957421 | D33: =IF(B33<=$F$11,(C33*$F$13),"") -> 7393.5526 | E33: =IF(B33<=$F$12,0,IF(B33<=$F$11,(-$F$16-D33),"")) -> 21369.355 | F33: =IF(B33<=$F$11,(($F$20*$F$2)+($F$19*$F$2)+(C33*$F$18)+($F$17*C33)),"") -> 5027.6157 | G33: =IF(B33<=$F$11,(D33+E33),"") -> 28762.907 | H33: =IF(B33<=$F$11,(F33+G33),"") -> 33790.523 | I33: =IF(B33<=$F$11,(C33*$F$13)*(1-$F$10),"") -> 5500.8031 | J33: =IF(B33<=$F$11,(($F$20*$F$2*(1-$F$10))+($F$19*$F$2)+((C33*$F$18)*(1-$F$10))+(($F$17*C33))),"") -> 3740.5461 | K33: =IF(B33<=$F$11,(E33+I33),"") -> 26870.158 | L33: =IF(B33<=$F$11,(J33+K33),"") -> 30610.704 | M33: =IF(B33<=$F$11,(C33-E33),IF(B33>$F$11,"",0)) -> 2936051.7
A34: =A33+1 -> 4 | B34: =IF(A34<=$F$11,A34,"") -> 4 | C34: =IF(M33=0,"",M33) -> 2936051.7 | D34: =IF(B34<=$F$11,(C34*$F$13),"") -> 7340.1292 | E34: =IF(B34<=$F$12,0,IF(B34<=$F$11,(-$F$16-D34),"")) -> 21422.778 | F34: =IF(B34<=$F$11,(($F$20*$F$2)+($F$19*$F$2)+(C34*$F$18)+($F$17*C34)),"") -> 4991.2878 | G34: =IF(B34<=$F$11,(D34+E34),"") -> 28762.907 | H34: =IF(B34<=$F$11,(F34+G34),"") -> 33754.195 | I34: =IF(B34<=$F$11,(C34*$F$13)*(1-$F$10),"") -> 5461.0561 | J34: =IF(B34<=$F$11,(($F$20*$F$2*(1-$F$10))+($F$19*$F$2)+((C34*$F$18)*(1-$F$10))+(($F$17*C34))),"") -> 3713.5182 | K34: =IF(B34<=$F$11,(E34+I34),"") -> 26883.834 | L34: =IF(B34<=$F$11,(J34+K34),"") -> 30597.352 | M34: =IF(B34<=$F$11,(C34-E34),IF(B34>$F$11,"",0)) -> 2914628.9
A35: =A34+1 -> 5 | B35: =IF(A35<=$F$11,A35,"") -> 5 | C35: =IF(M34=0,"",M34) -> 2914628.9 | D35: =IF(B35<=$F$11,(C35*$F$13),"") -> 7286.5722 | E35: =IF(B35<=$F$12,0,IF(B35<=$F$11,(-$F$16-D35),"")) -> 21476.335 | F35: =IF(B35<=$F$11,(($F$20*$F$2)+($F$19*$F$2)+(C35*$F$18)+($F$17*C35)),"") -> 4954.8691 | G35: =IF(B35<=$F$11,(D35+E35),"") -> 28762.907 | H35: =IF(B35<=$F$11,(F35+G35),"") -> 33717.776 | I35: =IF(B35<=$F$11,(C35*$F$13)*(1-$F$10),"") -> 5421.2097 | J35: =IF(B35<=$F$11,(($F$20*$F$2*(1-$F$10))+($F$19*$F$2)+((C35*$F$18)*(1-$F$10))+(($F$17*C35))),"") -> 3686.4226 | K35: =IF(B35<=$F$11,(E35+I35),"") -> 26897.545 | L35: =IF(B35<=$F$11,(J35+K35),"") -> 30583.967 | M35: =IF(B35<=$F$11,(C35-E35),IF(B35>$F$11,"",0)) -> 2893152.6
A36: =A35+1 -> 6 | B36: =IF(A36<=$F$11,A36,"") -> 6 | C36: =IF(M35=0,"",M35) -> 2893152.6 | D36: =IF(B36<=$F$11,(C36*$F$13),"") -> 7232.8814 | E36: =IF(B36<=$F$12,0,IF(B36<=$F$11,(-$F$16-D36),"")) -> 21530.026 | F36: =IF(B36<=$F$11,(($F$20*$F$2)+($F$19*$F$2)+(C36*$F$18)+($F$17*C36)),"") -> 4918.3594 | G36: =IF(B36<=$F$11,(D36+E36),"") -> 28762.907 | H36: =IF(B36<=$F$11,(F36+G36),"") -> 33681.267 | I36: =IF(B36<=$F$11,(C36*$F$13)*(1-$F$10),"") -> 5381.2638 | J36: =IF(B36<=$F$11,(($F$20*$F$2*(1-$F$10))+($F$19*$F$2)+((C36*$F$18)*(1-$F$10))+(($F$17*C36))),"") -> 3659.2594 | K36: =IF(B36<=$F$11,(E36+I36),"") -> 26911.29 | L36: =IF(B36<=$F$11,(J36+K36),"") -> 30570.549 | M36: =IF(B36<=$F$11,(C36-E36),IF(B36>$F$11,"",0)) -> 2871622.5
A37: =A36+1 -> 7 | B37: =IF(A37<=$F$11,A37,"") -> 7 | C37: =IF(M36=0,"",M36) -> 2871622.5 | D37: =IF(B37<=$F$11,(C37*$F$13),"") -> 7179.0563 | E37: =IF(B37<=$F$12,0,IF(B37<=$F$11,(-$F$16-D37),"")) -> 21583.851 | F37: =IF(B37<=$F$11,(($F$20*$F$2)+($F$19*$F$2)+(C37*$F$18)+($F$17*C37)),"") -> 4881.7583 | G37: =IF(B37<=$F$11,(D37+E37),"") -> 28762.907 | H37: =IF(B37<=$F$11,(F37+G37),"") -> 33644.666 | I37: =IF(B37<=$F$11,(C37*$F$13)*(1-$F$10),"") -> 5341.2179 | J37: =IF(B37<=$F$11,(($F$20*$F$2*(1-$F$10))+($F$19*$F$2)+((C37*$F$18)*(1-$F$10))+(($F$17*C37))),"") -> 3632.0282 | K37: =IF(B37<=$F$11,(E37+I37),"") -> 26925.069 | L37: =IF(B37<=$F$11,(J37+K37),"") -> 30557.097 | M37: =IF(B37<=$F$11,(C37-E37),IF(B37>$F$11,"",0)) -> 2850038.7
A38: =A37+1 -> 8 | B38: =IF(A38<=$F$11,A38,"") -> 8 | C38: =IF(M37=0,"",M37) -> 2850038.7 | D38: =IF(B38<=$F$11,(C38*$F$13),"") -> 7125.0967 | E38: =IF(B38<=$F$12,0,IF(B38<=$F$11,(-$F$16-D38),"")) -> 21637.81 | F38: =IF(B38<=$F$11,(($F$20*$F$2)+($F$19*$F$2)+(C38*$F$18)+($F$17*C38)),"") -> 4845.0658 | G38: =IF(B38<=$F$11,(D38+E38),"") -> 28762.907 | H38: =IF(B38<=$F$11,(F38+G38),"") -> 33607.973 | I38: =IF(B38<=$F$11,(C38*$F$13)*(1-$F$10),"") -> 5301.072 | J38: =IF(B38<=$F$11,(($F$20*$F$2*(1-$F$10))+($F$19*$F$2)+((C38*$F$18)*(1-$F$10))+(($F$17*C38))),"") -> 3604.7289 | K38: =IF(B38<=$F$11,(E38+I38),"") -> 26938.882 | L38: =IF(B38<=$F$11,(J38+K38),"") -> 30543.611 | M38: =IF(B38<=$F$11,(C38-E38),IF(B38>$F$11,"",0)) -> 2828400.9
A39: =A38+1 -> 9 | B39: =IF(A39<=$F$11,A39,"") -> 9 | C39: =IF(M38=0,"",M38) -> 2828400.9 | D39: =IF(B39<=$F$11,(C39*$F$13),"") -> 7071.0022 | E39: =IF(B39<=$F$12,0,IF(B39<=$F$11,(-$F$16-D39),"")) -> 21691.905 | F39: =IF(B39<=$F$11,(($F$20*$F$2)+($F$19*$F$2)+(C39*$F$18)+($F$17*C39)),"") -> 4808.2815 | G39: =IF(B39<=$F$11,(D39+E39),"") -> 28762.907 | H39: =IF(B39<=$F$11,(F39+G39),"") -> 33571.189 | I39: =IF(B39<=$F$11,(C39*$F$13)*(1-$F$10),"") -> 5260.8256 | J39: =IF(B39<=$F$11,(($F$20*$F$2*(1-$F$10))+($F$19*$F$2)+((C39*$F$18)*(1-$F$10))+(($F$17*C39))),"") -> 3577.3614 | K39: =IF(B39<=$F$11,(E39+I39),"") -> 26952.731 | L39: =IF(B39<=$F$11,(J39+K39),"") -> 30530.092 | M39: =IF(B39<=$F$11,(C39-E39),IF(B39>$F$11,"",0)) -> 2806709
A40: =A39+1 -> 10 | B40: =IF(A40<=$F$11,A40,"") -> 10 | C40: =IF(M39=0,"",M39) -> 2806709 | D40: =IF(B40<=$F$11,(C40*$F$13),"") -> 7016.7724 | E40: =IF(B40<=$F$12,0,IF(B40<=$F$11,(-$F$16-D40),"")) -> 21746.135 | F40: =IF(B40<=$F$11,(($F$20*$F$2)+($F$19*$F$2)+(C40*$F$18)+($F$17*C40)),"") -> 4771.4052 | G40: =IF(B40<=$F$11,(D40+E40),"") -> 28762.907 | H40: =IF(B40<=$F$11,(F40+G40),"") -> 33534.312 | I40: =IF(B40<=$F$11,(C40*$F$13)*(1-$F$10),"") -> 5220.4787 | J40: =IF(B40<=$F$11,(($F$20*$F$2*(1-$F$10))+($F$19*$F$2)+((C40*$F$18)*(1-$F$10))+(($F$17*C40))),"") -> 3549.9255 | K40: =IF(B40<=$F$11,(E40+I40),"") -> 26966.613 | L40: =IF(B40<=$F$11,(J40+K40),"") -> 30516.539 | M40: =IF(B40<=$F$11,(C40-E40),IF(B40>$F$11,"",0)) -> 2784962.8
A41: =A40+1 -> 11 | B41: =IF(A41<=$F$11,A41,"") -> 11 | C41: =IF(M40=0,"",M40) -> 2784962.8 | D41: =IF(B41<=$F$11,(C41*$F$13),"") -> 6962.4071 | E41: =IF(B41<=$F$12,0,IF(B41<=$F$11,(-$F$16-D41),"")) -> 21800.5 | F41: =IF(B41<=$F$11,(($F$20*$F$2)+($F$19*$F$2)+(C41*$F$18)+($F$17*C41)),"") -> 4734.4368 | G41: =IF(B41<=$F$11,(D41+E41),"") -> 28762.907 | H41: =IF(B41<=$F$11,(F41+G41),"") -> 33497.344 | I41: =IF(B41<=$F$11,(C41*$F$13)*(1-$F$10),"") -> 5180.0309 | J41: =IF(B41<=$F$11,(($F$20*$F$2*(1-$F$10))+($F$19*$F$2)+((C41*$F$18)*(1-$F$10))+(($F$17*C41))),"") -> 3522.421 | K41: =IF(B41<=$F$11,(E41+I41),"") -> 26980.531 | L41: =IF(B41<=$F$11,(J41+K41),"") -> 30502.952 | M41: =IF(B41<=$F$11,(C41-E41),IF(B41>$F$11,"",0)) -> 2763162.3
A42: =A41+1 -> 12 | B42: =IF(A42<=$F$11,A42,"") -> 12 | C42: =IF(M41=0,"",M41) -> 2763162.3 | D42: =IF(B42<=$F$11,(C42*$F$13),"") -> 6907.9058 | E42: =IF(B42<=$F$12,0,IF(B42<=$F$11,(-$F$16-D42),"")) -> 21855.001 | F42: =IF(B42<=$F$11,(($F$20*$F$2)+($F$19*$F$2)+(C42*$F$18)+($F$17*C42)),"") -> 4697.376 | G42: =IF(B42<=$F$11,(D42+E42),"") -> 28762.907 | H42: =IF(B42<=$F$11,(F42+G42),"") -> 33460.283 | I42: =IF(B42<=$F$11,(C42*$F$13)*(1-$F$10),"") -> 5139.4819 | J42: =IF(B42<=$F$11,(($F$20*$F$2*(1-$F$10))+($F$19*$F$2)+((C42*$F$18)*(1-$F$10))+(($F$17*C42))),"") -> 3494.8477 | K42: =IF(B42<=$F$11,(E42+I42),"") -> 26994.483 | L42: =IF(B42<=$F$11,(J42+K42),"") -> 30489.331 | M42: =IF(B42<=$F$11,(C42-E42),IF(B42>$F$11,"",0)) -> 2741307.3
A43: =A42+1 -> 13 | B43: =IF(A43<=$F$11,A43,"") -> 13 | C43: =IF(M42=0,"",M42) -> 2741307.3 | D43: =IF(B43<=$F$11,(C43*$F$13),"") -> 6853.2683 | E43: =IF(B43<=$F$12,0,IF(B43<=$F$11,(-$F$16-D43),"")) -> 21909.639 | F43: =IF(B43<=$F$11,(($F$20*$F$2)+($F$19*$F$2)+(C43*$F$18)+($F$17*C43)),"") -> 4660.2225 | G43: =IF(B43<=$F$11,(D43+E43),"") -> 28762.907 | H43: =IF(B43<=$F$11,(F43+G43),"") -> 33423.13 | I43: =IF(B43<=$F$11,(C43*$F$13)*(1-$F$10),"") -> 5098.8316 | J43: =IF(B43<=$F$11,(($F$20*$F$2*(1-$F$10))+($F$19*$F$2)+((C43*$F$18)*(1-$F$10))+(($F$17*C43))),"") -> 3467.2055 | K43: =IF(B43<=$F$11,(E43+I43),"") -> 27008.471 | L43: =IF(B43<=$F$11,(J43+K43),"") -> 30475.676 | M43: =IF(B43<=$F$11,(C43-E43),IF(B43>$F$11,"",0)) -> 2719397.7
...

Sheet Billån
A1: Hovedstol | B1: 150000
A2: Stiftelsesomk.
A3: Provenue | B3: =B1-B2 -> 150000
A4: Rente pr. år | B4: 0.06 | F4: Årlige renteudgifter
A5: Antal år | B5: 8 | F5: KUN VED 12 TERMINER PR. ÅR | J5: =7.22/12 -> 0.60166667
A6: Terminer pr. år | B6: 12 | F6: År 1 | G6: =SUM(B11:B22) -> 8590.2064 | J6: =7.22/12 -> 0.60166667
A7: Antal terminer | B7: =B5*B6 -> 96 | F7: År 2 | G7: =SUM(B23:B34) -> 7661.0691 | J7: =7.22/12 -> 0.60166667
A8: Ydelse pr. termin | B8: =PMT(B4/B6,B7,-B1) -> 1971.2145 | F8: År 3 | G8: =SUM(B35:B46) -> 6674.6247 | J8: =7.22/12 -> 0.60166667
F9: År 4 | G9: =SUM(B47:B58) -> 5627.3385 | J9: =7.22/12 -> 0.60166667
A10: Termin | B10: Rente | C10: afdrag | D10: restgæld | F10: År 5 | G10: =SUM(B59:B70) -> 4515.4581 | J10: =7.22/12 -> 0.60166667
A11: 1 | B11: =B1*B4/B6 -> 750 | C11: =$B$8-B11 -> 1221.2145 | D11: =B1-C11 -> 148778.79 | F11: År 6 | G11: =SUM(B71:B82) -> 3334.9993 | J11: =7.22/12 -> 0.60166667
A12: =IF(D11<0.1,0,A11+1) -> 2 | B12: =IF(D11<0.1,0,D11*$B$4/$B$6) -> 743.89393 | C12: =IF(D11<0.1,0,$B$8-B12) -> 1227.3206 | D12: =IF(D11<0.1,0,D11-C12) -> 147551.46 | F12: År 7 | G12: =SUM(B83:B94) -> 2081.7323 | J12: =7.22/12 -> 0.60166667
A13: =IF(D12<0.1,0,A12+1) -> 3 | B13: =IF(D12<0.1,0,D12*$B$4/$B$6) -> 737.75732 | C13: =IF(D12<0.1,0,$B$8-B13) -> 1233.4572 | D13: =IF(D12<0.1,0,D12-C13) -> 146318.01 | J13: =7.22/12 -> 0.60166667
A14: =IF(D13<0.1,0,A13+1) -> 4 | B14: =IF(D13<0.1,0,D13*$B$4/$B$6) -> 731.59004 | C14: =IF(D13<0.1,0,$B$8-B14) -> 1239.6245 | D14: =IF(D13<0.1,0,D13-C14) -> 145078.38 | F14: Årlig ydelse | G14: =B6*B8 -> 23654.574 | J14: =7.22/12 -> 0.60166667
A15: =IF(D14<0.1,0,A14+1) -> 5 | B15: =IF(D14<0.1,0,D14*$B$4/$B$6) -> 725.39192 | C15: =IF(D14<0.1,0,$B$8-B15) -> 1245.8226 | D15: =IF(D14<0.1,0,D14-C15) -> 143832.56 | J15: =7.22/12 -> 0.60166667
A16: =IF(D15<0.1,0,A15+1) -> 6 | B16: =IF(D15<0.1,0,D15*$B$4/$B$6) -> 719.1628 | C16: =IF(D15<0.1,0,$B$8-B16) -> 1252.0517 | D16: =IF(D15<0.1,0,D15-C16) -> 142580.51 | F16: Effektiv rente pr. termin | H16: =RATE(B7,-B8,B3) -> 0.005 | J16: =7.22/12 -> 0.60166667
A17: =IF(D16<0.1,0,A16+1) -> 7 | B17: =IF(D16<0.1,0,D16*$B$4/$B$6) -> 712.90254 | C17: =IF(D16<0.1,0,$B$8-B17) -> 1258.312 | D17: =IF(D16<0.1,0,D16-C17) -> 141322.2 | F17: ÅOP | G17: =(1+H16)^B6-1 -> 0.061677812
A18: =IF(D17<0.1,0,A17+1) -> 8 | B18: =IF(D17<0.1,0,D17*$B$4/$B$6) -> 706.61098 | C18: =IF(D17<0.1,0,$B$8-B18) -> 1264.6035 | D18: =IF(D17<0.1,0,D17-C18) -> 140057.59
A19: =IF(D18<0.1,0,A18+1) -> 9 | B19: =IF(D18<0.1,0,D18*$B$4/$B$6) -> 700.28797 | C19: =IF(D18<0.1,0,$B$8-B19) -> 1270.9266 | D19: =IF(D18<0.1,0,D18-C19) -> 138786.67
A20: =IF(D19<0.1,0,A19+1) -> 10 | B20: =IF(D19<0.1,0,D19*$B$4/$B$6) -> 693.93333 | C20: =IF(D19<0.1,0,$B$8-B20) -> 1277.2812 | D20: =IF(D19<0.1,0,D19-C20) -> 137509.39
A21: =IF(D20<0.1,0,A20+1) -> 11 | B21: =IF(D20<0.1,0,D20*$B$4/$B$6) -> 687.54693 | C21: =IF(D20<0.1,0,$B$8-B21) -> 1283.6676 | D21: =IF(D20<0.1,0,D20-C21) -> 136225.72
A22: =IF(D21<0.1,0,A21+1) -> 12 | B22: =IF(D21<0.1,0,D21*$B$4/$B$6) -> 681.12859 | C22: =IF(D21<0.1,0,$B$8-B22) -> 1290.0859 | D22: =IF(D21<0.1,0,D21-C22) -> 134935.63
A23: =IF(D22<0.1,0,A22+1) -> 13 | B23: =IF(D22<0.1,0,D22*$B$4/$B$6) -> 674.67816 | C23: =IF(D22<0.1,0,$B$8-B23) -> 1296.5364 | D23: =IF(D22<0.1,0,D22-C23) -> 133639.1
A24: =IF(D23<0.1,0,A23+1) -> 14 | B24: =IF(D23<0.1,0,D23*$B$4/$B$6) -> 668.19548 | C24: =IF(D23<0.1,0,$B$8-B24) -> 1303.0191 | D24: =IF(D23<0.1,0,D23-C24) -> 132336.08
A25: =IF(D24<0.1,0,A24+1) -> 15 | B25: =IF(D24<0.1,0,D24*$B$4/$B$6) -> 661.68038 | C25: =IF(D24<0.1,0,$B$8-B25) -> 1309.5341 | D25: =IF(D24<0.1,0,D24-C25) -> 131026.54
A26: =IF(D25<0.1,0,A25+1) -> 16 | B26: =IF(D25<0.1,0,D25*$B$4/$B$6) -> 655.13271 | C26: =IF(D25<0.1,0,$B$8-B26) -> 1316.0818 | D26: =IF(D25<0.1,0,D25-C26) -> 129710.46
A27: =IF(D26<0.1,0,A26+1) -> 17 | B27: =IF(D26<0.1,0,D26*$B$4/$B$6) -> 648.5523 | C27: =IF(D26<0.1,0,$B$8-B27) -> 1322.6622 | D27: =IF(D26<0.1,0,D26-C27) -> 128387.8
A28: =IF(D27<0.1,0,A27+1) -> 18 | B28: =IF(D27<0.1,0,D27*$B$4/$B$6) -> 641.93899 | C28: =IF(D27<0.1,0,$B$8-B28) -> 1329.2755 | D28: =IF(D27<0.1,0,D27-C28) -> 127058.52
A29: =IF(D28<0.1,0,A28+1) -> 19 | B29: =IF(D28<0.1,0,D28*$B$4/$B$6) -> 635.29261 | C29: =IF(D28<0.1,0,$B$8-B29) -> 1335.9219 | D29: =IF(D28<0.1,0,D28-C29) -> 125722.6
... A130: =IF(D129<0.1,0,A129+1) -> 0 | B130: =IF(D129<0.1,0,D129*$B$4/$B$6) -> 0 | C130: =IF(D129<0.1,0,$B$8-B130) -> 0 | D130: =IF(D129<0.1,0,D129-C130) -> 0
