Workbook
Name Gift: 'Skat. Frederik'!$G$8
Name Skatteordning: #REF!
Name TABLE: 'Skat. Frederik'!$C$2:$C$2
Name TABLE_10: 'Skat. Frederik'!$C$35:$C$35
Name TABLE_11: 'Skat. Frederik'!$C$36:$C$36
Name TABLE_12: 'Skat. Frederik'!#REF!
Name TABLE_13: 'Skat. Frederik'!$C$38:$C$38
Name TABLE_14: 'Skat. Frederik'!$C$40:$C$40
Name TABLE_15: 'Skat. Frederik'!#REF!
Name TABLE_16: 'Skat. Frederik'!$C$41:$C$41
Name TABLE_17: 'Skat. Frederik'!$C$42:$C$42
Name TABLE_18: 'Skat. Frederik'!$C$43:$C$43
Name TABLE_19: 'Skat. Frederik'!$C$44:$C$44
Name TABLE_2: 'Skat. Frederik'!$C$8:$C$8
Name TABLE_20: 'Skat. Frederik'!$C$47:$C$47
Name TABLE_21: 'Skat. Frederik'!$C$48:$C$48
Name TABLE_22: 'Skat. Frederik'!$C$49:$C$49
Name TABLE_23: 'Skat. Frederik'!$C$50:$C$50
Name TABLE_24: 'Skat. Frederik'!$C$51:$C$51
Name TABLE_25: 'Skat. Frederik'!$C$52:$C$52
Name TABLE_26: 'Skat. Frederik'!$C$53:$C$53
Name TABLE_27: 'Skat. Frederik'!$C$54:$C$54
Name TABLE_28: 'Skat. Frederik'!$C$57:$C$57
Name TABLE_29: 'Skat. Frederik'!$C$58:$C$58
Name TABLE_3: 'Skat. Frederik'!$C$9:$C$9
Name TABLE_30: 'Skat. Frederik'!$C$60:$C$60
Name TABLE_31: 'Skat. Frederik'!$C$61:$C$61
Name TABLE_32: 'Skat. Frederik'!$C$62:$C$62
Name TABLE_33: 'Skat. Frederik'!$C$63:$C$63
Name TABLE_34: 'Skat. Frederik'!$C$67:$C$67
Name TABLE_35: 'Skat. Frederik'!$C$68:$C$68
Name TABLE_36: 'Skat. Frederik'!$C$69:$C$69
Name TABLE_37: 'Skat. Frederik'!$C$70:$C$70
Name TABLE_38: 'Skat. Frederik'!$C$73:$C$73
Name TABLE_39: 'Skat. Frederik'!$C$74:$C$74
Name TABLE_4: 'Skat. Frederik'!$C$11:$C$11
Name TABLE_40: 'Skat. Frederik'!$C$76:$C$76
Name TABLE_41: 'Skat. Frederik'!$C$77:$C$77
Name TABLE_42: 'Skat. Frederik'!$C$81:$C$81
Name TABLE_43: 'Skat. Frederik'!#REF!
Name TABLE_44: 'Skat. Frederik'!#REF!
Name TABLE_45: 'Skat. Frederik'!$C$82:$C$82
Name TABLE_46: 'Skat. Frederik'!$C$83:$C$83
Name TABLE_47: 'Skat. Frederik'!$C$85:$C$85
Name TABLE_48: 'Skat. Frederik'!$C$86:$C$86
Name TABLE_49: 'Skat. Frederik'!$C$87:$C$87
Name TABLE_5: 'Skat. Frederik'!$C$13:$C$13
Name TABLE_50: 'Skat. Frederik'!$C$88:$C$88
Name TABLE_51: 'Skat. Frederik'!$C$89:$C$89
Name TABLE_52: 'Skat. Frederik'!$C$90:$C$90
Name TABLE_53: 'Skat. Frederik'!#REF!
Name TABLE_54: 'Skat. Frederik'!#REF!
Name TABLE_55: 'Skat. Frederik'!#REF!
Name TABLE_56: 'Skat. Frederik'!$C$102:$C$102
Name TABLE_57: 'Skat. Frederik'!$C$103:$C$103
Name TABLE_58: 'Skat. Frederik'!$C$109:$C$109
Name TABLE_59: 'Skat. Frederik'!$C$110:$C$110
Name TABLE_6: 'Skat. Frederik'!$C$18:$C$18
Name TABLE_60: 'Skat. Frederik'!$C$112:$C$112
Name TABLE_61: 'Skat. Frederik'!$C$122:$C$122

Sheet Budget
A1: Indkomst m.m. | D1: Gældsfaktor
A2: Løn, brutto/år | B2: =12*(44000+49000) -> 1116000 | D2: Indkomst:
A3: Skat/år | B3: ='Skat. Frederik'!E151+'Skat. Nina'!E151 -> 376300.8 | D3: Gæld:
A5: Disponibel indkomst/måned | B5: =(B2-B3+B4)/12 -> 61641.6
A7: Faste udgifter
A8: Boligafgift | B8: 10000
A9: Andelsboliglån | B9: =Andelsboliglån!B8 -> 6444.7455
A10: El, vand og varme | B10: 1500
A11: Indboforsikring | B11: 250
A12: SU lån | B12: 1900
A13: Billån | B13: =Billån!B8 -> 3315.8738
A14: Service, el, forsikring m.m. til bil | B14: 1800
A15: Øvrige transportudgifter | B15: 1000
A16: Fagforening | B16: 1000
A17: A-kasse | B17: 1100
A18: Internet/telefon/streaming | B18: 800
A19: Café og restaurantbesøg | B19: 2000
A20: Sport, fitness m.m. | B20: 2500
A21: Fast opsparing | B21: 7000
A23: Rådighedsbeløb/måned | B23: =B5-(SUM(B8:B22)) -> 21030.981

Sheet Andelsboliglån
A1: Hovedstol | B1: 800000
A2: Stiftelsesomk.
A3: Provenue | B3: =B1-B2 -> 800000
A4: Rente pr. år | B4: 0.075 | F4: Årlige renteudgifter
A5: Antal år | B5: 20 | F5: KUN VED 12 TERMINER PR. ÅR | J5: =7.22/12 -> 0.60166667
A6: Terminer pr. år | B6: 12 | F6: År 1 | G6: =SUM(B11:B22) -> 59391.45 | J6: =7.22/12 -> 0.60166667
A7: Antal terminer | B7: =B5*B6 -> 240 | F7: År 2 | G7: =SUM(B23:B34) -> 57998.295 | J7: =7.22/12 -> 0.60166667
A8: Ydelse pr. termin | B8: =PMT(B4/B6,B7,-B1) -> 6444.7455 | F8: År 3 | G8: =SUM(B35:B46) -> 56496.985 | J8: =7.22/12 -> 0.60166667
F9: År 4 | G9: =SUM(B47:B58) -> 54879.125 | J9: =7.22/12 -> 0.60166667
A10: Termin | B10: Rente | C10: afdrag | D10: restgæld | F10: År 5 | G10: =SUM(B59:B70) -> 53135.666 | J10: =7.22/12 -> 0.60166667
A11: 1 | B11: =B1*B4/B6 -> 5000 | C11: =$B$8-B11 -> 1444.7455 | D11: =B1-C11 -> 798555.25 | F11: År 6 | G11: =SUM(B71:B82) -> 51256.857 | J11: =7.22/12 -> 0.60166667
A12: =IF(D11<0.1,0,A11+1) -> 2 | B12: =IF(D11<0.1,0,D11*$B$4/$B$6) -> 4990.9703 | C12: =IF(D11<0.1,0,$B$8-B12) -> 1453.7752 | D12: =IF(D11<0.1,0,D11-C12) -> 797101.48 | F12: År 7 | G12: =SUM(B83:B94) -> 49232.192 | J12: =7.22/12 -> 0.60166667
A13: =IF(D12<0.1,0,A12+1) -> 3 | B13: =IF(D12<0.1,0,D12*$B$4/$B$6) -> 4981.8842 | C13: =IF(D12<0.1,0,$B$8-B13) -> 1462.8613 | D13: =IF(D12<0.1,0,D12-C13) -> 795638.62 | J13: =7.22/12 -> 0.60166667
A14: =IF(D13<0.1,0,A13+1) -> 4 | B14: =IF(D13<0.1,0,D13*$B$4/$B$6) -> 4972.7414 | C14: =IF(D13<0.1,0,$B$8-B14) -> 1472.0042 | D14: =IF(D13<0.1,0,D13-C14) -> 794166.61 | F14: Årlig ydelse | G14: =B6*B8 -> 77336.947 | J14: =7.22/12 -> 0.60166667
A15: =IF(D14<0.1,0,A14+1) -> 5 | B15: =IF(D14<0.1,0,D14*$B$4/$B$6) -> 4963.5413 | C15: =IF(D14<0.1,0,$B$8-B15) -> 1481.2042 | D15: =IF(D14<0.1,0,D14-C15) -> 792685.41 | J15: =7.22/12 -> 0.60166667
A16: =IF(D15<0.1,0,A15+1) -> 6 | B16: =IF(D15<0.1,0,D15*$B$4/$B$6) -> 4954.2838 | C16: =IF(D15<0.1,0,$B$8-B16) -> 1490.4617 | D16: =IF(D15<0.1,0,D15-C16) -> 791194.95 | F16: Effektiv rente pr. termin | H16: =RATE(B7,-B8,B3) -> 0.00625 | J16: =7.22/12 -> 0.60166667
A17: =IF(D16<0.1,0,A16+1) -> 7 | B17: =IF(D16<0.1,0,D16*$B$4/$B$6) -> 4944.9684 | C17: =IF(D16<0.1,0,$B$8-B17) -> 1499.7771 | D17: =IF(D16<0.1,0,D16-C17) -> 789695.17 | F17: ÅOP | G17: =(1+H16)^B6-1 -> 0.077632599
A18: =IF(D17<0.1,0,A17+1) -> 8 | B18: =IF(D17<0.1,0,D17*$B$4/$B$6) -> 4935.5948 | C18: =IF(D17<0.1,0,$B$8-B18) -> 1509.1507 | D18: =IF(D17<0.1,0,D17-C18) -> 788186.02
A19: =IF(D18<0.1,0,A18+1) -> 9 | B19: =IF(D18<0.1,0,D18*$B$4/$B$6) -> 4926.1626 | C19: =IF(D18<0.1,0,$B$8-B19) -> 1518.5829 | D19: =IF(D18<0.1,0,D18-C19) -> 786667.44
A20: =IF(D19<0.1,0,A19+1) -> 10 | B20: =IF(D19<0.1,0,D19*$B$4/$B$6) -> 4916.6715 | C20: =IF(D19<0.1,0,$B$8-B20) -> 1528.0741 | D20: =IF(D19<0.1,0,D19-C20) -> 785139.36
A21: =IF(D20<0.1,0,A20+1) -> 11 | B21: =IF(D20<0.1,0,D20*$B$4/$B$6) -> 4907.121 | C21: =IF(D20<0.1,0,$B$8-B21) -> 1537.6245 | D21: =IF(D20<0.1,0,D20-C21) -> 783601.74
A22: =IF(D21<0.1,0,A21+1) -> 12 | B22: =IF(D21<0.1,0,D21*$B$4/$B$6) -> 4897.5109 | C22: =IF(D21<0.1,0,$B$8-B22) -> 1547.2347 | D22: =IF(D21<0.1,0,D21-C22) -> 782054.5
A23: =IF(D22<0.1,0,A22+1) -> 13 | B23: =IF(D22<0.1,0,D22*$B$4/$B$6) -> 4887.8406 | C23: =IF(D22<0.1,0,$B$8-B23) -> 1556.9049 | D23: =IF(D22<0.1,0,D22-C23) -> 780497.6
A24: =IF(D23<0.1,0,A23+1) -> 14 | B24: =IF(D23<0.1,0,D23*$B$4/$B$6) -> 4878.11 | C24: =IF(D23<0.1,0,$B$8-B24) -> 1566.6356 | D24: =IF(D23<0.1,0,D23-C24) -> 778930.96
A25: =IF(D24<0.1,0,A24+1) -> 15 | B25: =IF(D24<0.1,0,D24*$B$4/$B$6) -> 4868.3185 | C25: =IF(D24<0.1,0,$B$8-B25) -> 1576.427 | D25: =IF(D24<0.1,0,D24-C25) -> 777354.54
A26: =IF(D25<0.1,0,A25+1) -> 16 | B26: =IF(D25<0.1,0,D25*$B$4/$B$6) -> 4858.4659 | C26: =IF(D25<0.1,0,$B$8-B26) -> 1586.2797 | D26: =IF(D25<0.1,0,D25-C26) -> 775768.26
A27: =IF(D26<0.1,0,A26+1) -> 17 | B27: =IF(D26<0.1,0,D26*$B$4/$B$6) -> 4848.5516 | C27: =IF(D26<0.1,0,$B$8-B27) -> 1596.1939 | D27: =IF(D26<0.1,0,D26-C27) -> 774172.06
A28: =IF(D27<0.1,0,A27+1) -> 18 | B28: =IF(D27<0.1,0,D27*$B$4/$B$6) -> 4838.5754 | C28: =IF(D27<0.1,0,$B$8-B28) -> 1606.1702 | D28: =IF(D27<0.1,0,D27-C28) -> 772565.89
A29: =IF(D28<0.1,0,A28+1) -> 19 | B29: =IF(D28<0.1,0,D28*$B$4/$B$6) -> 4828.5368 | C29: =IF(D28<0.1,0,$B$8-B29) -> 1616.2087 | D29: =IF(D28<0.1,0,D28-C29) -> 770949.68
... A130: =IF(D129<0.1,0,A129+1) -> 120 | B130: =IF(D129<0.1,0,D129*$B$4/$B$6) -> 3412.3023 | C130: =IF(D129<0.1,0,$B$8-B130) -> 3032.4432 | D130: =IF(D129<0.1,0,D129-C130) -> 542935.93

Sheet Billån
A1: Hovedstol | B1: 250000
A2: Stiftelsesomk.
A3: Provenue | B3: =B1-B2 -> 250000
A4: Rente pr. år | B4: 0.0625 | F4: Årlige renteudgifter
A5: Antal år | B5: 8 | F5: KUN VED 12 TERMINER PR. ÅR | J5: =7.22/12 -> 0.60166667
A6: Terminer pr. år | B6: 12 | F6: År 1 | G6: =SUM(B11:B22) -> 14920.599 | J6: =7.22/12 -> 0.60166667
A7: Antal terminer | B7: =B5*B6 -> 96 | F7: År 2 | G7: =SUM(B23:B34) -> 13320.923 | J7: =7.22/12 -> 0.60166667
A8: Ydelse pr. termin | B8: =PMT(B4/B6,B7,-B1) -> 3315.8738 | F8: År 3 | G8: =SUM(B35:B46) -> 11618.353 | J8: =7.22/12 -> 0.60166667
F9: År 4 | G9: =SUM(B47:B58) -> 9806.2701 | J9: =7.22/12 -> 0.60166667
A10: Termin | B10: Rente | C10: afdrag | D10: restgæld | F10: År 5 | G10: =SUM(B59:B70) -> 7877.631 | J10: =7.22/12 -> 0.60166667
A11: 1 | B11: =B1*B4/B6 -> 1302.0833 | C11: =$B$8-B11 -> 2013.7905 | D11: =B1-C11 -> 247986.21 | F11: År 6 | G11: =SUM(B71:B82) -> 5824.9382 | J11: =7.22/12 -> 0.60166667
A12: =IF(D11<0.1,0,A11+1) -> 2 | B12: =IF(D11<0.1,0,D11*$B$4/$B$6) -> 1291.5948 | C12: =IF(D11<0.1,0,$B$8-B12) -> 2024.279 | D12: =IF(D11<0.1,0,D11-C12) -> 245961.93 | F12: År 7 | G12: =SUM(B83:B94) -> 3640.2125 | J12: =7.22/12 -> 0.60166667
A13: =IF(D12<0.1,0,A12+1) -> 3 | B13: =IF(D12<0.1,0,D12*$B$4/$B$6) -> 1281.0517 | C13: =IF(D12<0.1,0,$B$8-B13) -> 2034.8221 | D13: =IF(D12<0.1,0,D12-C13) -> 243927.11 | J13: =7.22/12 -> 0.60166667
A14: =IF(D13<0.1,0,A13+1) -> 4 | B14: =IF(D13<0.1,0,D13*$B$4/$B$6) -> 1270.4537 | C14: =IF(D13<0.1,0,$B$8-B14) -> 2045.4202 | D14: =IF(D13<0.1,0,D13-C14) -> 241881.69 | F14: Årlig ydelse | G14: =B6*B8 -> 39790.486 | J14: =7.22/12 -> 0.60166667
A15: =IF(D14<0.1,0,A14+1) -> 5 | B15: =IF(D14<0.1,0,D14*$B$4/$B$6) -> 1259.8005 | C15: =IF(D14<0.1,0,$B$8-B15) -> 2056.0734 | D15: =IF(D14<0.1,0,D14-C15) -> 239825.61 | J15: =7.22/12 -> 0.60166667
A16: =IF(D15<0.1,0,A15+1) -> 6 | B16: =IF(D15<0.1,0,D15*$B$4/$B$6) -> 1249.0917 | C16: =IF(D15<0.1,0,$B$8-B16) -> 2066.7821 | D16: =IF(D15<0.1,0,D15-C16) -> 237758.83 | F16: Effektiv rente pr. termin | H16: =RATE(B7,-B8,B3) -> 0.0052083333 | J16: =7.22/12 -> 0.60166667
A17: =IF(D16<0.1,0,A16+1) -> 7 | B17: =IF(D16<0.1,0,D16*$B$4/$B$6) -> 1238.3273 | C17: =IF(D16<0.1,0,$B$8-B17) -> 2077.5466 | D17: =IF(D16<0.1,0,D16-C17) -> 235681.29 | F17: ÅOP | G17: =(1+H16)^B6-1 -> 0.064321815
A18: =IF(D17<0.1,0,A17+1) -> 8 | B18: =IF(D17<0.1,0,D17*$B$4/$B$6) -> 1227.5067 | C18: =IF(D17<0.1,0,$B$8-B18) -> 2088.3671 | D18: =IF(D17<0.1,0,D17-C18) -> 233592.92
A19: =IF(D18<0.1,0,A18+1) -> 9 | B19: =IF(D18<0.1,0,D18*$B$4/$B$6) -> 1216.6298 | C19: =IF(D18<0.1,0,$B$8-B19) -> 2099.2441 | D19: =IF(D18<0.1,0,D18-C19) -> 231493.67
A20: =IF(D19<0.1,0,A19+1) -> 10 | B20: =IF(D19<0.1,0,D19*$B$4/$B$6) -> 1205.6962 | C20: =IF(D19<0.1,0,$B$8-B20) -> 2110.1776 | D20: =IF(D19<0.1,0,D19-C20) -> 229383.5
A21: =IF(D20<0.1,0,A20+1) -> 11 | B21: =IF(D20<0.1,0,D20*$B$4/$B$6) -> 1194.7057 | C21: =IF(D20<0.1,0,$B$8-B21) -> 2121.1681 | D21: =IF(D20<0.1,0,D20-C21) -> 227262.33
A22: =IF(D21<0.1,0,A21+1) -> 12 | B22: =IF(D21<0.1,0,D21*$B$4/$B$6) -> 1183.658 | C22: =IF(D21<0.1,0,$B$8-B22) -> 2132.2159 | D22: =IF(D21<0.1,0,D21-C22) -> 225130.11
A23: =IF(D22<0.1,0,A22+1) -> 13 | B23: =IF(D22<0.1,0,D22*$B$4/$B$6) -> 1172.5527 | C23: =IF(D22<0.1,0,$B$8-B23) -> 2143.3212 | D23: =IF(D22<0.1,0,D22-C23) -> 222986.79
A24: =IF(D23<0.1,0,A23+1) -> 14 | B24: =IF(D23<0.1,0,D23*$B$4/$B$6) -> 1161.3895 | C24: =IF(D23<0.1,0,$B$8-B24) -> 2154.4843 | D24: =IF(D23<0.1,0,D23-C24) -> 220832.31
A25: =IF(D24<0.1,0,A24+1) -> 15 | B25: =IF(D24<0.1,0,D24*$B$4/$B$6) -> 1150.1683 | C25: =IF(D24<0.1,0,$B$8-B25) -> 2165.7056 | D25: =IF(D24<0.1,0,D24-C25) -> 218666.6
A26: =IF(D25<0.1,0,A25+1) -> 16 | B26: =IF(D25<0.1,0,D25*$B$4/$B$6) -> 1138.8886 | C26: =IF(D25<0.1,0,$B$8-B26) -> 2176.9853 | D26: =IF(D25<0.1,0,D25-C26) -> 216489.62
A27: =IF(D26<0.1,0,A26+1) -> 17 | B27: =IF(D26<0.1,0,D26*$B$4/$B$6) -> 1127.5501 | C27: =IF(D26<0.1,0,$B$8-B27) -> 2188.3238 | D27: =IF(D26<0.1,0,D26-C27) -> 214301.29
A28: =IF(D27<0.1,0,A27+1) -> 18 | B28: =IF(D27<0.1,0,D27*$B$4/$B$6) -> 1116.1526 | C28: =IF(D27<0.1,0,$B$8-B28) -> 2199.7213 | D28: =IF(D27<0.1,0,D27-C28) -> 212101.57
A29: =IF(D28<0.1,0,A28+1) -> 19 | B29: =IF(D28<0.1,0,D28*$B$4/$B$6) -> 1104.6957 | C29: =IF(D28<0.1,0,$B$8-B29) -> 2211.1782 | D29: =IF(D28<0.1,0,D28-C29) -> 209890.39
... A130: =IF(D129<0.1,0,A129+1) -> 0 | B130: =IF(D129<0.1,0,D129*$B$4/$B$6) -> 0 | C130: =IF(D129<0.1,0,$B$8-B130) -> 0 | D130: =IF(D129<0.1,0,D129-C130) -> 0

Sheet Skat. Frederik
C1: 45291 | I1: Kommuneskatteprocenter | O1: Satser | R1: TRUE | S1: ja
C2: Skatteberegning 2024 | R2: FALSE | S2: nej
C3: Regnearket implementerer hovedreglerne i indkomstbeskatningen. Brug af dette regneark sker på eget ansvar. Der ydes ikke erstatning, såfremt brugen af regnearket giver anledning til, at der lides et tab. | I3: 2024 | O3: 2024
I4: Kommune | J4: Skatte | K4: Kirke | L4: Nedslag | M4: Grundskyld | O4: Arbejdsmarkedsbidragsprocent AMB § 1 | P4: 8
J5: pct. | K5: pct. | L5: pct. | M5: prm. | O5: Bundskatprocent PSL § 6, stk. 2 | P5: 12.06
C6: 1. Forskellige oplysninger | O6: Sundhedsbidragsprocent PSL § 8 | P6: 0
E7: Frederik | I7: intet sommerhus | M7: 0 | O7: Topskatprocent PSL § 7, stk. 1 | P7: 15
C8: Gift ? | E8: nej | G8: =IF(E8=S1,TRUE,FALSE) -> FALSE | I8: Albertslund | J8: 25.6 | K8: 0.8 | L8: 0.59 | M8: 9.1 | O8: Topskatgrænse PSL § 7, stk. 2 | P8: 588900
C9: Under 18 år hele indkomståret ? | E9: nej | F9: nej | I9: Allerød | J9: 25.3 | K9: 0.58 | L9: 0.29 | M9: 8 | O9: Skatteloftprocent PSL § 19, stk. 1 | P9: 52.07
C10: Mere end 15 år til folkepensionsalderen ? | E10: ja | F10: ja | I10: Assens | J10: 26.1 | K10: 0.98 | L10: 1.09 | M10: 11.2 | O10: Skatteloftprocent positiv nettokapitalindkomst PSL § 19, stk. 2 | P10: 42
C11: Medlem af Folkekirken ? | E11: ja | F11: ja | I11: Ballerup | J11: 25.5 | K11: 0.72 | L11: 0.49 | M11: 8.3 | O11: Personfradrag unge PSL § 10, stk. 2 | P11: 39800
I12: Billund | J12: 24 | K12: 0.89 | L12: 0 | M12: 7.2 | O12: Personfradrag PSL § 10, stk. 1 | P12: 49700
C13: Bopælskommune pr. 5. september 2023 | E13: Lyngby-Taarbæk | I13: Bornholm | J13: 26.2 | K13: 0.93 | L13: 1.19 | M13: 10.7 | O13: Maksimalt kapitalpensionsfradrag PBL § 16, stk. 1 | P13: 0
C14: Kommuneskatteprocent | E14: =VLOOKUP(E13,I8:M105,2,FALSE) -> 24.38 | I14: Brøndby | J14: 24.3 | K14: 0.8 | L14: 0 | M14: 4.9 | O14: Bundfradrag positiv nettokapitalindkomst PSL § 7, stk. 1 | P14: 50500
C15: Kirkeskatteprocent | E15: =VLOOKUP(E13,I8:M105,3,FALSE) -> 0.6 | I15: Brønderslev | J15: 26.3 | K15: 1.08 | L15: 1.29 | M15: 17.1 | O15: Aktieskatprocent under grænse PSL § 8 a, stk. 1 | P15: 27
C16: Grundskyldspromille | E16: =VLOOKUP(E13,I7:M105,5,FALSE) -> 6.7 | I16: Dragør | J16: 24.8 | K16: 0.61 | L16: 0 | M16: 8.1 | O16: Aktieskatprocent over grænse PSL § 8 a, stk. 2 | P16: 42
I17: Egedal | J17: 25.7 | K17: 0.76 | L17: 0.69 | M17: 8.8 | O17: Grænse aktieskat PSL § 8 a, stk. 1 og 2 | P17: 61000
C18: Ejendomsværdi af enfamiliehus | I18: Esbjerg | J18: 25.8 | K18: 0.81 | L18: 0.79 | M18: 9.9 | O18: Bundgrænse lønmodtagerfradrag LL § 9, stk. 1 | P18: 7000
C19: Ejendomsværdi af ejerlejlighed | I19: Faaborg-Midtfyn | J19: 26.1 | K19: 1.05 | L19: 1.09 | M19: 8.5 | O19: Beskæftigelsesfradragsprocent LL § 9 J, stk. 2 | P19: 10.65
C20: Hus/ejerlejlighed erhvervet senest 1. juli 1998 ? | E20: nej | I20: Fanø | J20: 25.77 | K20: 1.14 | L20: 0.76 | M20: 12.5 | O20: Maksimalt beskæftigelsesfradrag LL § 9 J, stk. 2 | P20: 45100
C21: Grundværdi hus/ejerlejlighed | I21: Favrskov | J21: 25.7 | K21: 0.96 | L21: 0.69 | M21: 10.6 | O21: Ejendomsværdiskatteprocent under grænse | P21: 0.51
C22: Ejendomsværdi af sommerhus | I22: Faxe | J22: 25.8 | K22: 1.08 | L22: 0.79 | M22: 8 | O22: Ejendomsværdiskatteprocent over grænse | P22: 1.4
C23: Beliggenhed sommerhus | E23: Albertslund | I23: Fredensborg | J23: 25.3 | K23: 0.62 | L23: 0.29 | M23: 8.3 | O23: Grænse ejendomsværdiskat | P23: 9200000
C24: Grundskyldspromille | E24: =VLOOKUP(E23,I7:M105,5,FALSE) -> 9.1 | I24: Fredericia | J24: 25.5 | K24: 0.88 | L24: 0.49 | M24: 13 | O24: Nedslag ejendomsværdiskat ESL § 23, stk. 1 | P24: 0.1
C25: Grundværdi sommerhus | I25: Frederiksberg | J25: 24.57 | K25: 0.5 | L25: 0 | M25: 3.1 | O25: Nedslag ejendomsværdiskat ESL § 24, stk. 1 | P25: 0.21
C26: Sommerhus erhvervet senest 1. juli 1998 ? | E26: nej | I26: Frederikshavn | J26: 26.2 | K26: 1.03 | L26: 1.19 | M26: 13.4 | O26: Maksimalt nedslag efter ESL § 24, stk. 1 | P26: 1200
C27: Bidrag og præmie til arbejdsgiveradministreret pension med løbende udbetalinger og ratepension | E27: =E32*0.12 -> 63360 | I27: Frederikssund | J27: 25.8 | K27: 0.96 | L27: 0.79 | M27: 12 | O27: Nedslagsprocent negativ nettokapitalindkomst, PSL § 11, stk. 2 | P27: 8
I28: Furesø | J28: 24.88 | K28: 0.65 | L28: 0 | M28: 7 | O28: Bundfradrag udligningsskat, PSL § 7 a, stk. 4 | P28: 457500
C29: 2. Indkomst og fradrag | I29: Gentofte | J29: 24.34 | K29: 0.4 | L29: 0 | M29: 5.1 | O29: Udligningsskatteprocent, PSL § 7 a, stk. 5 | P29: 0
E30: Skatteyder | F30: =IF(E8=S1,"Ægtefælle","ugift") -> ugift | I30: Gladsaxe | J30: 23.6 | K30: 0.75 | L30: 0 | M30: 5.9 | O30: Overførbart bundfradrag udligningsskat, PSL § 7 a, stk. 6 | P30: 152600
C31: Personlig indkomst | I31: Glostrup | J31: 24.6 | K31: 0.8 | L31: 0 | M31: 6.5 | O31: Bundgrænse jobfradrag LL § 9 K, stk. 1 | P31: 216100
C32: Løn, honorarer mv. (før fradrag af AMB) | E32: =12*44000 -> 528000 | I32: Greve | J32: 24.52 | K32: 0.73 | L32: 0 | M32: 5.5 | O32: Jobfradragsprocent LL § 9 K, stk. 2 | P32: 4.5
C33: - reduceres med Arbejdsmarkedsbidrag (AMB) | E33: =E32*P4/100 -> 42240 | F33: =F32*P4/100 -> 0 | I33: Gribskov | J33: 25.4 | K33: 0.85 | L33: 0.39 | M33: 11.1 | O33: Maksimalt jobfradrag LL § 9 K, stk. 2 | P33: 2800
C34: Personlig indkomst fra selvstændig virksomhed | I34: Guldborgsund | J34: 25.8 | K34: 1.16 | L34: 0.79 | M34: 15.9 | O34: Maksimalt ekstra pensionsfradrag LL § 9 L | P34: 80600
C35: - reduceres med Arbejdsmarkedsbidrag (AMB) | E35: =MAX(0,E34*P4/100) -> 0 | I35: Haderslev | J35: 26.3 | K35: 0.95 | L35: 1.29 | M35: 12.7
C36: Dagpenge mv., SU og anden personlig indkomst, hvoraf der ikke skal betales AMB | I36: Halsnæs | J36: 25.7 | K36: 0.85 | L36: 0.69 | M36: 10.9
C37: Udbetalt pension mv., hvoraf der skal betales udligningsskat | I37: Hedensted | J37: 25.52 | K37: 0.98 | L37: 0.51 | M37: 7.9
C38: Bidrag og præmie til privattegnet pension med løbende udbetalinger og ratepension | I38: Helsingør | J38: 25.52 | K38: 0.63 | L38: 0.51 | M38: 9.5
I39: Herlev | J39: 23.7 | K39: 0.75 | L39: 0 | M39: 5.4
C40: Personlig indkomst i alt | E40: =E32-E33+E34-E35+E36+E37-E38 -> 485760 | F40: =F32-F33+F36+F37-F38 -> 0 | I40: Herning | J40: 25.4 | K40: 0.99 | L40: 0.39 | M40: 9.9
...

Sheet Skat. Nina
C1: 45291 | I1: Kommuneskatteprocenter | O1: Satser | R1: TRUE | S1: ja
C2: Skatteberegning 2024 | R2: FALSE | S2: nej
C3: Regnearket implementerer hovedreglerne i indkomstbeskatningen. Brug af dette regneark sker på eget ansvar. Der ydes ikke erstatning, såfremt brugen af regnearket giver anledning til, at der lides et tab. | I3: 2024 | O3: 2024
I4: Kommune | J4: Skatte | K4: Kirke | L4: Nedslag | M4: Grundskyld | O4: Arbejdsmarkedsbidragsprocent AMB § 1 | P4: 8
J5: pct. | K5: pct. | L5: pct. | M5: prm. | O5: Bundskatprocent PSL § 6, stk. 2 | P5: 12.06
C6: 1. Forskellige oplysninger | O6: Sundhedsbidragsprocent PSL § 8 | P6: 0
E7: Nina | I7: intet sommerhus | M7: 0 | O7: Topskatprocent PSL § 7, stk. 1 | P7: 15
C8: Gift ? | E8: nej | G8: =IF(E8=S1,TRUE,FALSE) -> FALSE | I8: Albertslund | J8: 25.6 | K8: 0.8 | L8: 0.59 | M8: 9.1 | O8: Topskatgrænse PSL § 7, stk. 2 | P8: 588900
C9: Under 18 år hele indkomståret ? | E9: nej | F9: nej | I9: Allerød | J9: 25.3 | K9: 0.58 | L9: 0.29 | M9: 8 | O9: Skatteloftprocent PSL § 19, stk. 1 | P9: 52.07
C10: Mere end 15 år til folkepensionsalderen ? | E10: ja | F10: ja | I10: Assens | J10: 26.1 | K10: 0.98 | L10: 1.09 | M10: 11.2 | O10: Skatteloftprocent positiv nettokapitalindkomst PSL § 19, stk. 2 | P10: 42
C11: Medlem af Folkekirken ? | E11: ja | F11: ja | I11: Ballerup | J11: 25.5 | K11: 0.72 | L11: 0.49 | M11: 8.3 | O11: Personfradrag unge PSL § 10, stk. 2 | P11: 39800
I12: Billund | J12: 24 | K12: 0.89 | L12: 0 | M12: 7.2 | O12: Personfradrag PSL § 10, stk. 1 | P12: 49700
C13: Bopælskommune pr. 5. september 2023 | E13: Lyngby-Taarbæk | I13: Bornholm | J13: 26.2 | K13: 0.93 | L13: 1.19 | M13: 10.7 | O13: Maksimalt kapitalpensionsfradrag PBL § 16, stk. 1 | P13: 0
C14: Kommuneskatteprocent | E14: =VLOOKUP(E13,I8:M105,2,FALSE) -> 24.38 | I14: Brøndby | J14: 24.3 | K14: 0.8 | L14: 0 | M14: 4.9 | O14: Bundfradrag positiv nettokapitalindkomst PSL § 7, stk. 1 | P14: 50500
C15: Kirkeskatteprocent | E15: =VLOOKUP(E13,I8:M105,3,FALSE) -> 0.6 | I15: Brønderslev | J15: 26.3 | K15: 1.08 | L15: 1.29 | M15: 17.1 | O15: Aktieskatprocent under grænse PSL § 8 a, stk. 1 | P15: 27
C16: Grundskyldspromille | E16: =VLOOKUP(E13,I7:M105,5,FALSE) -> 6.7 | I16: Dragør | J16: 24.8 | K16: 0.61 | L16: 0 | M16: 8.1 | O16: Aktieskatprocent over grænse PSL § 8 a, stk. 2 | P16: 42
I17: Egedal | J17: 25.7 | K17: 0.76 | L17: 0.69 | M17: 8.8 | O17: Grænse aktieskat PSL § 8 a, stk. 1 og 2 | P17: 61000
C18: Ejendomsværdi af enfamiliehus | I18: Esbjerg | J18: 25.8 | K18: 0.81 | L18: 0.79 | M18: 9.9 | O18: Bundgrænse lønmodtagerfradrag LL § 9, stk. 1 | P18: 7000
C19: Ejendomsværdi af ejerlejlighed | I19: Faaborg-Midtfyn | J19: 26.1 | K19: 1.05 | L19: 1.09 | M19: 8.5 | O19: Beskæftigelsesfradragsprocent LL § 9 J, stk. 2 | P19: 10.65
C20: Hus/ejerlejlighed erhvervet senest 1. juli 1998 ? | E20: nej | I20: Fanø | J20: 25.77 | K20: 1.14 | L20: 0.76 | M20: 12.5 | O20: Maksimalt beskæftigelsesfradrag LL § 9 J, stk. 2 | P20: 45100
C21: Grundværdi hus/ejerlejlighed | I21: Favrskov | J21: 25.7 | K21: 0.96 | L21: 0.69 | M21: 10.6 | O21: Ejendomsværdiskatteprocent under grænse | P21: 0.51
C22: Ejendomsværdi af sommerhus | I22: Faxe | J22: 25.8 | K22: 1.08 | L22: 0.79 | M22: 8 | O22: Ejendomsværdiskatteprocent over grænse | P22: 1.4
C23: Beliggenhed sommerhus | E23: Albertslund | I23: Fredensborg | J23: 25.3 | K23: 0.62 | L23: 0.29 | M23: 8.3 | O23: Grænse ejendomsværdiskat | P23: 9200000
C24: Grundskyldspromille | E24: =VLOOKUP(E23,I7:M105,5,FALSE) -> 9.1 | I24: Fredericia | J24: 25.5 | K24: 0.88 | L24: 0.49 | M24: 13 | O24: Nedslag ejendomsværdiskat ESL § 23, stk. 1 | P24: 0.1
C25: Grundværdi sommerhus | I25: Frederiksberg | J25: 24.57 | K25: 0.5 | L25: 0 | M25: 3.1 | O25: Nedslag ejendomsværdiskat ESL § 24, stk. 1 | P25: 0.21
C26: Sommerhus erhvervet senest 1. juli 1998 ? | E26: nej | I26: Frederikshavn | J26: 26.2 | K26: 1.03 | L26: 1.19 | M26: 13.4 | O26: Maksimalt nedslag efter ESL § 24, stk. 1 | P26: 1200
C27: Bidrag og præmie til arbejdsgiveradministreret pension med løbende udbetalinger og ratepension | E27: =E32*0.15 -> 88200 | I27: Frederikssund | J27: 25.8 | K27: 0.96 | L27: 0.79 | M27: 12 | O27: Nedslagsprocent negativ nettokapitalindkomst, PSL § 11, stk. 2 | P27: 8
I28: Furesø | J28: 24.88 | K28: 0.65 | L28: 0 | M28: 7 | O28: Bundfradrag udligningsskat, PSL § 7 a, stk. 4 | P28: 457500
C29: 2. Indkomst og fradrag | I29: Gentofte | J29: 24.34 | K29: 0.4 | L29: 0 | M29: 5.1 | O29: Udligningsskatteprocent, PSL § 7 a, stk. 5 | P29: 0
E30: Skatteyder | F30: =IF(E8=S1,"Ægtefælle","ugift") -> ugift | I30: Gladsaxe | J30: 23.6 | K30: 0.75 | L30: 0 | M30: 5.9 | O30: Overførbart bundfradrag udligningsskat, PSL § 7 a, stk. 6 | P30: 152600
C31: Personlig indkomst | I31: Glostrup | J31: 24.6 | K31: 0.8 | L31: 0 | M31: 6.5 | O31: Bundgrænse jobfradrag LL § 9 K, stk. 1 | P31: 216100
C32: Løn, honorarer mv. (før fradrag af AMB) | E32: =12*49000 -> 588000 | I32: Greve | J32: 24.52 | K32: 0.73 | L32: 0 | M32: 5.5 | O32: Jobfradragsprocent LL § 9 K, stk. 2 | P32: 4.5
C33: - reduceres med Arbejdsmarkedsbidrag (AMB) | E33: =E32*P4/100 -> 47040 | F33: =F32*P4/100 -> 0 | I33: Gribskov | J33: 25.4 | K33: 0.85 | L33: 0.39 | M33: 11.1 | O33: Maksimalt jobfradrag LL § 9 K, stk. 2 | P33: 2800
C34: Personlig indkomst fra selvstændig virksomhed | I34: Guldborgsund | J34: 25.8 | K34: 1.16 | L34: 0.79 | M34: 15.9 | O34: Maksimalt ekstra pensionsfradrag LL § 9 L | P34: 80600
C35: - reduceres med Arbejdsmarkedsbidrag (AMB) | E35: =MAX(0,E34*P4/100) -> 0 | I35: Haderslev | J35: 26.3 | K35: 0.95 | L35: 1.29 | M35: 12.7
C36: Dagpenge mv., SU og anden personlig indkomst, hvoraf der ikke skal betales AMB | I36: Halsnæs | J36: 25.7 | K36: 0.85 | L36: 0.69 | M36: 10.9
C37: Udbetalt pension mv., hvoraf der skal betales udligningsskat | I37: Hedensted | J37: 25.52 | K37: 0.98 | L37: 0.51 | M37: 7.9
C38: Bidrag og præmie til privattegnet pension med løbende udbetalinger og ratepension | I38: Helsingør | J38: 25.52 | K38: 0.63 | L38: 0.51 | M38: 9.5
I39: Herlev | J39: 23.7 | K39: 0.75 | L39: 0 | M39: 5.4
C40: Personlig indkomst i alt | E40: =E32-E33+E34-E35+E36+E37-E38 -> 540960 | F40: =F32-F33+F36+F37-F38 -> 0 | I40: Herning | J40: 25.4 | K40: 0.99 | L40: 0.39 | M40: 9.9
...

Sheet Realkredit

Sheet Boliglån
