Workbook
Name ArbBidrag: #REF!
Name ArbBidrag: #REF!
Name ArbBidrag: #REF!
Name ArbBidrag: #REF!
Name ArbBidrag: #REF!
Name ArbBidrag: #REF!
Name ArbBidrag: #REF!
Name ArbBidrag: #REF!
Name ArbBidrag: Skattesatser!$H$3
Name BeFradragHojSats: #REF!
Name BeFradragHojSats: #REF!
Name BeFradragHojSats: #REF!
Name BeFradragHojSats: #REF!
Name BeFradragHojSats: #REF!
Name BeFradragHojSats: #REF!
Name BeFradragHojSats: #REF!
Name BeFradragHojSats: #REF!
Name BeFradragHojSats: Skattesatser!$H$4
Name BeFradragKmMax: #REF!
Name BeFradragKmMax: #REF!
Name BeFradragKmMax: #REF!
Name BeFradragKmMax: #REF!
Name BeFradragKmMax: #REF!
Name BeFradragKmMax: #REF!
Name BeFradragKmMax: #REF!
Name BeFradragKmMax: #REF!
Name BeFradragKmMax: Skattesatser!$H$6
Name BeFradragKmMin: #REF!
Name BeFradragKmMin: #REF!
Name BeFradragKmMin: #REF!
Name BeFradragKmMin: #REF!
Name BeFradragKmMin: #REF!
Name BeFradragKmMin: #REF!
Name BeFradragKmMin: #REF!
Name BeFradragKmMin: #REF!
Name BeFradragKmMin: Skattesatser!$H$5
Name BeFradragLavSats: #REF!
Name BeFradragLavSats: #REF!
Name BeFradragLavSats: #REF!
Name BeFradragLavSats: #REF!
Name BeFradragLavSats: #REF!
Name BeFradragLavSats: #REF!
Name BeFradragLavSats: #REF!
Name BeFradragLavSats: #REF!
Name BeFradragLavSats: Skattesatser!$H$7
Name BFradragMax: #REF!
Name BFradragMax: #REF!
Name BFradragMax: #REF!
Name BFradragMax: #REF!
Name BFradragMax: #REF!
Name BFradragMax: #REF!
Name BFradragMax: #REF!
Name BFradragMax: #REF!
Name BFradragMax: Skattesatser!$H$10
Name BFradragProc: #REF!
Name BFradragProc: #REF!
Name BFradragProc: #REF!
Name BFradragProc: #REF!
Name BFradragProc: #REF!
Name BFradragProc: #REF!

Sheet Enlig skat før boligkøb
B1: Skatteberegningsprogram - enlig | C1: År 2025
C2: Person | I2: =C2 -> Person
B3: Privat indskud på ratepension (og ophørende livrente) | C3: 0 | I3: Beregnings-grundlag | J3: Beregnet skat
B4: Privat indskud på livrente | C4: 0 | F4: Beregning af skat | G4: Procent | H4: Fradrag
B5: Alder | C5: 30 | F5: Bundskat | G5: =Bundskat -> 0.1201 | H5: =Personfradrag -> 51600 | I5: =IF(C35>=0,C31+C35-H5,C31-H5) -> 408400 | J5: =+IF(I5>0,G5*I5,0) -> 49048.84
B6: Har fri telefon (ja/nej) | C6: nej | F6: Topskat | G6: =Topskat -> 0.15 | H6: =TopSkatGranse -> 611800 | I6: =MAX((C70-$H$6),0) -> 0 | J6: =G6*I6 -> 0
B7: Fagforening | C7: 0 | F7: Sundhedsbidrag | G7: =Sundhedsbidrag -> 0 | H7: =Personfradrag -> 51600 | I7: =($C$45+AB29)-(H7+AB43) -> 300338.4 | J7: =+IF(I7>0,I7*G7,0) -> 0
B8: A-kasse og efterløn | C8: 0 | F8: Kommuneskat | G8: =C13 -> 0.25 | H8: =Personfradrag -> 51600 | I8: =($C$45+AB29)-(H8+AB44) -> 300338.4 | J8: =+IF(I8>0,$C$13*I8,0) -> 75084.6
B9: Antal km til arbejde (tur/retur) | C9: 130 | F9: Kirkeskat | G9: =C14 -> 0.009 | H9: =Personfradrag -> 51600 | I9: =($C$45+AB29)-(H9+AB45) -> 300338.4 | J9: =+IF(I9>0,$C$14*I9,0) -> 2703.0456
B10: Antal arbejdsdage | C10: 220 | J10: =SUM(J5:J9) -> 126836.49
B11: Medlem af Folkekirken (ja/nej) | C11: ja
B12: Vælg Kommune | C12: Ishøj | F12: Evt skattetillæg af neg. KI under 50.000 | J12: =IF(C35>=0,0,IF(C35>=GranseNegKIEnlig,TillagNegKI*C35,TillagNegKI*GranseNegKIEnlig)) -> 0
B13: Kommuneskattesats | C13: =_xlfn.XLOOKUP(C12,Skattesatser!B6:B103,Skattesatser!C6:C103,2)/100 -> 0.25 | F13: Evt. nedslag i topskatten (lønindkomst) | I13: =IF($C$73>SkraatSkatteloftPI,$C$73-SkraatSkatteloftPI,0) -> 0 | J13: =-I13*C75 -> 0
B14: Kirkeskattesats | C14: =IF(C11="ja",_xlfn.XLOOKUP(C12,Skattesatser!B6:B103,Skattesatser!D6:D103,2)/100,0) -> 0.009 | F14: Evt. nedslag i topskatten (kapitalindkomst) | I14: =IF($C$73>SkraatSkatteloftKI,$C$73-SkraatSkatteloftKI,0) -> 0.1001 | J14: =-I14*C76 -> 0
B15: Grundskyldssats | C15: =_xlfn.XLOOKUP(C12,Skattesatser!B6:B103,Skattesatser!E6:E103,2)/1000 -> 0.0065 | J15: =SUM(J10:J14) -> 126836.49
B16: Ejendomsværdi (offentlig)
B17: Grundværdi (offentlig)
B18: Evt skatterabat (bolig købt før 1.jan.2024) | C18: 0 | F18: Indkomstskat i alt (incl. AM-bidrag) | J18: =J15+C27 -> 166836.49
F19: Ejendomsværdiskat | J19: =+F63 -> 0
B20: Lønindkomst (efter evt. ATP) | C20: 500000 | F20: Grundskyld | J20: =F64 -> 0
B21: arbejdsgiverpensionsordning % (kun eget indskud) | C21: 0 | F21: Skatterabat | J21: =-C18 -> 0
B22: - arbejdsgiverpensionsordning DKK (kun eget indskud) | C22: =C21*C20 -> 0
B23: + anden AM-pligtig indkomst | C23: 0 | F23: Skat i alt | J23: =SUM(J18:J21) -> 166836.49
B24: + fri telefon | C24: =IF(C6="ja",FriTelefon,0) -> 0
B25: = Beregningsgrundlag for AM-bidrag | C25: =C20-C22+C23+C24 -> 500000 | D25: BG 1
F26: Udbetalt efter skat | I26: =C2 -> Person
B27: - AM-bidrag | C27: =ArbBidrag*C25 -> 40000 | I27: Pr. år | J27: Pr. måned
B28: + Ikke AM-pligtig indkomst (SU, dagpenge, pension etc.) | C28: 0 | F28: Lønindkomst | I28: =C20+C23+C28 -> 500000 | J28: =I28/12 -> 41666.667
B29: - Eget indskud på ratepension (husk også at indtaste i budget) | C29: =IF(C3>RatepensionMax,RatepensionMax,C3) -> 0 | F29: - arbejdsgiver pensionsordning | I29: =C22 -> 0 | J29: =I29/12 -> 0
B30: - Eget indskud på livrente (husk også at indtaste i budget) | C30: =+C4 -> 0 | F30: - skat | I30: =J23 -> 166836.49 | J30: =I30/12 -> 13903.04
B31: = Personlig indkomst (PI) | C31: =C25-C27+C28-C29-C30 -> 460000 | D31: BG 2 | F31: Udbetalt efter skat | I31: =I28-I29-I30 -> 333163.51 | J31: =I31/12 -> 27763.626
B33: + Renteindtægter | C33: 0
B34: - Renteudgfter | C34: 0
B35: + Kapitalindkomst (KI) i alt | C35: =+C33-C34 -> 0
B37: Beskæftigelsesfradrag | C37: =MIN(+($C$25+$C$22*3)*BFradragProc,BFradragMax) -> 55600
B38: Jobfradrag | C38: =MAX(0,MIN(+($C$25+$C$22*3-Jfradraggranse)*Jfradragproc,JfradragMax)) -> 2900
B39: Ekstra pensionsfradrag | C39: =IF(C5<=52,MIN(+(C3+C4+C22*3)*EPENfradragProc,EPENfradragMax),MIN(+(C3+C4+C22*3)*EPENSeniorProc,EPENSeniorMax)) -> 0
B40: Fagforening, A-kasse og efterløn | C40: =IF(C7>FagforeningMax,FagforeningMax,C7)+C8 -> 0
B41: Befordring | C41: =+$H$56 -> 49561.6
B42: Andre ligningsmæssige fradrag | C42: 0
...

Sheet Ægtepar skat før boligkøb
B1: Skatteberegningsprogram - par | C1: År 2025
B2: Person 1, er den med højest indkomst | C2: Person 1 | D2: Person 2 | I2: =C2 -> Person 1 | K2: =D2 -> Person 2
B3: Privat indskud på ratepension (og ophørende livrente) | C3: 0 | D3: 0 | I3: Beregnings-grundlag | J3: Beregnet skat | K3: Beregnings-grundlag | L3: Beregnet skat
B4: Privat indskud på livrente | C4: 0 | D4: 0 | F4: Beregning af skat | G4: Procent | H4: Fradrag
B5: Alder | C5: 29 | D5: 27 | F5: Bundskat | G5: =Bundskat -> 0.1201 | H5: =Personfradrag -> 51600 | I5: =IF($AC$28=1,($C$31+$AC$29),$C$77)-($H$5+$AB$41) -> -100164 | J5: =+IF(I5>0,G5*I5,0) -> 0 | K5: =IF(AC28=1,(D31+AD29),$D$77)-H5 -> -51600 | L5: =+IF(K5>0,K5*G5,0) -> 0
B6: Har fri telefon (ja/nej) | C6: ja | D6: nej | F6: Topskat | G6: =Topskat -> 0.15 | H6: =TopSkatGranse -> 611800 | I6: =MAX((C78-$H$6),0) -> 0 | J6: =G6*I6 -> 0 | K6: =MAX((D77-$H$6),0) -> 0 | L6: =G6*K6 -> 0
B7: Fagforening | C7: 6000 | D7: 0 | F7: Sundhedsbidrag | G7: =Sundhedsbidrag -> 0 | H7: =Personfradrag -> 51600 | I7: =($C$45+AB29)-(H7+AB43) -> -106569.9 | J7: =+IF(I7>0,I7*G7,0) -> 0 | K7: =($D$45-AB29)-H7 -> -51600 | L7: =+IF(K7>0,G7*K7,0) -> 0
B8: A-kasse og efterløn | C8: 0 | D8: 0 | F8: Kommuneskat | G8: =C13 -> 0.2452 | H8: =Personfradrag -> 51600 | I8: =($C$45+AB29)-(H8+AB44) -> -106569.9 | J8: =+IF(I8>0,$C$13*I8,0) -> 0 | K8: =($D$45-AB29)-H8 -> -51600 | L8: =+IF(K8>0,$D$13*K8,0) -> 0
B9: Antal km til arbejde (tur/retur) | C9: 1 | D9: 0 | F9: Kirkeskat | G9: =C14 -> 0 | H9: =Personfradrag -> 51600 | I9: =($C$45+AB29)-(H9+AB45) -> -106569.9 | J9: =+IF(I9>0,$C$14*I9,0) -> 0 | K9: =($D$45-AB29)-H9 -> -51600 | L9: =+IF(K9>0,$D$14*K9,0) -> 0
B10: Antal arbejdsdage | C10: 216 | D10: 0 | J10: =SUM(J5:J9) -> 0 | L10: =SUM(L5:L9) -> 0
B11: Medlem af Folkekirken (ja/nej) | C11: nej | D11: nej
B12: Vælg Kommune | C12: Aarhus | D12: =C12 -> Aarhus | F12: Evt skattetillæg af neg. KI under 50.000 | J12: =IF(AA29>=0,0,IF(AA29>=GranseNegKIPar,TillagNegKI*AA29,TillagNegKI*GranseNegKIPar)) -> 0
B13: Kommuneskattesats | C13: =_xlfn.XLOOKUP(C12,Skattesatser!B6:B103,Skattesatser!C6:C103,2)/100 -> 0.2452 | D13: =_xlfn.XLOOKUP(D12,Skattesatser!B6:B103,Skattesatser!C6:C103,2)/100 -> 0.2452 | F13: Evt. nedslag i topskatten (lønindkomst) | I13: =IF($C$81>SkraatSkatteloftPI,$C$81-SkraatSkatteloftPI,0) -> 0 | J13: =-I13*C83 -> 0 | K13: =IF($D$81>SkraatSkatteloftPI,$D$81-SkraatSkatteloftPI,0) -> 0 | L13: =-K13*D83 -> 0
B14: Kirkeskattesats | C14: =IF(C11="ja",_xlfn.XLOOKUP(C12,Skattesatser!B6:B103,Skattesatser!D6:D103,2)/100,0) -> 0 | D14: =IF(D11="ja",_xlfn.XLOOKUP(D12,Skattesatser!B6:B103,Skattesatser!D6:D103,2)/100,0) -> 0 | F14: Evt. nedslag i topskatten (kapitalindkomst) | I14: =IF($C$81>SkraatSkatteloftKI,$C$81-SkraatSkatteloftKI,0) -> 0.0953 | J14: =-I14*C84 -> 0
B15: Grundskyldssats | C15: =_xlfn.XLOOKUP(C12,Skattesatser!B6:B103,Skattesatser!E6:E103,2)/1000 -> 0.006 | J15: =SUM(J10:J14) -> 0 | L15: =SUM(L10:L14) -> 0
B16: Ejendomsværdi (offentlig) | C16: 0
B17: Grundværdi (offentlig) | C17: 0
B18: Evt skatterabat (bolig købt før 1.jan.2024) | C18: 0 | F18: Indkomstskat i alt (incl. AM-bidrag) | J18: =J15+C27 -> 264 | L18: =L15+D27 -> 0
F19: Ejendomsværdiskat | J19: =+F71/2 -> 0 | L19: =J19 -> 0
B20: Lønindkomst (efter evt. ATP) | C20: 0 | D20: 0 | F20: Grundskyld | J20: =F72/2 -> 0 | L20: =J20 -> 0
B21: arbejdsgiverpensionsordning % (kun eget indskud) | C21: 0 | D21: 0 | F21: Skatterabat | J21: =-C18/2 -> 0 | L21: =J21 -> 0
B22: - arbejdsgiverpensionsordning DKK (kun eget indskud) | C22: =C21*C20 -> 0 | D22: =D21*D20 -> 0
B23: + anden AM-pligtig indkomst | C23: 0 | D23: 0 | F23: Skat i alt | J23: =SUM(J18:J22) -> 264 | L23: =SUM(L18:L22) -> 0
B24: + fri telefon | C24: =IF(C6="ja",FriTelefon,0) -> 3300 | D24: =IF(D6="ja",FriTelefon,0) -> 0
B25: = Beregningsgrundlag for AM-bidrag | C25: =C20-C22+C23+C24 -> 3300 | D25: =D20-D22+D23+D24 -> 0
F26: Udbetalt efter skat | I26: =C2 -> Person 1 | K26: =D2 -> Person 2 | AB26: Uudnyttet | AC26: Udligning af KI til brug for bundskat
B27: - AM-bidrag | C27: =ArbBidrag*C25 -> 264 | D27: =ArbBidrag*D25 -> 0 | I27: Pr. år | J27: Pr. måned | K27: Pr. år | L27: Pr. måned | AB27: KI | AC27: P1 | AD27: P2
B28: + Ikke AM-pligtig indkomst (SU, dagpenge, pension etc.) | C28: 0 | D28: 0 | F28: Lønindkomst | I28: =C20+C23+C28 -> 0 | J28: =I28/12 -> 0 | K28: =D20+D23+D28 -> 0 | L28: =K28/12 -> 0 | AB28: person 2 | AC28: =IF(AA29<0,0,IF((C35+0.00000001)*(D35+0.0000001)<0,1,0)) -> 0
B29: - Eget indskud på ratepension (husk også at indtaste i budget) | C29: =IF(C3>RatepensionMax,RatepensionMax,C3) -> 0 | D29: =IF(D3>RatepensionMax,RatepensionMax,D3) -> 0 | F29: - arbejdsgiver pensionsordning | I29: =C22 -> 0 | J29: =I29/12 -> 0 | K29: =D22 -> 0 | L29: =K29/12 -> 0 | AA29: =SUM(C35:D35) -> 0 | AB29: =IF(D45<0,IF(D31-D43<0,D35,D35+D31-D43),0) -> 0 | AC29: =IF(AC28=1,C35+D35,0) -> 0 | AD29: =IF(AC28=1,0,D35) -> 0
B30: - Eget indskud på livrente (husk også at indtaste i budget) | C30: =+C4 -> 0 | D30: =+D4 -> 0 | F30: - skat | I30: =J23 -> 264 | J30: =I30/12 -> 22 | K30: =L23 -> 0 | L30: =K30/12 -> 0
B31: = Personlig indkomst (PI) | C31: =C25-C27+C28-C29-C30 -> 3036 | D31: =D25-D27+D28-D29-D30 -> 0 | F31: Udbetalt efter skat | I31: =I28-I29-I30 -> -264 | J31: =I31/12 -> -22 | K31: =K28-K29-K30 -> 0 | L31: =K31/12 -> 0
B33: + Renteindtægter | C33: 0 | D33: 0
B34: - Renteudgfter | C34: 0 | D34: 0
B35: + Kapitalindkomst (KI) i alt | C35: =+C33-C34 -> 0 | D35: =+D33-D34 -> 0
B37: Beskæftigelsesfradrag | C37: =MIN(+(C25+C22*3)*BFradragProc,BFradragMax) -> 405.9 | D37: =MIN(+(D25+D22*3)*BFradragProc,BFradragMax) -> 0
B38: Jobfradrag | C38: =MAX(0,MIN(+($C$25+C22*3-Jfradraggranse)*Jfradragproc,JfradragMax)) -> 0 | D38: =MAX(0,MIN(+($D$25+D22*3-Jfradraggranse)*Jfradragproc,JfradragMax)) -> 0 | AB38: Uudnyttet
B39: Ekstra pensionsfradrag | C39: =IF(C5<=52,MIN(+(C3+C4+C22*3)*EPENfradragProc,EPENfradragMax),MIN(+(C3+C4+C22*3)*EPENSeniorProc,EPENSeniorMax)) -> 0 | D39: =IF(D5<=52,MIN(+(D3+D4+D22*3)*EPENfradragProc,EPENfradragMax),MIN(+(D3+D4+D22*3)*EPENSeniorProc,EPENSeniorMax)) -> 0 | AB39: fradrag
B40: Fagforening, A-kasse og efterløn | C40: =IF(C7>FagforeningMax,FagforeningMax,C7)+C8 -> 6000 | D40: =IF(D7>FagforeningMax,FagforeningMax,D7)+D8 -> 0 | AB40: person 2
B41: Befordring | C41: =+$H$56 -> 0 | D41: =H65 -> 0 | AB41: =IF(D77>H5,0,H5-D77) -> 51600
B42: Andre ligningsmæssige fradrag | C42: 0 | D42: 0
...

Sheet Budget før boligkøb
A1: Privatbudget - Par
A3: Indtægter | B3: jan | C3: feb | D3: mar | E3: apr | F3: maj | G3: juni | H3: juli | I3: aug | J3: sept | K3: okt | L3: nov | M3: dec | N3: TOTAL
A4: Løn, efter skat | B4: 25342.574 | C4: =B4 -> 25342.574 | D4: =C4 -> 25342.574 | E4: =D4 -> 25342.574 | F4: =E4 -> 25342.574 | G4: =F4 -> 25342.574 | H4: =G4 -> 25342.574 | I4: =H4 -> 25342.574 | J4: =I4 -> 25342.574 | ... M4: =L4 -> 25342.574 | N4: =SUM(B4:M4) -> 304110.88
A5: Løn, efter skat | B5: ='Ægtepar skat før boligkøb'!L31 -> 0 | C5: =B5 -> 0 | D5: =C5 -> 0 | E5: =D5 -> 0 | F5: =E5 -> 0 | G5: =F5 -> 0 | H5: =G5 -> 0 | I5: =H5 -> 0 | J5: =I5 -> 0 | ... M5: =L5 -> 0 | N5: =SUM(B5:M5) -> 0
A6: Renter/udbytte | B6: 10000 | C6: 0 | D6: 0 | E6: 0 | F6: 0 | G6: 0 | H6: 0 | I6: 0 | J6: 0 | K6: 0 | L6: 0 | M6: 0 | N6: =SUM(B6:M6) -> 10000
A7: Børne- og ungeydelse | B7: 0 | C7: 0 | D7: 0 | E7: =B7 -> 0 | F7: 0 | G7: 0 | H7: =E7 -> 0 | I7: 0 | J7: 0 | K7: =H7 -> 0 | L7: 0 | M7: 0 | N7: =SUM(B7:M7) -> 0
A8: Børnebidrag | B8: 0 | C8: 0 | D8: 0 | E8: 0 | F8: 0 | G8: 0 | H8: 0 | I8: 0 | J8: 0 | K8: 0 | L8: 0 | M8: 0 | N8: =SUM(B8:M8) -> 0
A9: Børnetilskud | B9: 0 | C9: 0 | D9: 0 | E9: 0 | F9: 0 | G9: 0 | H9: 0 | I9: 0 | J9: 0 | K9: 0 | L9: 0 | M9: 0 | N9: =SUM(B9:M9) -> 0
A10: Indtægter i alt | B10: =SUM(B4:B9) -> 35342.574 | C10: =SUM(C4:C9) -> 25342.574 | D10: =SUM(D4:D9) -> 25342.574 | E10: =SUM(E4:E9) -> 25342.574 | F10: =SUM(F4:F9) -> 25342.574 | G10: =SUM(G4:G9) -> 25342.574 | H10: =SUM(H4:H9) -> 25342.574 | I10: =SUM(I4:I9) -> 25342.574 | ... M10: =SUM(M4:M9) -> 25342.574 | N10: =SUM(B10:M10) -> 314110.88
A13: Udgifter | B13: jan | C13: feb | D13: mar | E13: apr | F13: maj | G13: juni | H13: juli | I13: aug | J13: sept | K13: okt | L13: nov | M13: dec | N13: TOTAL
A14: Bolig
A15: Husleje | B15: 0 | C15: =B15 -> 0 | D15: =C15 -> 0 | E15: =D15 -> 0 | F15: =E15 -> 0 | G15: =F15 -> 0 | H15: =G15 -> 0 | I15: =H15 -> 0 | J15: =I15 -> 0 | ... M15: =L15 -> 0 | N15: =SUM(B15:M15) -> 0
A16: Banklån, ydelse efter skat | B16: 0 | C16: =B16 -> 0 | D16: =C16 -> 0 | E16: =D16 -> 0 | F16: =E16 -> 0 | G16: =F16 -> 0 | H16: =G16 -> 0 | I16: =H16 -> 0 | J16: =I16 -> 0 | ... M16: =L16 -> 0 | N16: =SUM(B16:M16) -> 0
A17: Renovation | B17: 0 | C17: 0 | D17: 0 | E17: 0 | F17: 0 | G17: 0 | H17: 0 | I17: 0 | J17: 0 | K17: 0 | L17: 0 | M17: 0 | N17: =SUM(B17:M17) -> 0
A18: Varme | B18: 0 | C18: 0 | D18: 0 | E18: 0 | F18: 0 | G18: 0 | H18: 0 | I18: 0 | J18: 0 | K18: 0 | L18: 0 | M18: 0 | N18: =SUM(B18:M18) -> 0
A19: Elektricitet | B19: 0 | C19: 0 | D19: 0 | F19: 0 | G19: 0 | I19: 0 | J19: 0 | L19: 0 | M19: 0 | N19: =SUM(B19:M19) -> 0
A20: Vand | B20: 0 | C20: 0 | D20: 0 | E20: 0 | F20: 0 | G20: 0 | H20: 0 | I20: 0 | J20: 0 | K20: 0 | L20: 0 | M20: 0 | N20: =SUM(B20:M20) -> 0
A21: Ejendomsskatter | B21: 0 | C21: 0 | D21: 0 | E21: 0 | F21: 0 | G21: 0 | H21: 0 | I21: 0 | J21: 0 | K21: 0 | L21: 0 | M21: 0 | N21: =SUM(B21:M21) -> 0
A22: Fællesudgifter | B22: 0 | C22: =B22 -> 0 | D22: =C22 -> 0 | E22: =D22 -> 0 | F22: =E22 -> 0 | G22: =F22 -> 0 | H22: =G22 -> 0 | I22: =H22 -> 0 | J22: =I22 -> 0 | ... M22: =L22 -> 0 | N22: =SUM(B22:M22) -> 0
A23: Grundejerforening | B23: 0 | C23: 0 | D23: 0 | E23: 0 | F23: 0 | G23: 0 | H23: 0 | I23: 0 | J23: 0 | K23: 0 | L23: 0 | M23: 0 | N23: =SUM(B23:M23) -> 0
A24: Vedligeholdelse | B24: 0 | C24: 0 | D24: 0 | E24: 0 | F24: 0 | G24: 0 | H24: 0 | I24: 0 | J24: 0 | K24: 0 | L24: 0 | M24: 0 | N24: =SUM(B24:M24) -> 0
A25: Hus forsikring | B25: 0 | C25: 0 | D25: 0 | E25: 0 | F25: 0 | G25: 0 | H25: 0 | I25: 0 | J25: 0 | K25: 0 | L25: 0 | M25: 0 | N25: =SUM(B25:M25) -> 0
A26: Diverse | B26: 0 | C26: 0 | D26: 0 | E26: 0 | F26: 0 | G26: 0 | H26: 0 | I26: 0 | J26: 0 | K26: 0 | L26: 0 | M26: 0 | N26: =SUM(B26:M26) -> 0
A27: Bolig i alt | B27: =SUM(B15:B26) -> 0 | C27: =SUM(C15:C26) -> 0 | D27: =SUM(D15:D26) -> 0 | E27: =SUM(E15:E26) -> 0 | F27: =SUM(F15:F26) -> 0 | G27: =SUM(G15:G26) -> 0 | H27: =SUM(H15:H26) -> 0 | I27: =SUM(I15:I26) -> 0 | ... N27: =SUM(N15:N26) -> 0
A29: Bil
A30: Forsikring | B30: 0 | C30: 0 | D30: 0 | E30: 0 | F30: 0 | G30: 0 | H30: 0 | I30: 0 | J30: 0 | K30: 0 | L30: 0 | M30: 0 | N30: =SUM(B30:M30) -> 0
A31: Vægtafgift | B31: 0 | C31: 0 | D31: 0 | E31: 0 | F31: 0 | G31: 0 | H31: 0 | I31: 0 | J31: 0 | K31: 0 | L31: 0 | M31: 0 | N31: =SUM(B31:M31) -> 0
A32: Benzin | B32: 0 | C32: =B32 -> 0 | D32: =C32 -> 0 | E32: =D32 -> 0 | F32: =E32 -> 0 | G32: =F32 -> 0 | H32: =G32 -> 0 | I32: =H32 -> 0 | J32: =I32 -> 0 | ... M32: =L32 -> 0 | N32: =SUM(B32:M32) -> 0
A33: FDM | B33: 0 | C33: 0 | D33: 0 | E33: 0 | F33: 0 | G33: 0 | H33: 0 | I33: 0 | J33: 0 | K33: 0 | L33: 0 | M33: 0 | N33: =SUM(B33:M33) -> 0
A34: Billån | B34: 0 | C34: =B34 -> 0 | D34: =C34 -> 0 | E34: =D34 -> 0 | F34: =E34 -> 0 | G34: =F34 -> 0 | H34: =G34 -> 0 | I34: =H34 -> 0 | J34: =I34 -> 0 | ... M34: =L34 -> 0 | N34: =SUM(B34:M34) -> 0
A35: Vedligehold/reparation | B35: 0 | C35: 0 | D35: 0 | E35: 0 | F35: 0 | G35: 0 | H35: 0 | I35: 0 | J35: 0 | K35: 0 | L35: 0 | M35: 0 | N35: =SUM(B35:M35) -> 0
A36: Biludgifter i alt | B36: =SUM(B30:B35) -> 0 | C36: =SUM(C30:C35) -> 0 | D36: =SUM(D30:D35) -> 0 | E36: =SUM(E30:E35) -> 0 | F36: =SUM(F30:F35) -> 0 | G36: =SUM(G30:G35) -> 0 | H36: =SUM(H30:H35) -> 0 | I36: =SUM(I30:I35) -> 0 | ... M36: =SUM(M30:M35) -> 0 | N36: =SUM(B36:M36) -> 0
A38: Transport øvrig
A39: Offentlig transport | B39: 0 | C39: =B39 -> 0 | D39: =C39 -> 0 | E39: =D39 -> 0 | F39: =E39 -> 0 | G39: =F39 -> 0 | H39: =G39 -> 0 | I39: =H39 -> 0 | J39: =I39 -> 0 | ... M39: =L39 -> 0 | N39: =SUM(B39:M39) -> 0
A40: Diverse | B40: 0 | C40: 0 | D40: 0 | E40: 0 | F40: 0 | G40: 0 | H40: 0 | I40: 0 | J40: 0 | K40: 0 | L40: 0 | M40: 0 | N40: =SUM(B40:M40) -> 0
A41: Transport i alt | B41: =SUM(B39:B40) -> 0 | C41: =SUM(C39:C40) -> 0 | D41: =SUM(D39:D40) -> 0 | E41: =SUM(E39:E40) -> 0 | F41: =SUM(F39:F40) -> 0 | G41: =SUM(G39:G40) -> 0 | H41: =SUM(H39:H40) -> 0 | I41: =SUM(I39:I40) -> 0 | ... M41: =SUM(M39:M40) -> 0 | N41: =SUM(B41:M41) -> 0
A43: Kommunikation/TV
A44: Fastnettelefon | B44: 0 | C44: =B44 -> 0 | D44: =C44 -> 0 | E44: =D44 -> 0 | F44: =E44 -> 0 | G44: =F44 -> 0 | H44: =G44 -> 0 | I44: =H44 -> 0 | J44: =I44 -> 0 | ... M44: =L44 -> 0 | N44: =SUM(B44:M44) -> 0
A45: Mobiltelefon | B45: 0 | C45: =B45 -> 0 | D45: =C45 -> 0 | E45: =D45 -> 0 | F45: =E45 -> 0 | G45: =F45 -> 0 | H45: =G45 -> 0 | I45: =H45 -> 0 | J45: =I45 -> 0 | ... M45: =L45 -> 0 | N45: =SUM(B45:M45) -> 0
A46: Internet | B46: 0 | C46: =B46 -> 0 | D46: =C46 -> 0 | E46: =D46 -> 0 | F46: =E46 -> 0 | G46: =F46 -> 0 | H46: =G46 -> 0 | I46: =H46 -> 0 | J46: =I46 -> 0 | ... M46: =L46 -> 0 | N46: =SUM(B46:M46) -> 0
...

Sheet Skattesatser
B3: Kommuneskattesatser 2025 | G3: Arbejdsmarkedsbidrag | H3: 0.08
G4: Befordringsfradrag høje sats | H4: 2.23
B5: Kommunenavn | C5: Kommune | D5: Kirke | E5: Grundskyld (promille) | G5: Befordringsfradrag min km for høj sats | H5: 24
B6: Albertslund | C6: 25.6 | D6: 0.8 | E6: 9.1 | G6: Befordringsfradrag max km for høj sats | H6: 120
B7: Allerød | C7: 25.3 | D7: 0.58 | E7: 8 | G7: Befordringsfradrag lave sats | H7: 1.12
B8: Assens | C8: 26.1 | D8: 0.98 | E8: 11.2 | G8: Befordringsfradrag Indtægtsgrænse for forhøjet (før AM-bidrag) | H8: 325800
B9: Ballerup | C9: 25.5 | D9: 0.75 | E9: 8.3 | G9: Beskæftigelsesfradrag (%) | H9: 0.123
B10: Billund | C10: 24 | D10: 0.89 | E10: 7.2 | G10: Beskæftigelsesfradrag (max) | H10: 55600
B11: Bornholm | C11: 26.2 | D11: 0 | E11: 10.7 | G11: Bundskat | H11: 0.1201
B12: Brøndby | C12: 24.3 | D12: 0.8 | E12: 4.9 | G12: Ejendomsværdiskat - lave sats | H12: 0.0051
B13: Brønderslev | C13: 26.3 | D13: 1.06 | E13: 17.1 | G13: Ejendomsværdiskat - høje sats | H13: 0.014
B14: Dragør | C14: 24.8 | D14: 0.61 | E14: 8.1 | G14: Ejendomsværdiskat - skillegrænse | H14: 11500000
B15: Egedal | C15: 25.7 | D15: 0.76 | E15: 8.8 | G15: Ekstra pensionsfradrag (%) | H15: 0.12
B16: Esbjerg | C16: 26.1 | D16: 0.81 | E16: 9.9 | G16: Ekstra pensionsfradrag (max) | H16: 10056
B17: Fanø | C17: 26.1 | D17: 1.05 | E17: 8.5 | G17: Ekstra pensionsfradrag (%) Senior | H17: 0.32
... B25: Furesø | C25: 24.88 | D25: 0.96 | E25: 12 | G25: Grøn check | H25: 0
B26: Faaborg-Midtfyn | C26: 26.1 | D26: 0.65 | E26: 7 | G26: Grøn check modregning Start
B27: Gentofte | C27: 24.24 | D27: 0.39 | E27: 5.1 | G27: Grøn check modregning Slut
B28: Gladsaxe | C28: 23.6 | D28: 0.75 | E28: 5.9 | G28: Grøn check modregning Sats
B29: Glostrup | C29: 24.6 | D29: 0.8 | E29: 6.5 | G29: Jobfradrag (%) | H29: 0.045
B30: Greve | C30: 24.59 | D30: 0.81 | E30: 5.5 | G30: Jobfradraggrænse | H30: 224500
B31: Gribskov | C31: 25.4 | D31: 0.85 | E31: 11.1 | G31: Jobfradrag (max) | H31: 2900
B32: Guldborgsund | C32: 25.8 | D32: 1.16 | E32: 15.9 | G32: Kapitalindkomstgrænse til Topskat Par | H32: 104800
B33: Haderslev | C33: 26.3 | D33: 0.95 | E33: 12.7 | G33: Kapitalindkomstgrænse til Topskat Enlig | H33: 52400
B34: Halsnæs | C34: 25.7 | D34: 0.85 | E34: 10.9 | G34: Personfradrag | H34: 51600
B35: Hedensted | C35: 25.52 | D35: 0.98 | E35: 7.9 | G35: Personfradrag topskat | H35: 611800
B36: Helsingør | C36: 25.82 | D36: 0.63 | E36: 9.5 | G36: Ratepension Max indskud | H36: 65500
B37: Herlev | C37: 23.7 | D37: 0.75 | E37: 5.4 | G37: Skrå Skatteloft - personlig indkomst | H37: 0.5207
B38: Herning | C38: 25.4 | D38: 0.99 | E38: 9.9 | G38: Skrå Skatteloft - kapitalindkomst | H38: 0.42
B39: Hillerød | C39: 25.6 | D39: 0.69 | E39: 6.6 | G39: Sundhedsbidrag | H39: 0
B40: Hjørring | C40: 26.21 | D40: 1.19 | E40: 16.5 | G40: Tillæg for negativ kapitalindkomst procent | H40: 0.08
... B43: Horsens | C43: 25.69 | D43: 0.79 | E43: 8.7 | G43: Topskat | H43: 0.15
B44: Hvidovre | C44: 25.4 | D44: 0.72 | E44: 6.5
B45: Høje-Taastrup | C45: 24.6 | D45: 0.8 | E45: 6.3
B46: Hørsholm | C46: 23.7 | D46: 0.62 | E46: 8.5
B47: Ikast-Brande | C47: 25.1 | D47: 0.97 | E47: 9.1
B48: Ishøj | C48: 25 | D48: 0.9 | E48: 6.5
B49: Jammerbugt | C49: 25.7 | D49: 1.2 | E49: 13.2
B50: Kalundborg | C50: 24.2 | D50: 1.01 | E50: 16.6
B51: Kerteminde | C51: 26.1 | D51: 0.98 | E51: 12.4
...

Sheet Hvordan finansieres boligen
A2: Hvordan skal boligen finansieres? | G2: Hvordan anvendes pengene?
A5: Kontantpris på boligen | D5: kr. | E5: 6995000 | G5: Sælger skal have | J5: kr. | K5: =E5 -> 6995000
G7: Hvor kommer pengene fra:
A8: Realkreditlån, maks. 80% | D8: kr. | E8: 3000000 | F8: 0.8
A9: Hvad kommer kunden med | D9: kr. | E9: 500000 | G9: Provenu fra realkreditlån | J9: kr. | K9: ='Realkredit finansiering'!E7 -> 2937329.6 | L9: Tinglysning - Låneomkostninger, realkredit er trukket fra
A10: - op af "lommen penge": | G10: Provenu fra banklån | J10: kr. | K10: =IF(K18>0,Banklån!D16,0) -> 0 | L10: Tinglysning - Låneomkostninger, banklån er trukket fra
B11: Skøde | E11: =0.6%*E5+1850 -> 43820 | G11: Egne midler | J11: kr. | K11: =E15 -> 424430
B12: Advokat, anslået | E12: 5000
B13: Halv ejerskifteforsikring | E13: 6750 | G13: I alt | J13: kr. | K13: =K9+K10+K11 -> 3361759.6
B14: Flytteomkostninger/renovering og andet | E14: 20000
A15: Egen udbetaling, min. 5% | E15: =E9-E11-E12-E13-E14 -> 424430 | F15: =E15/E5 -> 0.060676197
G16: Mangler | J16: kr. | K16: =K13-K5 -> -3633240.4 | L16: Skal altid være 0
A17: Restfinansiering (minus = overskud) | D17: kr. | E17: =E5-E8-E15 -> 3570570 | F17: =E17/E5 -> 0.51044603
F18: =F8+F15+F17 -> 1.3711222 | G18: Banklån inkl. omkostninger | K18: 0
A20: Låneomkostninger
A22: Tinglysning - Låneomkostninger, realkredit | D22: kr. | E22: ='Realkredit finansiering'!B9 -> 62670.361
A23: Tinglysning - Låneomkostninger, banklån | D23: kr. | E23: =IF(K18>0,Banklån!D14,0) -> 0
A25: Låneomkostninger i alt | E25: =E22+E23 -> 62670.361
A28: Fremgangsmåde:
A30: 1) Start altid med at udfylde rente og kurs i fanebladet "Realkreditfinansiering" og rente i "Banklån"
A31: 2) Slet altid E8 og K18 inden start
A32: 2) Indtast boligens kontantpris (E5)
A33: 3) Indtast hvor mange penge kunden kommer med (E9)
A34: 4) Indtast ejerskifteforsikring (E13) og flytteomkostninger m.m. (E14)
A38: Er restfinansiering (E17) nu under 80%: | H38: Er restfinansiering (E17) nu over 80%:
A39: 1) Indtast realkreditlånet (E8) med det beløb som fremgår af E17 | H39: 1) Indtast realkreditlånet (E8) som 80% af kontantprisen
A40: 2) Lav en målsøgning så "Mangler" (K16) bliver 0 ved ændring af celle E8 | H40: 2) Lav en målsøgning så "Mangler" (K16) bliver 0 ved ændring af celle K18
A44: Hvis realkreditlånet (E8) bliver mere end 80%:
A45: 1) Gå til "Er restfinansiering (E17) nu over 80%"

Sheet Banklån
D4: Banklån til finasiering af boligen
B6: Lånets størrelse (hovedstol) | D6: ='Hvordan finansieres boligen'!K18 -> 0 | E6: jf. ark "Hvordan finansieres huset…"
B7: Løbetid,år | D7: 30 | E7: en bolig kan godt finansieres over 30 år
B8: Antal terminer pr år | D8: 12
B9: Rente pr år | D9: 0.05 | E9: (tjek rentesatsen på bankernes hjemmesider under bank boliglån - det er ikke et realkreditlån)
B11: Etableringsomkostninger:
B12: Tinglysning af pant | D12: =1825+1.45%*D6 -> 1825
B13: Bankens etableringsomk. | D13: 5690 | E13: (nordea's dokumentgebyr og vurderingsgebyr)
B14: Etableringsomkostninger i alt | D14: =D12+D13 -> 7515
B16: Provenu (hvad får jeg i hånden) | D16: =D6-D14 -> -7515
B19: Ydelse pr termin før skat | D19: =PMT(D9/D8,D7*D8,D6) -> 0
B20: Renteudgifter år 1 | D20: =-CUMIPMT(D9/D8,D8*D7,D6,1,D8,0) -> #NUM!
B21: Skattefar betaler 1/3 af renteudgifterne | D21: =1/3*D20 -> #NUM!
B22: Ydelse pr. termin efter skat | D22: =D19+(D21/D8) -> #NUM! | E22: = Den der anvendes i budgettet, medmindre du skriver renteudgiften ind i skattebegningen
B24: Omkostninger i procent pr termin | D24: =RATE(D7*D8,D19,D16) -> #NUM!
B25: ÅOP | D25: =(1+D24)^D8-1 -> #NUM!

Sheet Realkredit finansiering
D1: Lånetype | E1: Fastforrentet med afdrag | F1: Rentetilpasning med afdrag F5 | G1: Fastforrentet 10 års afdragsfrihed | H1: Rentetilpasning uden afdrag F1
A2: Husets pris | B2: 4000000 | C2: Belåningsgrad (max.80%)
A3: Lånebeløb | B3: ='Hvordan finansieres boligen'!E8 -> 3000000 | C3: 0.8 | D3: Obligationshovedstol | E3: =E5/E4*100 -> 3092783.5 | F3: =F5/F4*100 -> 3000000 | G3: =G5/G4*100 -> 3015075.4 | H3: =H5/H4*100 -> 3000000
D4: kurs på obligation | E4: 97 | F4: 100 | G4: 99.5 | H4: 100
A5: Låneomkostninger ved optagelse af realkreditlån: | D5: Kursværdi | E5: =B3 -> 3000000 | F5: =B3 -> 3000000 | G5: =B3 -> 3000000 | H5: =B3 -> 3000000
A6: Tinglysning af pant | B6: =1.45%*E3+1825 -> 46670.361 | D6: - lånekostninger | E6: =B9 -> 62670.361 | F6: =E6 -> 62670.361 | G6: =F6 -> 62670.361 | H6: =G6 -> 62670.361
A7: Etableringsomkostninger Realkreditinstitut | B7: 10000 | D7: Låneprovenu (det jeg får i hånden) | E7: =E5-E6 -> 2937329.6 | F7: =F5-F6 -> 2937329.6 | G7: =G5-G6 -> 2937329.6 | H7: =H5-H6 -> 2937329.6
A8: Kurtage/kursskæring, 0,2 pct. | B8: =0.2%*B3 -> 6000
A9: I alt | B9: =SUM(B6:B8) -> 62670.361 | D9: Pålydende rente | E9: 0.035 | F9: 0.026 | G9: 0.04 | H9: 0.024292
D10: Bidragssats | E10: 0.006812 | F10: 0.008564 | G10: =E10+0.002752 -> 0.009564 | H10: =0.008564+0.002752 -> 0.011316
D11: Rente + bidragssats | E11: =E10+E9 -> 0.041812 | F11: =F10+F9 -> 0.034564 | G11: =G10+G9 -> 0.049564 | H11: =H10+H9 -> 0.035608
D12: Løbetid, år | E12: 30 | F12: 30 | G12: 30 | H12: 30
D13: Terminer pr. år | E13: 12 | F13: =E13 -> 12 | G13: =F13 -> 12 | H13: =G13 -> 12
D14: Antal terminer i alt | E14: =E13*E12 -> 360 | F14: =F13*F12 -> 360 | G14: =G13*G12 -> 360 | H14: =H13*H12 -> 360
D16: Ydelse pr. termin | E16: =-PMT(E9/E13,E14,E3) -> 13887.98 | F16: =-PMT(F9/F13,F14,F5) -> 12010.191 | G16: =G3*G9/G13 -> 10050.251 | H16: =H5*H9/H13 -> 6073
D17: Ydelse pr. år | E17: =E16*E13 -> 166655.76 | F17: =F16*F13 -> 144122.3 | G17: =G16*G13 -> 120603.02 | H17: =H16*H13 -> 72876
D18: Bidrag 1.år | E18: {=SUMPRODUCT(FV(E9/E13, ROW(INDIRECT("1:" & E13))-1, PMT(E9/E13, E14, -E3, 0, 0), -E3, 0)) * E10/E13} -> 20883.896 | F18: {=SUMPRODUCT(FV(F9/F13, ROW(INDIRECT("1:" & F13))-1, PMT(F9/F13, F14, -F3, 0, 0), -F3, 0)) * F10/F13} -> 25430.575 | G18: =G3*G10/G13*G13 -> 28836.181 | H18: =H5*H10/H13*H13 -> 33948
D19: Bruttoydelse 1.år | E19: =SUM(E17:E18) -> 187539.66 | F19: =SUM(F17:F18) -> 169552.87 | G19: =SUM(G17:G18) -> 149439.2 | H19: =SUM(H17:H18) -> 106824
D21: Akkumuleret rente 1.år | E21: =-CUMIPMT(E9/E13,E14,E3,1,E13,0) -> 107301.29 | F21: =-CUMIPMT(F9/F13,F14,F3,1,F13,0) -> 77206.324 | G21: =G17 -> 120603.02 | H21: =H17 -> 72876
D22: Afdrag på gæld 1.år | E22: =-CUMPRINC(E9/E13,E14,E3,1,1*E13,0) -> 59354.474 | F22: =F17-F21 -> 66915.972 | G22: 0 | H22: 0
D24: Nettoydelse 1.år | E24: =E19-1/3*(E18+E21) -> 144811.26 | F24: =F19-1/3*(F18+F21) -> 135340.57 | G24: =G19-1/3*(G18+G21) -> 99626.131 | H24: =H19-1/3*(H18+H21) -> 71216
D25: Nettoydelse pr. termin (1.år) | E25: =E24/E13 -> 12067.605 | F25: =F24/F13 -> 11278.381 | G25: =G24/G13 -> 8302.1776 | H25: =H24/H13 -> 5934.6667
D27: Bruttoydelse pr. måned (gnsn) | E27: =E19/12 -> 15628.305 | F27: =F19/12 -> 14129.406 | G27: =G19/12 -> 12453.266 | H27: =H19/12 -> 8902
D28: Nettoydelse pr. måned (gnsn) | E28: =E24/12 -> 12067.605 | F28: =F24/12 -> 11278.381 | G28: =G24/12 -> 8302.1776 | H28: =H24/12 -> 5934.6667

Sheet F5
A1: Termin | B1: Restgæld | C1: Rente | D1: Afdrag | E1: Ydelse | F1: Bidrag | G1: Brutto- ydelse
A3: 0 | B3: ='Realkredit finansiering'!F5 -> 3000000
A4: 1 | B4: =B3-D4 -> 2994489.8 | C4: ='Realkredit finansiering'!$F$9/'Realkredit finansiering'!$F$13*'F5'!B3 -> 6500 | D4: =E4-C4 -> 5510.1913 | E4: ='Realkredit finansiering'!$F$16 -> 12010.191 | F4: ='Realkredit finansiering'!$F$10/'Realkredit finansiering'!$F$13*'F5'!B3 -> 2141 | G4: =E4+F4 -> 14151.191
A5: 2 | B5: =B4-D5 -> 2988967.7 | C5: ='Realkredit finansiering'!$F$9/'Realkredit finansiering'!$F$13*'F5'!B4 -> 6488.0613 | D5: =E5-C5 -> 5522.1301 | E5: ='Realkredit finansiering'!$F$16 -> 12010.191 | F5: ='Realkredit finansiering'!$F$10/'Realkredit finansiering'!$F$13*'F5'!B4 -> 2137.0676 | G5: =E5+F5 -> 14147.259
A6: 3 | B6: =B5-D6 -> 2983433.6 | C6: ='Realkredit finansiering'!$F$9/'Realkredit finansiering'!$F$13*'F5'!B5 -> 6476.0966 | D6: =E6-C6 -> 5534.0947 | E6: ='Realkredit finansiering'!$F$16 -> 12010.191 | F6: ='Realkredit finansiering'!$F$10/'Realkredit finansiering'!$F$13*'F5'!B5 -> 2133.1266 | G6: =E6+F6 -> 14143.318
A7: 4 | B7: =B6-D7 -> 2977887.5 | C7: ='Realkredit finansiering'!$F$9/'Realkredit finansiering'!$F$13*'F5'!B6 -> 6464.1061 | D7: =E7-C7 -> 5546.0852 | E7: ='Realkredit finansiering'!$F$16 -> 12010.191 | F7: ='Realkredit finansiering'!$F$10/'Realkredit finansiering'!$F$13*'F5'!B6 -> 2129.1771 | G7: =E7+F7 -> 14139.368
A8: 5 | B8: =B7-D8 -> 2972329.4 | C8: ='Realkredit finansiering'!$F$9/'Realkredit finansiering'!$F$13*'F5'!B7 -> 6452.0896 | D8: =E8-C8 -> 5558.1018 | E8: ='Realkredit finansiering'!$F$16 -> 12010.191 | F8: ='Realkredit finansiering'!$F$10/'Realkredit finansiering'!$F$13*'F5'!B7 -> 2125.219 | G8: =E8+F8 -> 14135.41
A9: 6 | B9: =B8-D9 -> 2966759.3 | C9: ='Realkredit finansiering'!$F$9/'Realkredit finansiering'!$F$13*'F5'!B8 -> 6440.047 | D9: =E9-C9 -> 5570.1443 | E9: ='Realkredit finansiering'!$F$16 -> 12010.191 | F9: ='Realkredit finansiering'!$F$10/'Realkredit finansiering'!$F$13*'F5'!B8 -> 2121.2524 | G9: =E9+F9 -> 14131.444
A10: 7 | B10: =B9-D10 -> 2961177 | C10: ='Realkredit finansiering'!$F$9/'Realkredit finansiering'!$F$13*'F5'!B9 -> 6427.9784 | D10: =E10-C10 -> 5582.213 | E10: ='Realkredit finansiering'!$F$16 -> 12010.191 | F10: ='Realkredit finansiering'!$F$10/'Realkredit finansiering'!$F$13*'F5'!B9 -> 2117.2772 | G10: =E10+F10 -> 14127.469
A11: 8 | B11: =B10-D11 -> 2955582.7 | C11: ='Realkredit finansiering'!$F$9/'Realkredit finansiering'!$F$13*'F5'!B10 -> 6415.8836 | D11: =E11-C11 -> 5594.3078 | E11: ='Realkredit finansiering'!$F$16 -> 12010.191 | F11: ='Realkredit finansiering'!$F$10/'Realkredit finansiering'!$F$13*'F5'!B10 -> 2113.2933 | G11: =E11+F11 -> 14123.485
A12: 9 | B12: =B11-D12 -> 2949976.3 | C12: ='Realkredit finansiering'!$F$9/'Realkredit finansiering'!$F$13*'F5'!B11 -> 6403.7626 | D12: =E12-C12 -> 5606.4288 | E12: ='Realkredit finansiering'!$F$16 -> 12010.191 | F12: ='Realkredit finansiering'!$F$10/'Realkredit finansiering'!$F$13*'F5'!B11 -> 2109.3009 | G12: =E12+F12 -> 14119.492
A13: 10 | B13: =B12-D13 -> 2944357.7 | C13: ='Realkredit finansiering'!$F$9/'Realkredit finansiering'!$F$13*'F5'!B12 -> 6391.6153 | D13: =E13-C13 -> 5618.576 | E13: ='Realkredit finansiering'!$F$16 -> 12010.191 | F13: ='Realkredit finansiering'!$F$10/'Realkredit finansiering'!$F$13*'F5'!B12 -> 2105.2998 | G13: =E13+F13 -> 14115.491
A14: 11 | B14: =B13-D14 -> 2938727 | C14: ='Realkredit finansiering'!$F$9/'Realkredit finansiering'!$F$13*'F5'!B13 -> 6379.4417 | D14: =E14-C14 -> 5630.7496 | E14: ='Realkredit finansiering'!$F$16 -> 12010.191 | F14: ='Realkredit finansiering'!$F$10/'Realkredit finansiering'!$F$13*'F5'!B13 -> 2101.29 | G14: =E14+F14 -> 14111.481
A15: 12 | B15: =B14-D15 -> 2933084 | C15: ='Realkredit finansiering'!$F$9/'Realkredit finansiering'!$F$13*'F5'!B14 -> 6367.2418 | D15: =E15-C15 -> 5642.9496 | E15: ='Realkredit finansiering'!$F$16 -> 12010.191 | F15: ='Realkredit finansiering'!$F$10/'Realkredit finansiering'!$F$13*'F5'!B14 -> 2097.2715 | G15: =E15+F15 -> 14107.463
... A123: 120 | B123: =B122-D123 -> 2245785.3 | C123: ='Realkredit finansiering'!$F$9/'Realkredit finansiering'!$F$13*'F5'!B122 -> 4881.314 | D123: =E123-C123 -> 7128.8773 | E123: ='Realkredit finansiering'!$F$16 -> 12010.191 | F123: ='Realkredit finansiering'!$F$10/'Realkredit finansiering'!$F$13*'F5'!B122 -> 1607.8297 | G123: =E123+F123 -> 13618.021

Sheet Enlig skat efter boligkøb
B1: Skatteberegningsprogram - enlig | C1: År 2025
C2: Person | I2: =C2 -> Person
B3: Privat indskud på ratepension (og ophørende livrente) | C3: 0 | I3: Beregnings-grundlag | J3: Beregnet skat
B4: Privat indskud på livrente | C4: 0 | F4: Beregning af skat | G4: Procent | H4: Fradrag
B5: Alder | C5: 0 | F5: Bundskat | G5: =Bundskat -> 0.1201 | H5: =Personfradrag -> 51600 | I5: =IF(C35>=0,C31+C35-H5,C31-H5) -> -51600 | J5: =+IF(I5>0,G5*I5,0) -> 0
B6: Har fri telefon (ja/nej) | C6: nej | F6: Topskat | G6: =Topskat -> 0.15 | H6: =TopSkatGranse -> 611800 | I6: =MAX((C70-$H$6),0) -> 0 | J6: =G6*I6 -> 0
B7: Fagforening | C7: 0 | F7: Sundhedsbidrag | G7: =Sundhedsbidrag -> 0 | H7: =Personfradrag -> 51600 | I7: =($C$45+AB29)-(H7+AB43) -> -51600 | J7: =+IF(I7>0,I7*G7,0) -> 0
B8: A-kasse og efterløn | C8: 0 | F8: Kommuneskat | G8: =C13 -> 0.256 | H8: =Personfradrag -> 51600 | I8: =($C$45+AB29)-(H8+AB44) -> -51600 | J8: =+IF(I8>0,$C$13*I8,0) -> 0
B9: Antal km til arbejde (tur/retur) | C9: 0 | F9: Kirkeskat | G9: =C14 -> 0 | H9: =Personfradrag -> 51600 | I9: =($C$45+AB29)-(H9+AB45) -> -51600 | J9: =+IF(I9>0,$C$14*I9,0) -> 0
B10: Antal arbejdsdage | C10: 0 | J10: =SUM(J5:J9) -> 0
B11: Medlem af Folkekirken (ja/nej) | C11: nej
B12: Vælg Kommune | C12: Albertslund | F12: Evt skattetillæg af neg. KI under 50.000 | J12: =IF(C35>=0,0,IF(C35>=GranseNegKIEnlig,TillagNegKI*C35,TillagNegKI*GranseNegKIEnlig)) -> 0
B13: Kommuneskattesats | C13: =VLOOKUP($C$12,Skattesatser!$B$6:$E$103,2)/100 -> 0.256 | F13: Evt. nedslag i topskatten (lønindkomst) | I13: =IF($C$73>SkraatSkatteloftPI,$C$73-SkraatSkatteloftPI,0) -> 0.0054 | J13: =-I13*C75 -> 0
B14: Kirkeskattesats | C14: =IF(C11="ja",VLOOKUP($C$12,Skattesatser!$B$6:$E$103,3)/100,0) -> 0 | F14: Evt. nedslag i topskatten (kapitalindkomst) | I14: =IF($C$73>SkraatSkatteloftKI,$C$73-SkraatSkatteloftKI,0) -> 0.1061 | J14: =-I14*C76 -> 0
B15: Grundskyldssats | C15: =VLOOKUP($C$12,Skattesatser!$B$6:$E$103,4)/1000 -> 0.0091 | J15: =SUM(J10:J14) -> 0
B16: Ejendomsværdi (offentlig) | C16: 0
B17: Grundværdi (offentlig) | C17: 0
B18: Evt skatterabat (bolig købt før 1.jan.2024) | C18: 0 | F18: Indkomstskat i alt (incl. AM-bidrag) | J18: =J15+C27 -> 0
F19: Ejendomsværdiskat | J19: =+F63 -> 0
B20: Lønindkomst (efter evt. ATP) | C20: 0 | F20: Grundskyld | J20: =F64 -> 0
B21: arbejdsgiverpensionsordning % (kun eget indskud) | C21: 0 | F21: Skatterabat | J21: =-C18 -> 0
B22: - arbejdsgiverpensionsordning DKK (kun eget indskud) | C22: =C21*C20 -> 0
B23: + anden AM-pligtig indkomst | C23: 0 | F23: Skat i alt | J23: =SUM(J18:J21) -> 0
B24: + fri telefon | C24: =IF(C6="ja",FriTelefon,0) -> 0
B25: = Beregningsgrundlag for AM-bidrag | C25: =C20-C22+C23+C24 -> 0
F26: Udbetalt efter skat | I26: =C2 -> Person
B27: - AM-bidrag | C27: =ArbBidrag*C25 -> 0 | I27: Pr. år | J27: Pr. måned
B28: + Ikke AM-pligtig indkomst (SU, dagpenge, pension etc.) | C28: 0 | F28: Lønindkomst | I28: =C20+C23+C28 -> 0 | J28: =I28/12 -> 0
B29: - Eget indskud på ratepension (husk også at indtaste i budget) | C29: =IF(C3>RatepensionMax,RatepensionMax,C3) -> 0 | F29: - arbejdsgiver pensionsordning | I29: =C22 -> 0 | J29: =I29/12 -> 0
B30: - Eget indskud på livrente (husk også at indtaste i budget) | C30: =+C4 -> 0 | F30: - skat | I30: =J23 -> 0 | J30: =I30/12 -> 0
B31: = Personlig indkomst (PI) | C31: =C25-C27+C28-C29-C30 -> 0 | F31: Udbetalt efter skat | I31: =I28-I29-I30 -> 0 | J31: =I31/12 -> 0
B33: + Renteindtægter | C33: 0
B34: - Renteudgfter | C34: 0
B35: + Kapitalindkomst (KI) i alt | C35: =+C33-C34 -> 0
B37: Beskæftigelsesfradrag | C37: =MIN(+($C$25+$C$22*3)*BFradragProc,BFradragMax) -> 0
B38: Jobfradrag | C38: =MAX(0,MIN(+($C$25+$C$22*3-Jfradraggranse)*Jfradragproc,JfradragMax)) -> 0
B39: Ekstra pensionsfradrag | C39: =IF(C5<=52,MIN(+(C3+C4+C22*3)*EPENfradragProc,EPENfradragMax),MIN(+(C3+C4+C22*3)*EPENSeniorProc,EPENSeniorMax)) -> 0
B40: Fagforening, A-kasse og efterløn | C40: =IF(C7>FagforeningMax,FagforeningMax,C7)+C8 -> 0
B41: Befordring | C41: =+$H$56 -> 0
B42: Andre ligningsmæssige fradrag | C42: 0
...

Sheet Ægtepar skat efter boligkøb
B1: Skatteberegningsprogram - par | C1: År 2025
B2: Person 1, er den med højest indkomst | C2: Person 1 | D2: Person 2 | I2: =C2 -> Person 1 | K2: =D2 -> Person 2
B3: Privat indskud på ratepension (og ophørende livrente) | C3: 0 | D3: 0 | I3: Beregnings-grundlag | J3: Beregnet skat | K3: Beregnings-grundlag | L3: Beregnet skat
B4: Privat indskud på livrente | C4: 0 | D4: 0 | F4: Beregning af skat | G4: Procent | H4: Fradrag
B5: Alder | C5: 0 | D5: 0 | F5: Bundskat | G5: =Bundskat -> 0.1201 | H5: =Personfradrag -> 51600 | I5: =IF($AC$28=1,($C$31+$AC$29),$C$77)-($H$5+$AB$41) -> -103200 | J5: =+IF(I5>0,G5*I5,0) -> 0 | K5: =IF(AC28=1,(D31+AD29),$D$77)-H5 -> -51600 | L5: =+IF(K5>0,K5*G5,0) -> 0
B6: Har fri telefon (ja/nej) | C6: nej | D6: nej | F6: Topskat | G6: =Topskat -> 0.15 | H6: =TopSkatGranse -> 611800 | I6: =MAX((C78-$H$6),0) -> 0 | J6: =G6*I6 -> 0 | K6: =MAX((D77-$H$6),0) -> 0 | L6: =G6*K6 -> 0
B7: Fagforening | C7: 0 | D7: 0 | F7: Sundhedsbidrag | G7: =Sundhedsbidrag -> 0 | H7: =Personfradrag -> 51600 | I7: =($C$45+AB29)-(H7+AB43) -> -103200 | J7: =+IF(I7>0,I7*G7,0) -> 0 | K7: =($D$45-AB29)-H7 -> -51600 | L7: =+IF(K7>0,G7*K7,0) -> 0
B8: A-kasse og efterløn | C8: 0 | D8: 0 | F8: Kommuneskat | G8: =C13 -> 0.256 | H8: =Personfradrag -> 51600 | I8: =($C$45+AB29)-(H8+AB44) -> -103200 | J8: =+IF(I8>0,$C$13*I8,0) -> 0 | K8: =($D$45-AB29)-H8 -> -51600 | L8: =+IF(K8>0,$D$13*K8,0) -> 0
B9: Antal km til arbejde (tur/retur) | C9: 0 | D9: 0 | F9: Kirkeskat | G9: =C14 -> 0 | H9: =Personfradrag -> 51600 | I9: =($C$45+AB29)-(H9+AB45) -> -103200 | J9: =+IF(I9>0,$C$14*I9,0) -> 0 | K9: =($D$45-AB29)-H9 -> -51600 | L9: =+IF(K9>0,$D$14*K9,0) -> 0
B10: Antal arbejdsdage | C10: 0 | D10: 0 | J10: =SUM(J5:J9) -> 0 | L10: =SUM(L5:L9) -> 0
B11: Medlem af Folkekirken (ja/nej) | C11: nej | D11: nej
B12: Vælg Kommune | C12: Albertslund | D12: =C12 -> Albertslund | F12: Evt skattetillæg af neg. KI under 50.000 | J12: =IF(AA29>=0,0,IF(AA29>=GranseNegKIPar,TillagNegKI*AA29,TillagNegKI*GranseNegKIPar)) -> 0
B13: Kommuneskattesats | C13: =VLOOKUP($C$12,Skattesatser!$B$6:$E$103,2)/100 -> 0.256 | D13: =VLOOKUP($D$12,Skattesatser!$B$6:$E$103,2)/100 -> 0.256 | F13: Evt. nedslag i topskatten (lønindkomst) | I13: =IF($C$81>SkraatSkatteloftPI,$C$81-SkraatSkatteloftPI,0) -> 0.0054 | J13: =-I13*C83 -> 0 | K13: =IF($D$81>SkraatSkatteloftPI,$D$81-SkraatSkatteloftPI,0) -> 0.0054 | L13: =-K13*D83 -> 0
B14: Kirkeskattesats | C14: =IF(C11="ja",VLOOKUP($C$12,Skattesatser!$B$6:$E$103,3)/100,0) -> 0 | D14: =IF(D11="ja",VLOOKUP($C$12,Skattesatser!$B$6:$E$103,3)/100,0) -> 0 | F14: Evt. nedslag i topskatten (kapitalindkomst) | I14: =IF($C$81>SkraatSkatteloftKI,$C$81-SkraatSkatteloftKI,0) -> 0.1061 | J14: =-I14*C84 -> 0
B15: Grundskyldssats | C15: =VLOOKUP($C$12,Skattesatser!$B$6:$E$103,4)/1000 -> 0.0091 | J15: =SUM(J10:J14) -> 0 | L15: =SUM(L10:L14) -> 0
B16: Ejendomsværdi (offentlig) | C16: 0
B17: Grundværdi (offentlig) | C17: 0
B18: Evt skatterabat (bolig købt før 1.jan.2024) | C18: 0 | F18: Indkomstskat i alt (incl. AM-bidrag) | J18: =J15+C27 -> 0 | L18: =L15+D27 -> 0
F19: Ejendomsværdiskat | J19: =+F71/2 -> 0 | L19: =J19 -> 0
B20: Lønindkomst (efter evt. ATP) | C20: 0 | D20: 0 | F20: Grundskyld | J20: =F72/2 -> 0 | L20: =J20 -> 0
B21: arbejdsgiverpensionsordning % (kun eget indskud) | C21: 0 | D21: 0 | F21: Skatterabat | J21: =-C18/2 -> 0 | L21: =J21 -> 0
B22: - arbejdsgiverpensionsordning DKK (kun eget indskud) | C22: =C21*C20 -> 0 | D22: =D21*D20 -> 0
B23: + anden AM-pligtig indkomst | C23: 0 | D23: 0 | F23: Skat i alt | J23: =SUM(J18:J22) -> 0 | L23: =SUM(L18:L22) -> 0
B24: + fri telefon | C24: =IF(C6="ja",FriTelefon,0) -> 0 | D24: =IF(D6="ja",FriTelefon,0) -> 0
B25: = Beregningsgrundlag for AM-bidrag | C25: =C20-C22+C23+C24 -> 0 | D25: =D20-D22+D23+D24 -> 0
F26: Udbetalt efter skat | I26: =C2 -> Person 1 | K26: =D2 -> Person 2 | AB26: Uudnyttet | AC26: Udligning af KI til brug for bundskat
B27: - AM-bidrag | C27: =ArbBidrag*C25 -> 0 | D27: =ArbBidrag*D25 -> 0 | I27: Pr. år | J27: Pr. måned | K27: Pr. år | L27: Pr. måned | AB27: KI | AC27: P1 | AD27: P2
B28: + Ikke AM-pligtig indkomst (SU, dagpenge, pension etc.) | C28: 0 | D28: 0 | F28: Lønindkomst | I28: =C20+C23+C28 -> 0 | J28: =I28/12 -> 0 | K28: =D20+D23+D28 -> 0 | L28: =K28/12 -> 0 | AB28: person 2 | AC28: =IF(AA29<0,0,IF((C35+0.00000001)*(D35+0.0000001)<0,1,0)) -> 0
B29: - Eget indskud på ratepension (husk også at indtaste i budget) | C29: =IF(C3>RatepensionMax,RatepensionMax,C3) -> 0 | D29: =IF(D3>RatepensionMax,RatepensionMax,D3) -> 0 | F29: - arbejdsgiver pensionsordning | I29: =C22 -> 0 | J29: =I29/12 -> 0 | K29: =D22 -> 0 | L29: =K29/12 -> 0 | AA29: =SUM(C35:D35) -> 0 | AB29: =IF(D45<0,IF(D31-D43<0,D35,D35+D31-D43),0) -> 0 | AC29: =IF(AC28=1,C35+D35,0) -> 0 | AD29: =IF(AC28=1,0,D35) -> 0
B30: - Eget indskud på livrente (husk også at indtaste i budget) | C30: =+C4 -> 0 | D30: =+D4 -> 0 | F30: - skat | I30: =J23 -> 0 | J30: =I30/12 -> 0 | K30: =L23 -> 0 | L30: =K30/12 -> 0
B31: = Personlig indkomst (PI) | C31: =C25-C27+C28-C29-C30 -> 0 | D31: =D25-D27+D28-D29-D30 -> 0 | F31: Udbetalt efter skat | I31: =I28-I29-I30 -> 0 | J31: =I31/12 -> 0 | K31: =K28-K29-K30 -> 0 | L31: =K31/12 -> 0
B33: + Renteindtægter | C33: 0 | D33: 0
B34: - Renteudgfter | C34: 0 | D34: 0
B35: + Kapitalindkomst (KI) i alt | C35: =+C33-C34 -> 0 | D35: =+D33-D34 -> 0
B37: Beskæftigelsesfradrag | C37: =MIN(+(C25+C22*3)*BFradragProc,BFradragMax) -> 0 | D37: =MIN(+(D25+D22*3)*BFradragProc,BFradragMax) -> 0
B38: Jobfradrag | C38: =MAX(0,MIN(+($C$25+C22*3-Jfradraggranse)*Jfradragproc,JfradragMax)) -> 0 | D38: =MAX(0,MIN(+($D$25+D22*3-Jfradraggranse)*Jfradragproc,JfradragMax)) -> 0 | AB38: Uudnyttet
B39: Ekstra pensionsfradrag | C39: =IF(C5<=52,MIN(+(C3+C4+C22*3)*EPENfradragProc,EPENfradragMax),MIN(+(C3+C4+C22*3)*EPENSeniorProc,EPENSeniorMax)) -> 0 | D39: =IF(D5<=52,MIN(+(D3+D4+D22*3)*EPENfradragProc,EPENfradragMax),MIN(+(D3+D4+D22*3)*EPENSeniorProc,EPENSeniorMax)) -> 0 | AB39: fradrag
B40: Fagforening, A-kasse og efterløn | C40: =IF(C7>FagforeningMax,FagforeningMax,C7)+C8 -> 0 | D40: =IF(D7>FagforeningMax,FagforeningMax,D7)+D8 -> 0 | AB40: person 2
B41: Befordring | C41: =+$H$56 -> 0 | D41: =H65 -> 0 | AB41: =IF(D77>H5,0,H5-D77) -> 51600
B42: Andre ligningsmæssige fradrag | C42: 0 | D42: 0
...

Sheet Budget efter boligkøb
A1: Privatbudget - Par
A3: Indtægter | B3: jan | C3: feb | D3: mar | E3: apr | F3: maj | G3: juni | H3: juli | I3: aug | J3: sept | K3: okt | L3: nov | M3: dec | N3: TOTAL
A4: Løn, efter skat | B4: ='Ægtepar skat efter boligkøb'!J31 -> 0 | C4: =B4 -> 0 | D4: =C4 -> 0 | E4: =D4 -> 0 | F4: =E4 -> 0 | G4: =F4 -> 0 | H4: =G4 -> 0 | I4: =H4 -> 0 | J4: =I4 -> 0 | ... M4: =L4 -> 0 | N4: =SUM(B4:M4) -> 0
A5: Løn, efter skat | B5: ='Ægtepar skat efter boligkøb'!L31 -> 0 | C5: =B5 -> 0 | D5: =C5 -> 0 | E5: =D5 -> 0 | F5: =E5 -> 0 | G5: =F5 -> 0 | H5: =G5 -> 0 | I5: =H5 -> 0 | J5: =I5 -> 0 | ... M5: =L5 -> 0 | N5: =SUM(B5:M5) -> 0
A6: Renter/udbytte | B6: 0 | C6: 0 | D6: 0 | E6: 0 | F6: 0 | G6: 0 | H6: 0 | I6: 0 | J6: 0 | K6: 0 | L6: 0 | M6: 0 | N6: =SUM(B6:M6) -> 0
A7: Børne- og ungeydelse | C7: 0 | D7: 0 | E7: =B7 -> 0 | F7: 0 | G7: 0 | H7: =E7 -> 0 | I7: 0 | J7: 0 | K7: =H7 -> 0 | L7: 0 | M7: 0 | N7: =SUM(B7:M7) -> 0
A8: Børnebidrag | B8: 0 | C8: 0 | D8: 0 | E8: 0 | F8: 0 | G8: 0 | H8: 0 | I8: 0 | J8: 0 | K8: 0 | L8: 0 | M8: 0 | N8: =SUM(B8:M8) -> 0
A9: Børnetilskud | B9: 0 | C9: 0 | D9: 0 | E9: 0 | F9: 0 | G9: 0 | H9: 0 | I9: 0 | J9: 0 | K9: 0 | L9: 0 | M9: 0 | N9: =SUM(B9:M9) -> 0
A10: Indtægter i alt | B10: =SUM(B4:B9) -> 0 | C10: =SUM(C4:C9) -> 0 | D10: =SUM(D4:D9) -> 0 | E10: =SUM(E4:E9) -> 0 | F10: =SUM(F4:F9) -> 0 | G10: =SUM(G4:G9) -> 0 | H10: =SUM(H4:H9) -> 0 | I10: =SUM(I4:I9) -> 0 | ... M10: =SUM(M4:M9) -> 0 | N10: =SUM(B10:M10) -> 0
A13: Udgifter | B13: jan | C13: feb | D13: mar | E13: apr | F13: maj | G13: juni | H13: juli | I13: aug | J13: sept | K13: okt | L13: nov | M13: dec | N13: TOTAL
A14: Bolig
A15: Realkreditlån, ydelse efter skat | B15: ='Realkredit finansiering'!E28 -> 12067.605 | C15: =B15 -> 12067.605 | D15: =C15 -> 12067.605 | E15: =D15 -> 12067.605 | F15: =E15 -> 12067.605 | G15: =F15 -> 12067.605 | H15: =G15 -> 12067.605 | I15: =H15 -> 12067.605 | J15: =I15 -> 12067.605 | ... M15: =L15 -> 12067.605 | N15: =SUM(B15:M15) -> 144811.26 | O15: Hvis der ikke er realkreditlån skrives nul
A16: Banklån, ydelse efter skat | B16: =-Banklån!D22 -> #NUM! | C16: =B16 -> #NUM! | D16: =C16 -> #NUM! | E16: =D16 -> #NUM! | F16: =E16 -> #NUM! | G16: =F16 -> #NUM! | H16: =G16 -> #NUM! | I16: =H16 -> #NUM! | J16: =I16 -> #NUM! | ... M16: =L16 -> #NUM! | N16: =SUM(B16:M16) -> #NUM! | O16: Hvis der ikke er banklån skrives nul
A17: Renovation | B17: 0 | C17: 0 | D17: 0 | E17: 0 | F17: 0 | G17: 0 | H17: 0 | I17: 0 | J17: 0 | K17: 0 | L17: 0 | M17: 0 | N17: =SUM(B17:M17) -> 0
A18: Varme | B18: 0 | C18: =B18 -> 0 | D18: =C18 -> 0 | E18: =D18 -> 0 | F18: =E18 -> 0 | G18: =F18 -> 0 | H18: =G18 -> 0 | I18: =H18 -> 0 | J18: =I18 -> 0 | ... M18: =L18 -> 0 | N18: =SUM(B18:M18) -> 0
A19: Elektricitet | B19: 0 | C19: 0 | D19: 0 | E19: 0 | F19: 0 | G19: 0 | H19: 0 | I19: 0 | J19: 0 | K19: 0 | L19: 0 | M19: 0 | N19: =SUM(B19:M19) -> 0
A20: Vand | B20: 0 | C20: =B20 -> 0 | D20: =C20 -> 0 | E20: =D20 -> 0 | F20: =E20 -> 0 | G20: =F20 -> 0 | H20: =G20 -> 0 | I20: =H20 -> 0 | J20: =I20 -> 0 | ... M20: =L20 -> 0 | N20: =SUM(B20:M20) -> 0
A21: Ejendomsskatter | B21: 0 | C21: 0 | D21: 0 | E21: 0 | F21: 0 | G21: 0 | H21: 0 | I21: 0 | J21: 0 | K21: 0 | L21: 0 | M21: 0 | N21: =SUM(B21:M21) -> 0
A22: Fællesudgifter | B22: 0 | C22: =B22 -> 0 | D22: =C22 -> 0 | E22: =D22 -> 0 | F22: =E22 -> 0 | G22: =F22 -> 0 | H22: =G22 -> 0 | I22: =H22 -> 0 | J22: =I22 -> 0 | ... M22: =L22 -> 0 | N22: =SUM(B22:M22) -> 0
A23: Grundejerforening | B23: 0 | C23: 0 | D23: 0 | E23: 0 | F23: 0 | G23: 0 | H23: 0 | I23: 0 | J23: 0 | K23: 0 | L23: 0 | M23: 0 | N23: =SUM(B23:M23) -> 0
A24: Vedligeholdelse | B24: 0 | C24: =B24 -> 0 | D24: =C24 -> 0 | E24: =D24 -> 0 | F24: =E24 -> 0 | G24: =F24 -> 0 | H24: =G24 -> 0 | I24: =H24 -> 0 | J24: =I24 -> 0 | ... M24: =L24 -> 0 | N24: =SUM(B24:M24) -> 0
A25: Hus forsikring | B25: 0 | C25: 0 | D25: 0 | E25: 0 | F25: 0 | G25: 0 | H25: 0 | I25: 0 | J25: 0 | K25: 0 | L25: 0 | M25: 0 | N25: =SUM(B25:M25) -> 0
A26: Ejerudgift | B26: 0 | C26: =B26 -> 0 | D26: =C26 -> 0 | E26: =D26 -> 0 | F26: =E26 -> 0 | G26: =F26 -> 0 | H26: =G26 -> 0 | I26: =H26 -> 0 | J26: =I26 -> 0 | ... M26: =L26 -> 0 | N26: =SUM(B26:M26) -> 0
A27: Bolig i alt | B27: =SUM(B15:B26) -> #NUM! | C27: =SUM(C15:C26) -> #NUM! | D27: =SUM(D15:D26) -> #NUM! | E27: =SUM(E15:E26) -> #NUM! | F27: =SUM(F15:F26) -> #NUM! | G27: =SUM(G15:G26) -> #NUM! | H27: =SUM(H15:H26) -> #NUM! | I27: =SUM(I15:I26) -> #NUM! | ... N27: =SUM(N15:N26) -> #NUM!
A29: Bil
A30: Forsikring | B30: 0 | C30: 0 | D30: 0 | E30: 0 | F30: 0 | G30: 0 | H30: 0 | I30: 0 | J30: 0 | K30: 0 | L30: 0 | M30: 0 | N30: =SUM(B30:M30) -> 0
A31: Vægtafgift | B31: 0 | C31: 0 | D31: 0 | E31: 0 | F31: 0 | G31: 0 | H31: 0 | I31: 0 | J31: 0 | K31: 0 | L31: 0 | M31: 0 | N31: =SUM(B31:M31) -> 0
A32: Benzin | B32: 0 | C32: =B32 -> 0 | D32: =C32 -> 0 | E32: =D32 -> 0 | F32: =E32 -> 0 | G32: =F32 -> 0 | H32: =G32 -> 0 | I32: =H32 -> 0 | J32: =I32 -> 0 | ... M32: =L32 -> 0 | N32: =SUM(B32:M32) -> 0
A33: FDM | B33: 0 | C33: 0 | D33: 0 | E33: 0 | F33: 0 | G33: 0 | H33: 0 | I33: 0 | J33: 0 | K33: 0 | L33: 0 | M33: 0 | N33: =SUM(B33:M33) -> 0
A34: Billån | B34: 0 | C34: =B34 -> 0 | D34: =C34 -> 0 | E34: =D34 -> 0 | F34: =E34 -> 0 | G34: =F34 -> 0 | H34: =G34 -> 0 | I34: =H34 -> 0 | J34: =I34 -> 0 | ... M34: =L34 -> 0 | N34: =SUM(B34:M34) -> 0
A35: Vedligehold/reparation | B35: 0 | C35: 0 | D35: 0 | E35: 0 | F35: 0 | G35: 0 | H35: 0 | I35: 0 | J35: 0 | K35: 0 | L35: 0 | M35: 0 | N35: =SUM(B35:M35) -> 0
A36: Biludgifter i alt | B36: =SUM(B30:B35) -> 0 | C36: =SUM(C30:C35) -> 0 | D36: =SUM(D30:D35) -> 0 | E36: =SUM(E30:E35) -> 0 | F36: =SUM(F30:F35) -> 0 | G36: =SUM(G30:G35) -> 0 | H36: =SUM(H30:H35) -> 0 | I36: =SUM(I30:I35) -> 0 | ... M36: =SUM(M30:M35) -> 0 | N36: =SUM(B36:M36) -> 0
A38: Transport øvrig
A39: Offentlig transport | B39: 0 | C39: =B39 -> 0 | D39: =C39 -> 0 | E39: =D39 -> 0 | F39: =E39 -> 0 | G39: =F39 -> 0 | H39: =G39 -> 0 | I39: =H39 -> 0 | J39: =I39 -> 0 | ... M39: =L39 -> 0 | N39: =SUM(B39:M39) -> 0
A40: Diverse | B40: 0 | C40: 0 | D40: 0 | E40: 0 | F40: 0 | G40: 0 | H40: 0 | I40: 0 | J40: 0 | K40: 0 | L40: 0 | M40: 0 | N40: =SUM(B40:M40) -> 0
A41: Transport i alt | B41: =SUM(B39:B40) -> 0 | C41: =SUM(C39:C40) -> 0 | D41: =SUM(D39:D40) -> 0 | E41: =SUM(E39:E40) -> 0 | F41: =SUM(F39:F40) -> 0 | G41: =SUM(G39:G40) -> 0 | H41: =SUM(H39:H40) -> 0 | I41: =SUM(I39:I40) -> 0 | ... M41: =SUM(M39:M40) -> 0 | N41: =SUM(B41:M41) -> 0
A43: Kommunikation/TV
A44: Fastnettelefon | B44: 0 | C44: =B44 -> 0 | D44: =C44 -> 0 | E44: =D44 -> 0 | F44: =E44 -> 0 | G44: =F44 -> 0 | H44: =G44 -> 0 | I44: =H44 -> 0 | J44: =I44 -> 0 | ... M44: =L44 -> 0 | N44: =SUM(B44:M44) -> 0
A45: Mobiltelefon | B45: 0 | C45: =B45 -> 0 | D45: =C45 -> 0 | E45: =D45 -> 0 | F45: =E45 -> 0 | G45: =F45 -> 0 | H45: =G45 -> 0 | I45: =H45 -> 0 | J45: =I45 -> 0 | ... M45: =L45 -> 0 | N45: =SUM(B45:M45) -> 0
A46: Internet | B46: 0 | C46: =B46 -> 0 | D46: =C46 -> 0 | E46: =D46 -> 0 | F46: =E46 -> 0 | G46: =F46 -> 0 | H46: =G46 -> 0 | I46: =H46 -> 0 | J46: =I46 -> 0 | ... M46: =L46 -> 0 | N46: =SUM(B46:M46) -> 0
...

Sheet Rådighedsbeløb og gældsfaktor
D1: Rådighedsbeløb før og efter køb | G1: Gældsfaktor ved køb
E3: kr.
D4: Rådighedsbeløb før køb af hus | E4: ='Budget før boligkøb'!N88 -> 26175.907 | G4: Gældsfaktor v/enlig | O4: =(Banklån!D6+'Realkredit finansiering'!E3)/'Enlig skat før boligkøb'!C20 -> 6.185567
D5: Rådighedsbeløb fastforrrentet MED afdrag | E5: ='Budget efter boligkøb'!N88 -> #NUM!
D6: Rådighedsbeløb F5 MED afdrag | E6: =E5+'Realkredit finansiering'!E28-'Realkredit finansiering'!F28 -> #NUM! | G6: Gældsfaktor v/par | O6: =(Banklån!D6+'Realkredit finansiering'!E3)/('Ægtepar skat før boligkøb'!C20+'Ægtepar skat før boligkøb'!D20) -> #DIV/0!
D7: Rådighedsbeløb fastforrentet UDEN afdrag | E7: =E5+'Realkredit finansiering'!E28-'Realkredit finansiering'!G28 -> #NUM!
D8: Rådighedsbeløb F1 UDEN afdrag | E8: =E5+'Realkredit finansiering'!E28-'Realkredit finansiering'!H28 -> #NUM!
G10: Hvilket lån skal jeg vælge?
G12: De skal kreditvurderes ud fra et fastforrentet realkreditlån MED afdrag!
G13: De kan IKKE blive kreditvurderet udfra andre realkreditlån!!!
G15: Vælger de efter den kreditvurdering at tage et andet lån skal
G16: de rådgives omkring fordele/ulemper vedr. fast vs. flex og afdrag vs. uden afdrag
G17: Afdragsfrihed på realkreditlånet kan være hensigtsmæssigt, hvis de har et dyrt banklån også
G19: Der er "frit valg" af realkreditlån hvis gældsfaktor er under 4 eller belåningsgrad er under 60%

Sheet Nedkonvertering
E1: NEDKONVERTERING
E2: Nuværende lån optaget for | F2: =H19 -> 0 | G2: år siden
E3: Du må ikke skrive her | G3: Hovedstol (oprindelig) | H3: 0
G4: Pålydende rente
G5: Bidrag | H5: 0.006812
G6: Pålydende rente+bidrag | H6: =H4+H5 -> 0.006812
G7: Kurs i dag | I7: Kursen bliver ikke brugt i beregningen her øverst, men den siger noget om hvorvidt vi skal indfri til markedskurs eller kurs 100 ved konverterbar obligationer
G8: Løbetid (oprindelig)
G9: Terminer pr. år | H9: 4
G10: Antal terminer i alt | H10: =H8*H9 -> 0
G12: Ydelse pr. termin | H12: =-PMT(H4/H9,H10,H3) -> #NUM!
G13: Ydelse i år | H13: =H12*H9 -> #NUM!
G14: Bidrag i år | H14: =($H$3+CUMPRINC($H$4/4,$H$10,$H$3,1,$F$2*$H$9,0))*$H$5/$H$9+($H$3+CUMPRINC($H$4/4,$H$10,$H$3,1,$F$2*$H$9+1,0))*$H$5/$H$9+($H$3+CUMPRINC($H$4/4,$H$10,$H$3,1,$F$2*$H$9+2,0))*$H$5/$H$9+($H$3+CUMPRINC($H$4/4,$H$10,$H$3,1,$F$2*$H$9+3,0))*$H$5/$H$9 -> #NUM!
G15: Bruttoydelse i år | H15: =SUM(H13:H14) -> #NUM!
G16: Akkumuleret rente i år | H16: =-CUMIPMT(H4/H9,H10,H3,H19*H9+1,H19*H9+4,0) -> #NUM!
G17: Nettoydelse i år | H17: =H15-1/3*(H14+H16) -> #NUM!
G19: Antal år hvor der er afdraget på lånet
G20: Afdrag på lånet "so far" | H20: =-CUMPRINC(H4/H9,H10,H3,1,H19*H9,0) -> #NUM!
G21: Obligationsrestgæld | H21: =H3-H20 -> #NUM!
E22: Skal de konvertere:
G24: Kunden kan nedkonvertere til et ? pct. konverterbart obligationslån
G25: => eksisterende høj rente lån indfries til kurs 100 da det er KONVERTERBART. NEDkonvertering
E27: Eksisterende lån:
G28: Obligationsrestgæld på eksisterende lån | H28: =H21 -> #NUM!
G29: Indfries til kurs 100(konverterbare oblig.) | H29: =H28 -> #NUM!
E31: Nyt lån: | G31: Låneomkostninger i forbindelse med konvertering | H31: =20000 -> 20000 | I31: Oven i låneomkostningerne kan du lægge en evt. belåning af friværdi, hvis der fx skal lånes til en bil eller sommerhus m.m. Husk max 80% realkreditlån i alt.
G32: Lånebehov | H32: =H29+H31 -> #NUM!
G33: Kurs på nyt lån
G34: Ny hovedstol | H34: =H32/(H33/100) -> #NUM!
G35: Pålydende rente
G36: Bidrag | H36: =H5 -> 0.006812
G37: Pålydende rente+bidrag | H37: =H35+H36 -> 0.006812
G38: Løbetid, år
G39: Antal terminer pr. år | H39: =H9 -> 4
G40: Antal terminer i alt | H40: =H39*H38 -> 0
G42: Ydelse pr. termin | H42: =-PMT(H35/H39,H40,H34) -> #NUM!
G43: Ydelse i år | H43: =H42*H39 -> #NUM!
G44: Bidrag i år | H44: =H34*H36/H39+(H34+CUMPRINC(H35/H39,H40,H34,1,H39,0))*H36/H39+(H34+CUMPRINC(H35/H39,H40,H34,1,H39+1,0))*H36/H39+(H34+CUMPRINC(H35/H39,H40,H34,1,H39+2,0))*H36/H39 -> #NUM!
G45: Bruttoydelse i år | H45: =SUM(H43:H44) -> #NUM!
G46: Akkumuleret rente i år | H46: =-CUMIPMT(H35/H39,H40,H34,1,H39,0) -> #NUM!
...

Sheet Opkonvertering
E1: OPKONVERTERING
E2: Nuværende lån optaget for | F2: =H19 -> 0 | G2: år siden
E3: Du må ikke skrive her | G3: Hovedstol (oprindelig)
G4: Pålydende rente
G5: Bidrag | H5: 0.006812
G6: Pålydende rente+bidrag | H6: =H4+H5 -> 0.006812
G7: Kurs i dag
G8: Løbetid (oprindelig)
G9: Terminer pr. år | H9: 4
G10: Antal terminer i alt | H10: =H8*H9 -> 0
G12: Ydelse pr. termin | H12: =-PMT(H4/H9,H10,H3) -> #NUM!
G13: Ydelse i år | H13: =H12*H9 -> #NUM!
G14: Bidrag i år | H14: =($H$3+CUMPRINC($H$4/4,$H$10,$H$3,1,$F$2*$H$9,0))*$H$5/$H$9+($H$3+CUMPRINC($H$4/4,$H$10,$H$3,1,$F$2*$H$9+1,0))*$H$5/$H$9+($H$3+CUMPRINC($H$4/4,$H$10,$H$3,1,$F$2*$H$9+2,0))*$H$5/$H$9+($H$3+CUMPRINC($H$4/4,$H$10,$H$3,1,$F$2*$H$9+3,0))*$H$5/$H$9 -> #NUM!
G15: Bruttoydelse i år | H15: =SUM(H13:H14) -> #NUM!
G16: Akkumuleret rente i år | H16: =-CUMIPMT(H4/H9,H10,H3,H19*H9+1,H19*H9+4,0) -> #NUM!
G17: Nettoydelse i år | H17: =H15-1/3*(H14+H16) -> #NUM!
G19: Antal år hvor der er afdraget på lånet
G20: Afdrag på lånet "so far" | H20: =-CUMPRINC(H4/H9,H10,H3,1,H19*H9,0) -> #NUM!
G21: Obligationsrestgæld | H21: =H3-H20 -> #NUM!
E22: Skal de konvertere:
G24: Kunden kan OPkonvertere til et ? pct. konverterbart obligationslån
G25: => eksisterende lavrente-lån indfries til nuværende markedskurs
E27: Eksisterende lån:
G28: Obligationsrestgæld på eksisterende lån | H28: =H21 -> #NUM!
G29: Indfries til aktuelle markedskurs | H29: =H28*H7/100 -> #NUM!
E31: Nyt lån: | G31: Låneomkostninger i forbindelse med konvertering | H31: =20000 -> 20000 | I31: Oven i låneomkostningerne kan du lægge en evt. belåning af friværdi, hvis der fx skal lånes til en bil, indfries gæld eller køb af sommerhus m.m. Husk max 80% realkreditlån i alt.
G32: Lånebehov | H32: =H29+H31 -> #NUM!
G33: Kurs på nyt lån
G34: Ny hovedstol | H34: =H32/(H33/100) -> #NUM!
G35: Pålydende rente
G36: Bidrag | H36: =H5 -> 0.006812
G37: Pålydende rente+bidrag | H37: =H35+H36 -> 0.006812
G38: Løbetid, år
G39: Antal terminer pr. år | H39: =H9 -> 4
G40: Antal terminer i alt | H40: =H39*H38 -> 0
G42: Ydelse pr. termin | H42: =-PMT(H35/H39,H40,H34) -> #NUM!
G43: Ydelse i år | H43: =H42*H39 -> #NUM!
G44: Bidrag i år | H44: =H34*H36/H39+(H34+CUMPRINC(H35/H39,H40,H34,1,H39,0))*H36/H39+(H34+CUMPRINC(H35/H39,H40,H34,1,H39+1,0))*H36/H39+(H34+CUMPRINC(H35/H39,H40,H34,1,H39+2,0))*H36/H39 -> #NUM!
G45: Bruttoydelse i år | H45: =SUM(H43:H44) -> #NUM!
G46: Akkumuleret rente i år | H46: =-CUMIPMT(H35/H39,H40,H34,1,H39,0) -> #NUM!
...

Sheet Byg realkredit beregn restgæld
A1: 3 | D1: Lånetype | E1: Fastforrentet med afdrag | G1: Termin (4= 1 år) | H1: Restgæld | I1: Rente | J1: Afdrag | K1: Ydelse | L1: Bidrag | S1: Brutto- ydelse | T1: Netto- ydelse
A2: Husets pris | B2: 4000000 | M2: Ydelse inkl. | N2: Fradrag | O2: Ydelse | V2: ÅOP
A3: 80 pct. belåning | B3: =0.8*B2 -> 3200000 | D3: Obligationshovedstol | E3: =E5*100/E4 -> 3232323.2 | G3: 0 | H3: =E3 -> 3232323.2 | K3: =-E5 -> -3200000 | S3: =-E7 -> -3134906.3 | V3: =-E7 -> -3134906.3
D4: kurs på obligation | E4: 99 | G4: 1 | H4: =H3-J4 -> 3227666 | I4: =$E$9/$E$13*H3 -> 10774.411 | J4: =K4-I4 -> 4657.1947 | K4: =IF(G4>$E$14,0,$E$16) -> 15431.606 | L4: =$E$10/$E$13*H3 -> 1834.8822 | S4: =K4+L4 -> 17266.488 | T4: =S4-1/3*(I4+L4) -> 13063.39 | V4: =S4 -> 17266.488
A5: Låneomkostninger ved optagelse af realkreditlån: | D5: Kursværdi | E5: =B3 -> 3200000 | G5: 2 | H5: =H4-J5 -> 3222993.3 | I5: =$E$9/$E$13*H4 -> 10758.887 | J5: =K5-I5 -> 4672.7187 | K5: =IF(G5>$E$14,0,$E$16) -> 15431.606 | L5: =$E$10/$E$13*H4 -> 1832.2384 | S5: =K5+L5 -> 17263.844 | T5: =S5-1/3*(I5+L5) -> 13066.802 | V5: =S5 -> 17263.844
A6: Tinglysning af pant | B6: =1.45%*E3+1825 -> 48693.687 | D6: - lånekostninger | E6: =B9 -> 65093.687 | G6: 3 | H6: =H5-J6 -> 3218305 | I6: =$E$9/$E$13*H5 -> 10743.311 | J6: =K6-I6 -> 4688.2944 | K6: =IF(G6>$E$14,0,$E$16) -> 15431.606 | L6: =$E$10/$E$13*H5 -> 1829.5859 | S6: =K6+L6 -> 17261.191 | T6: =S6-1/3*(I6+L6) -> 13070.226 | V6: =S6 -> 17261.191
A7: Etableringsomkostninger Realkreditinstitut | B7: 10000 | D7: Låneprovenu (det jeg får i hånden) | E7: =E5-E6 -> 3134906.3 | G7: 4 | H7: =H6-J7 -> 3213601.1 | I7: =$E$9/$E$13*H6 -> 10727.683 | J7: =K7-I7 -> 4703.9221 | K7: =IF(G7>$E$14,0,$E$16) -> 15431.606 | L7: =$E$10/$E$13*H6 -> 1826.9245 | S7: =K7+L7 -> 17258.53 | T7: =S7-1/3*(I7+L7) -> 13073.661
