Workbook
Name ArbBidrag: #REF!
Name ArbBidrag: #REF!
Name ArbBidrag: #REF!
Name ArbBidrag: #REF!
Name ArbBidrag: #REF!
Name ArbBidrag: #REF!
Name ArbBidrag: Skattesatser!$H$3
Name BeFradragHojSats: #REF!
Name BeFradragHojSats: #REF!
Name BeFradragHojSats: #REF!
Name BeFradragHojSats: #REF!
Name BeFradragHojSats: #REF!
Name BeFradragHojSats: #REF!
Name BeFradragHojSats: Skattesatser!$H$4
Name BeFradragKmMax: #REF!
Name BeFradragKmMax: #REF!
Name BeFradragKmMax: #REF!
Name BeFradragKmMax: #REF!
Name BeFradragKmMax: #REF!
Name BeFradragKmMax: #REF!
Name BeFradragKmMax: Skattesatser!$H$6
Name BeFradragKmMin: #REF!
Name BeFradragKmMin: #REF!
Name BeFradragKmMin: #REF!
Name BeFradragKmMin: #REF!
Name BeFradragKmMin: #REF!
Name BeFradragKmMin: #REF!
Name BeFradragKmMin: Skattesatser!$H$5
Name BeFradragLavSats: #REF!
Name BeFradragLavSats: #REF!
Name BeFradragLavSats: #REF!
Name BeFradragLavSats: #REF!
Name BeFradragLavSats: #REF!
Name BeFradragLavSats: #REF!
Name BeFradragLavSats: Skattesatser!$H$7
Name BFradragMax: #REF!
Name BFradragMax: #REF!
Name BFradragMax: #REF!
Name BFradragMax: #REF!
Name BFradragMax: #REF!
Name BFradragMax: #REF!
Name BFradragMax: Skattesatser!$H$10
Name BFradragProc: #REF!
Name BFradragProc: #REF!
Name BFradragProc: #REF!
Name BFradragProc: #REF!
Name BFradragProc: #REF!
Name BFradragProc: #REF!
Name BFradragProc: Skattesatser!$H$9
Name Bundskat: #REF!
Name Bundskat: #REF!
Name Bundskat: #REF!
Name Bundskat: #REF!
Name Bundskat: #REF!
Name Bundskat: #REF!
Name Bundskat: Skattesatser!$H$11
Name EjVSkatGranse: #REF!
Name EjVSkatGranse: #REF!
Name EjVSkatGranse: Skattesatser!$H$14
Name EjVSkatMax: #REF!

Sheet Ægtepar
B1: Skatteberegningsprogram - par | C1: År 2025
B2: Person 1, er den med højest indkomst | C2: Alicia | D2: Jacob | I2: =C2 -> Alicia | K2: =D2 -> Jacob
B3: Privat indskud på ratepension (og ophørende livrente) | C3: 0 | D3: 0 | I3: Beregnings-grundlag | J3: Beregnet skat | K3: Beregnings-grundlag | L3: Beregnet skat
B4: Privat indskud på livrente | C4: 0 | D4: 0 | F4: Beregning af skat | G4: Procent | H4: Fradrag
B5: Alder | C5: 42 | D5: 42 | F5: Bundskat | G5: =Bundskat -> 0.1201 | H5: =Personfradrag -> 51600 | I5: =IF($AC$28=1,($C$31+$AC$29),$C$77)-($H$5+$AB$41) -> 622668 | J5: =+IF(I5>0,G5*I5,0) -> 74782.427 | K5: =IF(AC28=1,(D31+AD29),$D$77)-H5 -> 454860 | L5: =+IF(K5>0,K5*G5,0) -> 54628.686
B6: Har fri telefon (ja/nej) | C6: ja | D6: ja | F6: Topskat | G6: =Topskat -> 0.15 | H6: =TopSkatGranse -> 611800 | I6: =MAX((C78-$H$6),0) -> 62468 | J6: =G6*I6 -> 9370.2 | K6: =MAX((D77-$H$6),0) -> 0 | L6: =G6*K6 -> 0
B7: Fagforening | C7: 3600 | D7: 3600 | F7: Sundhedsbidrag | G7: =Sundhedsbidrag -> 0 | H7: =Personfradrag -> 51600 | I7: =($C$45+AB29)-(H7+AB43) -> 544512 | J7: =+IF(I7>0,I7*G7,0) -> 0 | K7: =($D$45-AB29)-H7 -> 376704 | L7: =+IF(K7>0,G7*K7,0) -> 0
B8: A-kasse og efterløn | C8: 6000 | D8: 6000 | F8: Kommuneskat | G8: =C13 -> 0.235 | H8: =Personfradrag -> 51600 | I8: =($C$45+AB29)-(H8+AB44) -> 544512 | J8: =+IF(I8>0,$C$13*I8,0) -> 127960.32 | K8: =($D$45-AB29)-H8 -> 376704 | L8: =+IF(K8>0,$D$13*K8,0) -> 88525.44
B9: Antal km til arbejde (tur/retur) | C9: 19.8 | D9: 12 | F9: Kirkeskat | G9: =C14 -> 0 | H9: =Personfradrag -> 51600 | I9: =($C$45+AB29)-(H9+AB45) -> 544512 | J9: =+IF(I9>0,$C$14*I9,0) -> 0 | K9: =($D$45-AB29)-H9 -> 376704 | L9: =+IF(K9>0,$D$14*K9,0) -> 0
B10: Antal arbejdsdage | C10: 200 | D10: 200 | J10: =SUM(J5:J9) -> 212112.95 | L10: =SUM(L5:L9) -> 143154.13
B11: Medlem af Folkekirken (ja/nej) | C11: nej | D11: nej
B12: Vælg Kommune | C12: København | D12: =C12 -> København | F12: Evt skattetillæg af neg. KI under 50.000 | J12: =IF(AA29>=0,0,IF(AA29>=GranseNegKIPar,TillagNegKI*AA29,TillagNegKI*GranseNegKIPar)) -> 0
B13: Kommuneskattesats | C13: =VLOOKUP($C$12,Skattesatser!$B$6:$E$103,2)/100 -> 0.235 | D13: =VLOOKUP($D$12,Skattesatser!$B$6:$E$103,2)/100 -> 0.235 | F13: Evt. nedslag i topskatten (lønindkomst) | I13: =IF($C$81>SkraatSkatteloftPI,$C$81-SkraatSkatteloftPI,0) -> 0 | J13: =-I13*C83 -> 0 | K13: =IF($D$81>SkraatSkatteloftPI,$D$81-SkraatSkatteloftPI,0) -> 0 | L13: =-K13*D83 -> 0
B14: Kirkeskattesats | C14: =IF(C11="ja",VLOOKUP($C$12,Skattesatser!$B$6:$E$103,3)/100,0) -> 0 | D14: =IF(D11="ja",VLOOKUP($C$12,Skattesatser!$B$6:$E$103,3)/100,0) -> 0 | F14: Evt. nedslag i topskatten (kapitalindkomst) | I14: =IF($C$81>SkraatSkatteloftKI,$C$81-SkraatSkatteloftKI,0) -> 0.0851 | J14: =-I14*C84 -> 0
B15: Grundskyldssats | C15: =VLOOKUP($C$12,Skattesatser!$B$6:$E$103,4)/1000 -> 0.0051 | J15: =SUM(J10:J14) -> 212112.95 | L15: =SUM(L10:L14) -> 143154.13
B16: Ejendomsværdi (offentlig) | C16: 0
B17: Grundværdi (offentlig) | C17: 0
B18: Evt skatterabat (bolig købt før 1.jan.2024) | C18: 0 | F18: Indkomstskat i alt (incl. AM-bidrag) | J18: =J15+C27 -> 270744.95 | L18: =L15+D27 -> 187194.13
F19: Ejendomsværdiskat | J19: =+F71/2 -> 0 | L19: =J19 -> 0
B20: Lønindkomst (efter evt. ATP) | C20: 768000 | D20: 576000 | F20: Grundskyld | J20: =F72/2 -> 0 | L20: =J20 -> 0
B21: arbejdsgiverpensionsordning % (kun eget indskud) | C21: 0.05 | D21: 0.05 | F21: Skatterabat | J21: =-C18/2 -> 0 | L21: =J21 -> 0
B22: - arbejdsgiverpensionsordning DKK (kun eget indskud) | C22: =C21*C20 -> 38400 | D22: =D21*D20 -> 28800
B23: + anden AM-pligtig indkomst | C23: 0 | D23: 0 | F23: Skat i alt | J23: =SUM(J18:J22) -> 270744.95 | L23: =SUM(L18:L22) -> 187194.13
B24: + fri telefon | C24: =IF(C6="ja",FriTelefon,0) -> 3300 | D24: =IF(D6="ja",FriTelefon,0) -> 3300
B25: = Beregningsgrundlag for AM-bidrag | C25: =C20-C22+C23+C24 -> 732900 | D25: =D20-D22+D23+D24 -> 550500
F26: Udbetalt efter skat | I26: =C2 -> Alicia | K26: =D2 -> Jacob | AB26: Uudnyttet | AC26: Udligning af KI til brug for bundskat
B27: - AM-bidrag | C27: =ArbBidrag*C25 -> 58632 | D27: =ArbBidrag*D25 -> 44040 | I27: Pr. år | J27: Pr. måned | K27: Pr. år | L27: Pr. måned | AB27: KI | AC27: P1 | AD27: P2
B28: + Ikke AM-pligtig indkomst (SU, dagpenge, pension etc.) | C28: 0 | D28: 0 | F28: Lønindkomst | I28: =C20+C23+C28 -> 768000 | J28: =I28/12 -> 64000 | K28: =D20+D23+D28 -> 576000 | L28: =K28/12 -> 48000 | AB28: person 2 | AC28: =IF(AA29<0,0,IF((C35+0.00000001)*(D35+0.0000001)<0,1,0)) -> 0
B29: - Eget indskud på ratepension (husk også at indtaste i budget) | C29: =IF(C3>RatepensionMax,RatepensionMax,C3) -> 0 | D29: =IF(D3>RatepensionMax,RatepensionMax,D3) -> 0 | F29: - arbejdsgiver pensionsordning | I29: =C22 -> 38400 | J29: =I29/12 -> 3200 | K29: =D22 -> 28800 | L29: =K29/12 -> 2400 | AA29: =SUM(C35:D35) -> 0 | AB29: =IF(D45<0,IF(D31-D43<0,D35,D35+D31-D43),0) -> 0 | AC29: =IF(AC28=1,C35+D35,0) -> 0 | AD29: =IF(AC28=1,0,D35) -> 0
B30: - Eget indskud på livrente (husk også at indtaste i budget) | C30: =+C4 -> 0 | D30: =+D4 -> 0 | F30: - skat | I30: =J23 -> 270744.95 | J30: =I30/12 -> 22562.079 | K30: =L23 -> 187194.13 | L30: =K30/12 -> 15599.51
B31: = Personlig indkomst (PI) | C31: =C25-C27+C28-C29-C30 -> 674268 | D31: =D25-D27+D28-D29-D30 -> 506460 | F31: Udbetalt efter skat | I31: =I28-I29-I30 -> 458855.05 | J31: =I31/12 -> 38237.921 | K31: =K28-K29-K30 -> 360005.87 | L31: =K31/12 -> 30000.489
B33: + Renteindtægter | C33: 0 | D33: 0
B34: - Renteudgfter | C34: 0 | D34: 0
B35: + Kapitalindkomst (KI) i alt | C35: =+C33-C34 -> 0 | D35: =+D33-D34 -> 0
B37: Beskæftigelsesfradrag | C37: =MIN(+(C25+C22*3)*BFradragProc,BFradragMax) -> 55600 | D37: =MIN(+(D25+D22*3)*BFradragProc,BFradragMax) -> 55600
B38: Jobfradrag | C38: =MAX(0,MIN(+($C$25+C22*3-Jfradraggranse)*Jfradragproc,JfradragMax)) -> 2900 | D38: =MAX(0,MIN(+($D$25+D22*3-Jfradraggranse)*Jfradragproc,JfradragMax)) -> 2900 | AB38: Uudnyttet
B39: Ekstra pensionsfradrag | C39: =IF(C5<=52,MIN(+(C3+C4+C22*3)*EPENfradragProc,EPENfradragMax),MIN(+(C3+C4+C22*3)*EPENSeniorProc,EPENSeniorMax)) -> 10056 | D39: =IF(D5<=52,MIN(+(D3+D4+D22*3)*EPENfradragProc,EPENfradragMax),MIN(+(D3+D4+D22*3)*EPENSeniorProc,EPENSeniorMax)) -> 10056 | AB39: fradrag
B40: Fagforening, A-kasse og efterløn | C40: =IF(C7>FagforeningMax,FagforeningMax,C7)+C8 -> 9600 | D40: =IF(D7>FagforeningMax,FagforeningMax,D7)+D8 -> 9600 | AB40: person 2
B41: Befordring | C41: =+$H$56 -> 0 | D41: =H65 -> 0 | AB41: =IF(D77>H5,0,H5-D77) -> 0
B42: Andre ligningsmæssige fradrag | C42: 0 | D42: 0
...

Sheet Budget lejebolig
A1: Privatbudget - | F1: boligkøb
A3: Indtægter | B3: jan | C3: feb | D3: mar | E3: apr | F3: maj | G3: juni | H3: juli | I3: aug | J3: sept | K3: okt | L3: nov | M3: dec | N3: TOTAL
A4: Alicia Løn, efter skat | B4: =Ægtepar!J31 -> 38237.921 | C4: =B4 -> 38237.921 | D4: =C4 -> 38237.921 | E4: =D4 -> 38237.921 | F4: =E4 -> 38237.921 | G4: =F4 -> 38237.921 | H4: =G4 -> 38237.921 | I4: =H4 -> 38237.921 | J4: =I4 -> 38237.921 | ... M4: =L4 -> 38237.921 | N4: =SUM(B4:M4) -> 458855.05
A5: Jacob Løn, efter skat | B5: =Ægtepar!L31 -> 30000.489 | C5: =B5 -> 30000.489 | D5: =C5 -> 30000.489 | E5: =D5 -> 30000.489 | F5: =E5 -> 30000.489 | G5: =F5 -> 30000.489 | H5: =G5 -> 30000.489 | I5: =H5 -> 30000.489 | J5: =I5 -> 30000.489 | ... M5: =L5 -> 30000.489 | N5: =SUM(B5:M5) -> 360005.87
A6: Renter/udbytte | B6: 0 | C6: 0 | D6: 0 | E6: 0 | F6: 0 | G6: 0 | H6: 0 | I6: 0 | J6: 0 | K6: 0 | L6: 0 | M6: 0 | N6: =SUM(B6:M6) -> 0
A7: Børnefamilie ydelser | B7: =2*3192 -> 6384 | E7: =B7 -> 6384 | H7: =E7 -> 6384 | K7: =H7 -> 6384 | L7: 0 | M7: =L7 -> 0 | N7: =SUM(B7:M7) -> 25536
A8: Børnebidrag | B8: 0 | C8: 0 | D8: 0 | E8: 0 | F8: 0 | G8: 0 | H8: 0 | I8: 0 | J8: 0 | K8: 0 | L8: 0 | M8: 0 | N8: =SUM(B8:M8) -> 0
A9: Diverse | B9: 0 | C9: 0 | D9: 0 | E9: 0 | F9: 0 | G9: 0 | H9: 0 | I9: 0 | J9: 0 | K9: 0 | L9: 0 | M9: 0 | N9: =SUM(B9:M9) -> 0
A10: Indtægter i alt | B10: =SUM(B4:B9) -> 74622.411 | C10: =SUM(C4:C9) -> 68238.411 | D10: =SUM(D4:D9) -> 68238.411 | E10: =SUM(E4:E9) -> 74622.411 | F10: =SUM(F4:F9) -> 68238.411 | G10: =SUM(G4:G9) -> 68238.411 | H10: =SUM(H4:H9) -> 74622.411 | I10: =SUM(I4:I9) -> 68238.411 | ... M10: =SUM(M4:M9) -> 68238.411 | N10: =SUM(B10:M10) -> 844396.93
A13: Udgifter | B13: jan | C13: feb | D13: mar | E13: apr | F13: maj | G13: juni | H13: juli | I13: aug | J13: sept | K13: okt | L13: nov | M13: dec | N13: TOTAL
A14: Bolig
A15: Husleje incl vand og varme | B15: 18500 | C15: =B15 -> 18500 | D15: =C15 -> 18500 | E15: =D15 -> 18500 | F15: =E15 -> 18500 | G15: =F15 -> 18500 | H15: =G15 -> 18500 | I15: =H15 -> 18500 | J15: =I15 -> 18500 | ... M15: =L15 -> 18500 | N15: =SUM(B15:M15) -> 222000 | O15: efter skat
A16: Banklån | B16: 0 | C16: =B16 -> 0 | D16: =C16 -> 0 | E16: =D16 -> 0 | F16: =E16 -> 0 | G16: =F16 -> 0 | H16: =G16 -> 0 | I16: =H16 -> 0 | J16: =I16 -> 0 | ... M16: =L16 -> 0 | N16: =SUM(B16:M16) -> 0
A17: Renovation | C17: 0 | D17: 0 | E17: 0 | F17: 0 | G17: 0 | H17: 0 | I17: 0 | J17: 0 | K17: 0 | L17: 0 | M17: 0 | N17: =SUM(B17:M17) -> 0
A18: Varme | B18: 0 | C18: =B18 -> 0 | D18: =C18 -> 0 | E18: =D18 -> 0 | F18: =E18 -> 0 | G18: =F18 -> 0 | H18: =G18 -> 0 | I18: =H18 -> 0 | J18: =I18 -> 0 | ... M18: =L18 -> 0
A19: Elektricitet | B19: 1000 | C19: 0 | D19: 0 | E19: =B19 -> 1000 | F19: 0 | G19: 0 | H19: =E19 -> 1000 | I19: 0 | J19: 0 | K19: =H19 -> 1000 | L19: 0 | M19: 0 | N19: =SUM(B19:M19) -> 4000
A20: Vand | B20: 0 | C20: =B20 -> 0 | D20: =C20 -> 0 | E20: =D20 -> 0 | F20: =E20 -> 0 | G20: =F20 -> 0 | H20: =G20 -> 0 | I20: =H20 -> 0 | J20: =I20 -> 0 | ... M20: =L20 -> 0 | N20: =SUM(B20:M20) -> 0
A21: Ejendomsskatter | C21: 0 | D21: 0 | E21: 0 | F21: 0 | G21: 0 | H21: =B21 | I21: 0 | J21: 0 | K21: 0 | L21: 0 | M21: 0 | N21: =SUM(B21:M21) -> 0
A22: Fællesudgifter | C22: =B22 | D22: =C22 | E22: =D22 | F22: =E22 | G22: =F22 | H22: =G22 | I22: =H22 | J22: =I22 | ... M22: =L22 | N22: =SUM(B22:M22) -> 0
A23: Grundejerforening | C23: 0 | D23: 0 | E23: 0 | F23: 0 | G23: 0 | H23: 0 | I23: 0 | J23: 0 | K23: 0 | L23: 0 | M23: 0 | N23: =SUM(B23:M23) -> 0
A24: Vedligeholdelse | B24: 0 | C24: =B24 -> 0 | D24: =C24 -> 0 | E24: =D24 -> 0 | F24: =E24 -> 0 | G24: =F24 -> 0 | H24: =G24 -> 0 | I24: =H24 -> 0 | J24: =I24 -> 0 | ... M24: =L24 -> 0 | N24: =SUM(B24:M24) -> 0
A25: Hus forsikring | C25: 0 | D25: 0 | E25: 0 | F25: 0 | G25: 0 | H25: 0 | I25: 0 | J25: 0 | K25: 0 | L25: 0 | M25: 0 | N25: =SUM(B25:M25) -> 0
A26: Ejerudgift | B26: 0 | C26: =B26 -> 0 | D26: =C26 -> 0 | E26: =D26 -> 0 | F26: =E26 -> 0 | G26: =F26 -> 0 | H26: =G26 -> 0 | I26: =H26 -> 0 | J26: =I26 -> 0 | ... M26: =L26 -> 0 | N26: =SUM(B26:M26) -> 0
A27: Bolig i alt | B27: =SUM(B15:B26) -> 19500 | C27: =SUM(C15:C26) -> 18500 | D27: =SUM(D15:D26) -> 18500 | E27: =SUM(E15:E26) -> 19500 | F27: =SUM(F15:F26) -> 18500 | G27: =SUM(G15:G26) -> 18500 | H27: =SUM(H15:H26) -> 19500 | I27: =SUM(I15:I26) -> 18500 | ... N27: =SUM(N15:N26) -> 226000
A29: Bil
A30: Forsikring | B30: 8000 | C30: 0 | D30: 0 | E30: 0 | F30: 0 | G30: 0 | H30: 0 | I30: 0 | J30: 0 | K30: 0 | L30: 0 | M30: 0 | N30: =SUM(B30:M30) -> 8000
A31: Vægtafgift | B31: 800 | C31: 0 | D31: 0 | E31: 0 | F31: 0 | G31: 0 | H31: 0 | I31: 0 | J31: 0 | K31: 0 | L31: 0 | M31: 0 | N31: =SUM(B31:M31) -> 800
A32: EL | B32: 700 | C32: =B32 -> 700 | D32: =C32 -> 700 | E32: =D32 -> 700 | F32: =E32 -> 700 | G32: =F32 -> 700 | H32: =G32 -> 700 | I32: =H32 -> 700 | J32: =I32 -> 700 | ... M32: =L32 -> 700 | N32: =SUM(B32:M32) -> 8400
A33: Falck | B33: 0 | C33: 0 | D33: 0 | E33: 0 | F33: 0 | G33: 0 | H33: 0 | I33: 0 | J33: 0 | K33: 0 | L33: 0 | M33: 0 | N33: =SUM(B33:M33) -> 0
A34: Billån | B34: 0 | C34: =B34 -> 0 | D34: =C34 -> 0 | E34: =D34 -> 0 | F34: =E34 -> 0 | G34: =F34 -> 0 | H34: =G34 -> 0 | I34: =H34 -> 0 | J34: =I34 -> 0 | ... M34: =L34 -> 0 | N34: =SUM(B34:M34) -> 0
A35: Vedligehold/reparation | B35: 500 | C35: 500 | D35: 500 | E35: 500 | F35: 500 | G35: 500 | H35: 500 | I35: 500 | J35: 500 | K35: 500 | L35: 500 | M35: 500 | N35: =SUM(B35:M35) -> 6000
A36: Biludgifter i alt | B36: =SUM(B30:B35) -> 10000 | C36: =SUM(C30:C35) -> 1200 | D36: =SUM(D30:D35) -> 1200 | E36: =SUM(E30:E35) -> 1200 | F36: =SUM(F30:F35) -> 1200 | G36: =SUM(G30:G35) -> 1200 | H36: =SUM(H30:H35) -> 1200 | I36: =SUM(I30:I35) -> 1200 | ... M36: =SUM(M30:M35) -> 1200 | N36: =SUM(B36:M36) -> 23200
A38: Transport øvrig
A39: Offentlig transport | B39: 0 | C39: =B39 -> 0 | D39: =C39 -> 0 | E39: =D39 -> 0 | F39: =E39 -> 0 | G39: =F39 -> 0 | H39: =G39 -> 0 | I39: =H39 -> 0 | J39: =I39 -> 0 | ... M39: =L39 -> 0 | N39: =SUM(B39:M39) -> 0
A40: Diverse | B40: 0 | C40: 0 | D40: 0 | E40: 0 | F40: 0 | G40: 0 | H40: 0 | I40: 0 | J40: 0 | K40: 0 | L40: 0 | M40: 0 | N40: =SUM(B40:M40) -> 0
A41: Transport i alt | B41: =SUM(B39:B40) -> 0 | C41: =SUM(C39:C40) -> 0 | D41: =SUM(D39:D40) -> 0 | E41: =SUM(E39:E40) -> 0 | F41: =SUM(F39:F40) -> 0 | G41: =SUM(G39:G40) -> 0 | H41: =SUM(H39:H40) -> 0 | I41: =SUM(I39:I40) -> 0 | ... M41: =SUM(M39:M40) -> 0 | N41: =SUM(B41:M41) -> 0
A43: Kommunikation/TV
A44: Fastnettelefon | B44: 0 | C44: =B44 -> 0 | D44: =C44 -> 0 | E44: =D44 -> 0 | F44: =E44 -> 0 | G44: =F44 -> 0 | H44: =G44 -> 0 | I44: =H44 -> 0 | J44: =I44 -> 0 | ... M44: =L44 -> 0 | N44: =SUM(B44:M44) -> 0
A45: Mobiltelefon | B45: 0 | C45: =B45 -> 0 | D45: =C45 -> 0 | E45: =D45 -> 0 | F45: =E45 -> 0 | G45: =F45 -> 0 | H45: =G45 -> 0 | I45: =H45 -> 0 | J45: =I45 -> 0 | ... M45: =L45 -> 0 | N45: =SUM(B45:M45) -> 0
A46: Internet | B46: 250 | C46: =B46 -> 250 | D46: =C46 -> 250 | E46: =D46 -> 250 | F46: =E46 -> 250 | G46: =F46 -> 250 | H46: =G46 -> 250 | I46: =H46 -> 250 | J46: =I46 -> 250 | ... M46: =L46 -> 250 | N46: =SUM(B46:M46) -> 3000
...

Sheet Hvordan finansieres boligen
A2: Hvordan skal boligen finansieres? | G2: Hvordan anvendes pengene?
A5: Kontantpris på boligen | D5: kr. | E5: 6995000 | G5: Sælger skal have | J5: kr. | K5: =E5 -> 6995000
G7: Hvor kommer pengene fra:
A8: Realkreditlån, maks. 80% | D8: kr. | E8: 5016423.9 | F8: =E8/E5 -> 0.71714424
A9: Hvad kommer kunden med | D9: kr. | E9: 2150000 | G9: Provenu fra realkreditlån | J9: kr. | K9: ='Realkredit finansiering (2)'!E7 -> 4920570 | L9: Tinglysning - Låneomkostninger, realkredit er trukket fra
A10: - op af "lommen penge": | G10: Provenu fra banklån | J10: kr. | K10: =IF(K18>0,'Banklån (2)'!D16,0) -> 0 | L10: Tinglysning - Låneomkostninger, banklån er trukket fra
B11: Skøde | E11: =0.6%*E5+1850 -> 43820 | G11: Egne midler | J11: kr. | K11: =E15 -> 2074430
B12: Advokat, anslået | E12: 5000
B13: Halv ejerskifteforsikring | E13: 6750 | G13: I alt | J13: kr. | K13: =K9+K10+K11 -> 6995000
B14: Flytteomkostninger/renovering og andet | E14: 20000
A15: Egen udbetaling, min. 5% | E15: =E9-E11-E12-E13-E14 -> 2074430 | F15: =E15/E5 -> 0.29655897
G16: Mangler | J16: kr. | K16: =K13-K5 -> 0 | L16: Skal altid være 0
A17: Restfinansiering (minus = overskud) | D17: kr. | E17: =E5-E8-E15 -> -95853.928 | F17: =E17/E5 -> -0.013703206
F18: =F8+F15+F17 -> 1 | G18: Banklån inkl. omkostninger
A20: Låneomkostninger
G21: Lægger 2 mio kr + 150 tkr af opsparingen
A22: Tinglysning - Låneomkostninger, realkredit | D22: kr. | E22: ='Realkredit finansiering (2)'!B9 -> 95853.928
A23: Tinglysning - Låneomkostninger, banklån | D23: kr. | E23: =IF(K18>0,'Banklån (2)'!D14,0) -> 0
A25: Låneomkostninger i alt | E25: =E22+E23 -> 95853.928
A28: Fremgangsmåde:
A30: 1) Start altid med at udfylde rente og kurs i fanebladet "Realkreditfinansiering" og rente i "Banklån"
A31: 2) Slet altid E8 og K18 inden start
A32: 2) Indtast boligens kontantpris (E5)
A33: 3) Indtast hvor mange penge kunden kommer med (E9)
A34: 4) Indtast ejerskifteforsikring (E13) og flytteomkostninger m.m. (E14)
A38: Er restfinansiering (E17) nu under 80%: | H38: Er restfinansiering (E17) nu over 80%:
A39: 1) Indtast realkreditlånet (E8) med det beløb som fremgår af E17 | H39: 1) Indtast realkreditlånet (E8) som 80% af kontantprisen
A40: 2) Lav en målsøgning så "Mangler" (K16) bliver 0 ved ændring af celle E8 | H40: 2) Lav en målsøgning så "Mangler" (K16) bliver 0 ved ændring af celle K18
A44: Hvis realkreditlånet (E8) bliver mere end 80%:
A45: 1) Gå til "Er restfinansiering (E17) nu over 80%"

Sheet Banklån (2)
D4: Banklån til finasiering af boligen
B6: Lånets størrelse (hovedstol) | D6: ='Hvordan finansieres boligen'!K18 -> 0 | E6: jf. ark "Hvordan finansieres huset…"
B7: Løbetid,år | D7: 30 | E7: en bolig kan godt finansieres over 30 år
B8: Antal terminer pr år | D8: 12
B9: Rente pr år | D9: 0.05 | E9: (tjek rentesatsen på bankernes hjemmesider under bank boliglån - det er ikke et realkreditlån)
B11: Etableringsomkostninger:
B12: Tinglysning af pant | D12: =1825+1.45%*D6 -> 1825
B13: Bankens etableringsomk. | D13: 5690 | E13: (nordea's dokumentgebyr og vurderingsgebyr)
B14: Etableringsomkostninger i alt | D14: =D12+D13 -> 7515
B16: Provenu (hvad får jeg i hånden) | D16: =D6-D14 -> -7515
B19: Ydelse pr termin før skat | D19: =PMT(D9/D8,D7*D8,D6) -> 0
B20: Renteudgifter år 1 | D20: =-CUMIPMT(D9/D8,D8*D7,D6,1,D8,0) -> #NUM!
B21: Skattefar betaler 1/3 af renteudgifterne | D21: =1/3*D20 -> #NUM!
B22: Ydelse pr. termin efter skat | D22: =D19+(D21/D8) -> #NUM! | E22: = Den der anvendes i budgettet, medmindre du skriver renteudgiften ind i skattebegningen
B24: Omkostninger i procent pr termin | D24: =RATE(D7*D8,D19,D16) -> #NUM!
B25: ÅOP | D25: =(1+D24)^D8-1 -> #NUM!

Sheet Realkredit finansiering (2)
D1: Lånetype | E1: Fastforrentet med afdrag | F1: Rentetilpasning med afdrag F5 | G1: Fastforrentet uden afdrag | H1: Rentetilpasning uden afdrag F1
A2: Husets pris | B2: ='Hvordan finansieres boligen'!E5 -> 6995000 | C2: Belåningsgrad (max.80%)
A3: Lånebeløb | B3: ='Hvordan finansieres boligen'!E8 -> 5016423.9 | C3: =B3/B2 -> 0.71714424 | D3: Obligationshovedstol | E3: =E5/E4*100 -> 5103178 | F3: =F5/F4*100 -> 5016423.9 | G3: =G5/G4*100 -> 5139778.6 | H3: =H5/H4*100 -> 5016423.9
D4: kurs på obligation | E4: 98.3 | F4: 100 | G4: 97.6 | H4: 100
A5: Låneomkostninger ved optagelse af realkreditlån: | D5: Kursværdi | E5: =B3 -> 5016423.9 | F5: =B3 -> 5016423.9 | G5: =B3 -> 5016423.9 | H5: =B3 -> 5016423.9
A6: Tinglysning af pant | B6: =1.45%*E3+1825 -> 75821.08 | D6: - lånekostninger | E6: =B9 -> 95853.928 | F6: =E6 -> 95853.928 | G6: =F6 -> 95853.928 | H6: =G6 -> 95853.928
A7: Etableringsomkostninger Realkreditinstitut | B7: 10000 | D7: Låneprovenu (det jeg får i hånden) | E7: =E5-E6 -> 4920570 | F7: =F5-F6 -> 4920570 | G7: =G5-G6 -> 4920570 | H7: =H5-H6 -> 4920570
A8: Kurtage/kursskæring, 0,2 pct. | B8: =0.2%*B3 -> 10032.848
A9: I alt | B9: =SUM(B6:B8) -> 95853.928 | D9: Pålydende rente | E9: 0.04 | F9: 0.026 | G9: 0.04 | H9: 0.0399
D10: Bidragssats | E10: 0.006812 | F10: 0.008564 | G10: =E10+0.002752 -> 0.009564 | H10: =0.011064+0.002752 -> 0.013816
D11: Rente + bidragssats | E11: =E10+E9 -> 0.046812 | F11: =F10+F9 -> 0.034564 | G11: =G10+G9 -> 0.049564 | H11: =H10+H9 -> 0.053716
D12: Løbetid, år | E12: 30 | F12: 30 | G12: 30 | H12: 30
D13: Terminer pr. år | E13: 4 | F13: =E13 -> 4 | G13: =F13 -> 4 | H13: =G13 -> 4
D14: Antal terminer i alt | E14: =E13*E12 -> 120 | F14: =F13*F12 -> 120 | G14: =G13*G12 -> 120 | H14: =H13*H12 -> 120
D16: Ydelse pr. termin | E16: =-PMT(E9/E13,E14,E3) -> 73215.778 | F16: =-PMT(F9/F13,F14,F5) -> 60334.225 | G16: =G3*G9/G13 -> 51397.786 | H16: =H5*H9/H13 -> 50038.829
D17: Ydelse pr. år | E17: =E16*E13 -> 292863.11 | F17: =F16*F13 -> 241336.9 | G17: =G16*G13 -> 205591.14 | H17: =H16*H13 -> 200155.31
D18: Bidrag 1.år | E18: =E3*E10/E13+(E3+CUMPRINC(E9/E13,E14,E3,1,1,0))*E10/E13+(E3+CUMPRINC(E9/E13,E14,E3,1,2,0))*E10/E13+(E3+CUMPRINC(E9/E13,E14,E3,1,3,0))*E10/E13 -> 34534.657 | F18: ='F5 (2)'!F4+'F5 (2)'!F5+'F5 (2)'!F6+'F5 (2)'!F7 -> 42602.921 | G18: =G3*G10/G13*G13 -> 49156.843 | H18: =H5*H10/H13*H13 -> 69306.913
D19: Bruttoydelse 1.år | E19: =SUM(E17:E18) -> 327397.77 | F19: =SUM(F17:F18) -> 283939.82 | G19: =SUM(G17:G18) -> 254747.99 | H19: =SUM(H17:H18) -> 269462.23
D21: Akkumuleret rente 1.år | E21: =-CUMIPMT(E9/E13,E14,E3,1,E13,0) -> 202787.18 | F21: ='F5 (2)'!C4+'F5 (2)'!C5+'F5 (2)'!C6+'F5 (2)'!C7 -> 129340.96 | G21: =G17 -> 205591.14 | H21: =H17 -> 200155.31
D22: Afdrag på gæld 1.år | E22: =-CUMPRINC(E9/E13,E14,E3,1,1*E13,0) -> 90075.93 | F22: =F17-F21 -> 111995.94 | G22: 0 | H22: 0
D24: Nettoydelse 1.år | E24: =E19-1/3*(E18+E21) -> 248290.49 | F24: =F19-1/3*(F18+F21) -> 226625.19 | G24: =G19-1/3*(G18+G21) -> 169831.99 | H24: =H19-1/3*(H18+H21) -> 179641.49
D25: Nettoydelse pr. termin (1.år) | E25: =E24/E13 -> 62072.622 | F25: =F24/F13 -> 56656.298 | G25: =G24/G13 -> 42457.998 | H25: =H24/H13 -> 44910.371
D27: Bruttoydelse pr. måned (gnsn) | E27: =E19/12 -> 27283.147 | F27: =F19/12 -> 23661.652 | G27: =G19/12 -> 21228.999 | H27: =H19/12 -> 22455.186
D28: Nettoydelse pr. måned (gnsn) | E28: =E24/12 -> 20690.874 | F28: =F24/12 -> 18885.433 | G28: =G24/12 -> 14152.666 | H28: =H24/12 -> 14970.124

Sheet F5 (2)
A1: Termin | B1: Restgæld | C1: Rente | D1: Afdrag | E1: Ydelse | F1: Bidrag | G1: Brutto- ydelse
A3: 0 | B3: ='Realkredit finansiering (2)'!F5 -> 5016423.9
A4: 1 | B4: =B3-D4 -> 4988696.5 | C4: ='Realkredit finansiering (2)'!$F$9/'Realkredit finansiering (2)'!$F$13*'F5 (2)'!B3 -> 32606.756 | D4: =E4-C4 -> 27727.469 | E4: ='Realkredit finansiering (2)'!$F$16 -> 60334.225 | F4: ='Realkredit finansiering (2)'!$F$10/'Realkredit finansiering (2)'!$F$13*'F5 (2)'!B3 -> 10740.164 | G4: =E4+F4 -> 71074.388
A5: 2 | B5: =B4-D5 -> 4960788.8 | C5: ='Realkredit finansiering (2)'!$F$9/'Realkredit finansiering (2)'!$F$13*'F5 (2)'!B4 -> 32426.527 | D5: =E5-C5 -> 27907.698 | E5: ='Realkredit finansiering (2)'!$F$16 -> 60334.225 | F5: ='Realkredit finansiering (2)'!$F$10/'Realkredit finansiering (2)'!$F$13*'F5 (2)'!B4 -> 10680.799 | G5: =E5+F5 -> 71015.024
A6: 3 | B6: =B5-D6 -> 4932699.7 | C6: ='Realkredit finansiering (2)'!$F$9/'Realkredit finansiering (2)'!$F$13*'F5 (2)'!B5 -> 32245.127 | D6: =E6-C6 -> 28089.098 | E6: ='Realkredit finansiering (2)'!$F$16 -> 60334.225 | F6: ='Realkredit finansiering (2)'!$F$10/'Realkredit finansiering (2)'!$F$13*'F5 (2)'!B5 -> 10621.049 | G6: =E6+F6 -> 70955.273
A7: 4 | B7: =B6-D7 -> 4904428 | C7: ='Realkredit finansiering (2)'!$F$9/'Realkredit finansiering (2)'!$F$13*'F5 (2)'!B6 -> 32062.548 | D7: =E7-C7 -> 28271.677 | E7: ='Realkredit finansiering (2)'!$F$16 -> 60334.225 | F7: ='Realkredit finansiering (2)'!$F$10/'Realkredit finansiering (2)'!$F$13*'F5 (2)'!B6 -> 10560.91 | G7: =E7+F7 -> 70895.134
A8: 5 | B8: =B7-D8 -> 4875972.5 | C8: ='Realkredit finansiering (2)'!$F$9/'Realkredit finansiering (2)'!$F$13*'F5 (2)'!B7 -> 31878.782 | D8: =E8-C8 -> 28455.443 | E8: ='Realkredit finansiering (2)'!$F$16 -> 60334.225 | F8: ='Realkredit finansiering (2)'!$F$10/'Realkredit finansiering (2)'!$F$13*'F5 (2)'!B7 -> 10500.38 | G8: =E8+F8 -> 70834.605
A9: 6 | B9: =B8-D9 -> 4847332.1 | C9: ='Realkredit finansiering (2)'!$F$9/'Realkredit finansiering (2)'!$F$13*'F5 (2)'!B8 -> 31693.822 | D9: =E9-C9 -> 28640.403 | E9: ='Realkredit finansiering (2)'!$F$16 -> 60334.225 | F9: ='Realkredit finansiering (2)'!$F$10/'Realkredit finansiering (2)'!$F$13*'F5 (2)'!B8 -> 10439.457 | G9: =E9+F9 -> 70773.682
A10: 7 | B10: =B9-D10 -> 4818505.6 | C10: ='Realkredit finansiering (2)'!$F$9/'Realkredit finansiering (2)'!$F$13*'F5 (2)'!B9 -> 31507.659 | D10: =E10-C10 -> 28826.566 | E10: ='Realkredit finansiering (2)'!$F$16 -> 60334.225 | F10: ='Realkredit finansiering (2)'!$F$10/'Realkredit finansiering (2)'!$F$13*'F5 (2)'!B9 -> 10378.138 | G10: =E10+F10 -> 70712.363
A11: 8 | B11: =B10-D11 -> 4789491.6 | C11: ='Realkredit finansiering (2)'!$F$9/'Realkredit finansiering (2)'!$F$13*'F5 (2)'!B10 -> 31320.286 | D11: =E11-C11 -> 29013.938 | E11: ='Realkredit finansiering (2)'!$F$16 -> 60334.225 | F11: ='Realkredit finansiering (2)'!$F$10/'Realkredit finansiering (2)'!$F$13*'F5 (2)'!B10 -> 10316.42 | G11: =E11+F11 -> 70650.645
A12: 9 | B12: =B11-D12 -> 4760289.1 | C12: ='Realkredit finansiering (2)'!$F$9/'Realkredit finansiering (2)'!$F$13*'F5 (2)'!B11 -> 31131.696 | D12: =E12-C12 -> 29202.529 | E12: ='Realkredit finansiering (2)'!$F$16 -> 60334.225 | F12: ='Realkredit finansiering (2)'!$F$10/'Realkredit finansiering (2)'!$F$13*'F5 (2)'!B11 -> 10254.302 | G12: =E12+F12 -> 70588.526
A13: 10 | B13: =B12-D13 -> 4730896.8 | C13: ='Realkredit finansiering (2)'!$F$9/'Realkredit finansiering (2)'!$F$13*'F5 (2)'!B12 -> 30941.879 | D13: =E13-C13 -> 29392.345 | E13: ='Realkredit finansiering (2)'!$F$16 -> 60334.225 | F13: ='Realkredit finansiering (2)'!$F$10/'Realkredit finansiering (2)'!$F$13*'F5 (2)'!B12 -> 10191.779 | G13: =E13+F13 -> 70526.003
A14: 11 | B14: =B13-D14 -> 4701313.4 | C14: ='Realkredit finansiering (2)'!$F$9/'Realkredit finansiering (2)'!$F$13*'F5 (2)'!B13 -> 30750.829 | D14: =E14-C14 -> 29583.396 | E14: ='Realkredit finansiering (2)'!$F$16 -> 60334.225 | F14: ='Realkredit finansiering (2)'!$F$10/'Realkredit finansiering (2)'!$F$13*'F5 (2)'!B13 -> 10128.85 | G14: =E14+F14 -> 70463.074
A15: 12 | B15: =B14-D15 -> 4671537.7 | C15: ='Realkredit finansiering (2)'!$F$9/'Realkredit finansiering (2)'!$F$13*'F5 (2)'!B14 -> 30558.537 | D15: =E15-C15 -> 29775.688 | E15: ='Realkredit finansiering (2)'!$F$16 -> 60334.225 | F15: ='Realkredit finansiering (2)'!$F$10/'Realkredit finansiering (2)'!$F$13*'F5 (2)'!B14 -> 10065.512 | G15: =E15+F15 -> 70399.736
... A123: 120 | B123: =B122-D123 -> -7.6033757e-09 | C123: ='Realkredit finansiering (2)'!$F$9/'Realkredit finansiering (2)'!$F$13*'F5 (2)'!B122 -> 389.6398 | D123: =E123-C123 -> 59944.585 | E123: ='Realkredit finansiering (2)'!$F$16 -> 60334.225 | F123: ='Realkredit finansiering (2)'!$F$10/'Realkredit finansiering (2)'!$F$13*'F5 (2)'!B122 -> 128.34136 | G123: =E123+F123 -> 60462.566

Sheet Budget med hus
A1: Privatbudget - | F1: boligkøb
A3: Indtægter | B3: jan | C3: feb | D3: mar | E3: apr | F3: maj | G3: juni | H3: juli | I3: aug | J3: sept | K3: okt | L3: nov | M3: dec | N3: TOTAL
A4: Jens Løn, efter skat | B4: =Ægtepar!J31 -> 38237.921 | C4: =B4 -> 38237.921 | D4: =C4 -> 38237.921 | E4: =D4 -> 38237.921 | F4: =E4 -> 38237.921 | G4: =F4 -> 38237.921 | H4: =G4 -> 38237.921 | I4: =H4 -> 38237.921 | J4: =I4 -> 38237.921 | ... M4: =L4 -> 38237.921 | N4: =SUM(B4:M4) -> 458855.05
A5: Anna Løn, efter skat | B5: =Ægtepar!L31 -> 30000.489 | C5: =B5 -> 30000.489 | D5: =C5 -> 30000.489 | E5: =D5 -> 30000.489 | F5: =E5 -> 30000.489 | G5: =F5 -> 30000.489 | H5: =G5 -> 30000.489 | I5: =H5 -> 30000.489 | J5: =I5 -> 30000.489 | ... M5: =L5 -> 30000.489 | N5: =SUM(B5:M5) -> 360005.87
A6: Renter/udbytte | B6: 0 | C6: 0 | D6: 0 | E6: 0 | F6: 0 | G6: 0 | H6: 0 | I6: 0 | J6: 0 | K6: 0 | L6: 0 | M6: 0 | N6: =SUM(B6:M6) -> 0
A7: Børnefamilie ydelser | B7: =3192*2 -> 6384 | E7: =B7 -> 6384 | H7: =E7 -> 6384 | K7: =H7 -> 6384 | M7: =L7 -> 0 | N7: =SUM(B7:M7) -> 25536
A8: Børnebidrag | B8: 0 | C8: 0 | D8: 0 | E8: 0 | F8: 0 | G8: 0 | H8: 0 | I8: 0 | J8: 0 | K8: 0 | L8: 0 | M8: 0 | N8: =SUM(B8:M8) -> 0
A9: Diverse | B9: 0 | C9: 0 | D9: 0 | E9: 0 | F9: 0 | G9: 0 | H9: 0 | I9: 0 | J9: 0 | K9: 0 | L9: 0 | M9: 0 | N9: =SUM(B9:M9) -> 0
A10: Indtægter i alt | B10: =SUM(B4:B9) -> 74622.411 | C10: =SUM(C4:C9) -> 68238.411 | D10: =SUM(D4:D9) -> 68238.411 | E10: =SUM(E4:E9) -> 74622.411 | F10: =SUM(F4:F9) -> 68238.411 | G10: =SUM(G4:G9) -> 68238.411 | H10: =SUM(H4:H9) -> 74622.411 | I10: =SUM(I4:I9) -> 68238.411 | ... M10: =SUM(M4:M9) -> 68238.411 | N10: =SUM(B10:M10) -> 844396.93
A13: Udgifter | B13: jan | C13: feb | D13: mar | E13: apr | F13: maj | G13: juni | H13: juli | I13: aug | J13: sept | K13: okt | L13: nov | M13: dec | N13: TOTAL
A14: Bolig
A15: Ydelse realkreditlån netto | B15: ='Realkredit finansiering (2)'!E28 -> 20690.874 | C15: =B15 -> 20690.874 | D15: =C15 -> 20690.874 | E15: =D15 -> 20690.874 | F15: =E15 -> 20690.874 | G15: =F15 -> 20690.874 | H15: =G15 -> 20690.874 | I15: =H15 -> 20690.874 | J15: =I15 -> 20690.874 | ... M15: =L15 -> 20690.874 | N15: =SUM(B15:M15) -> 248290.49 | O15: efter skat
A16: Banklån | B16: 0 | C16: =B16 -> 0 | D16: =C16 -> 0 | E16: =D16 -> 0 | F16: =E16 -> 0 | G16: =F16 -> 0 | H16: =G16 -> 0 | I16: =H16 -> 0 | J16: =I16 -> 0 | ... M16: =L16 -> 0 | N16: =SUM(B16:M16) -> 0
A17: Renovation | C17: 0 | D17: 0 | E17: 0 | F17: 0 | G17: 0 | H17: 0 | I17: 0 | J17: 0 | K17: 0 | L17: 0 | M17: 0 | N17: =SUM(B17:M17) -> 0
A18: Varme | B18: =N18/12 -> 2075 | C18: =B18 -> 2075 | D18: =C18 -> 2075 | E18: =D18 -> 2075 | F18: =E18 -> 2075 | G18: =F18 -> 2075 | H18: =G18 -> 2075 | I18: =H18 -> 2075 | J18: =I18 -> 2075 | ... M18: =L18 -> 2075 | N18: 24900
A19: Elektricitet | B19: 1500 | C19: 0 | D19: 0 | E19: =B19 -> 1500 | F19: 0 | G19: 0 | H19: =E19 -> 1500 | I19: 0 | J19: 0 | K19: =H19 -> 1500 | L19: 0 | M19: 0 | N19: =SUM(B19:M19) -> 6000
A20: Vand | B20: 700 | C20: =B20 -> 700 | D20: =C20 -> 700 | E20: =D20 -> 700 | F20: =E20 -> 700 | G20: =F20 -> 700 | H20: =G20 -> 700 | I20: =H20 -> 700 | J20: =I20 -> 700 | ... M20: =L20 -> 700 | N20: =SUM(B20:M20) -> 8400
A21: Ejendomsskatter | C21: 0 | D21: 0 | E21: 0 | F21: 0 | G21: 0 | H21: =B21 | I21: 0 | J21: 0 | K21: 0 | L21: 0 | M21: 0 | N21: =SUM(B21:M21) -> 0
A22: Fællesudgifter | C22: =B22 | D22: =C22 | E22: =D22 | F22: =E22 | G22: =F22 | H22: =G22 | I22: =H22 | J22: =I22 | ... M22: =L22 | N22: =SUM(B22:M22) -> 0
A23: Grundejerforening | C23: 0 | D23: 0 | E23: 0 | F23: 0 | G23: 0 | H23: 0 | I23: 0 | J23: 0 | K23: 0 | L23: 0 | M23: 0 | N23: =SUM(B23:M23) -> 0
A24: Vedligeholdelse | B24: 500 | C24: =B24 -> 500 | D24: =C24 -> 500 | E24: =D24 -> 500 | F24: =E24 -> 500 | G24: =F24 -> 500 | H24: =G24 -> 500 | I24: =H24 -> 500 | J24: =I24 -> 500 | ... M24: =L24 -> 500 | N24: =SUM(B24:M24) -> 6000
A25: Hus forsikring | C25: 0 | D25: 0 | E25: 0 | F25: 0 | G25: 0 | H25: 0 | I25: 0 | J25: 0 | K25: 0 | L25: 0 | M25: 0 | N25: =SUM(B25:M25) -> 0
A26: Ejerudgift | B26: 6252 | C26: =B26 -> 6252 | D26: =C26 -> 6252 | E26: =D26 -> 6252 | F26: =E26 -> 6252 | G26: =F26 -> 6252 | H26: =G26 -> 6252 | I26: =H26 -> 6252 | J26: =I26 -> 6252 | ... M26: =L26 -> 6252 | N26: =SUM(B26:M26) -> 75024
A27: Bolig i alt | B27: =SUM(B15:B26) -> 31717.874 | C27: =SUM(C15:C26) -> 30217.874 | D27: =SUM(D15:D26) -> 30217.874 | E27: =SUM(E15:E26) -> 31717.874 | F27: =SUM(F15:F26) -> 30217.874 | G27: =SUM(G15:G26) -> 30217.874 | H27: =SUM(H15:H26) -> 31717.874 | I27: =SUM(I15:I26) -> 30217.874 | ... N27: =SUM(N15:N26) -> 368614.49
A29: Bil
A30: Forsikring | B30: 8000 | C30: 0 | D30: 0 | E30: 0 | F30: 0 | G30: 0 | H30: 0 | I30: 0 | J30: 0 | K30: 0 | L30: 0 | M30: 0 | N30: =SUM(B30:M30) -> 8000
A31: Vægtafgift | B31: 800 | C31: 0 | D31: 0 | E31: 0 | F31: 0 | G31: 0 | H31: 0 | I31: 0 | J31: 0 | K31: 0 | L31: 0 | M31: 0 | N31: =SUM(B31:M31) -> 800
A32: EL | B32: 700 | C32: =B32 -> 700 | D32: =C32 -> 700 | E32: =D32 -> 700 | F32: =E32 -> 700 | G32: =F32 -> 700 | H32: =G32 -> 700 | I32: =H32 -> 700 | J32: =I32 -> 700 | ... M32: =L32 -> 700 | N32: =SUM(B32:M32) -> 8400
A33: Falck | B33: 0 | C33: 0 | D33: 0 | E33: 0 | F33: 0 | G33: 0 | H33: 0 | I33: 0 | J33: 0 | K33: 0 | L33: 0 | M33: 0 | N33: =SUM(B33:M33) -> 0
A34: Billån | B34: 0 | C34: =B34 -> 0 | D34: =C34 -> 0 | E34: =D34 -> 0 | F34: =E34 -> 0 | G34: =F34 -> 0 | H34: =G34 -> 0 | I34: =H34 -> 0 | J34: =I34 -> 0 | ... M34: =L34 -> 0 | N34: =SUM(B34:M34) -> 0
A35: Vedligehold/reparation | B35: 500 | C35: 500 | D35: 500 | E35: 500 | F35: 500 | G35: 500 | H35: 500 | I35: 500 | J35: 500 | K35: 500 | L35: 500 | M35: 500 | N35: =SUM(B35:M35) -> 6000
A36: Biludgifter i alt | B36: =SUM(B30:B35) -> 10000 | C36: =SUM(C30:C35) -> 1200 | D36: =SUM(D30:D35) -> 1200 | E36: =SUM(E30:E35) -> 1200 | F36: =SUM(F30:F35) -> 1200 | G36: =SUM(G30:G35) -> 1200 | H36: =SUM(H30:H35) -> 1200 | I36: =SUM(I30:I35) -> 1200 | ... M36: =SUM(M30:M35) -> 1200 | N36: =SUM(B36:M36) -> 23200
A38: Transport øvrig
A39: Offentlig transport | B39: 0 | C39: =B39 -> 0 | D39: =C39 -> 0 | E39: =D39 -> 0 | F39: =E39 -> 0 | G39: =F39 -> 0 | H39: =G39 -> 0 | I39: =H39 -> 0 | J39: =I39 -> 0 | ... M39: =L39 -> 0 | N39: =SUM(B39:M39) -> 0
A40: Diverse | B40: 0 | C40: 0 | D40: 0 | E40: 0 | F40: 0 | G40: 0 | H40: 0 | I40: 0 | J40: 0 | K40: 0 | L40: 0 | M40: 0 | N40: =SUM(B40:M40) -> 0
A41: Transport i alt | B41: =SUM(B39:B40) -> 0 | C41: =SUM(C39:C40) -> 0 | D41: =SUM(D39:D40) -> 0 | E41: =SUM(E39:E40) -> 0 | F41: =SUM(F39:F40) -> 0 | G41: =SUM(G39:G40) -> 0 | H41: =SUM(H39:H40) -> 0 | I41: =SUM(I39:I40) -> 0 | ... M41: =SUM(M39:M40) -> 0 | N41: =SUM(B41:M41) -> 0
A43: Kommunikation/TV
A44: Fastnettelefon | B44: 0 | C44: =B44 -> 0 | D44: =C44 -> 0 | E44: =D44 -> 0 | F44: =E44 -> 0 | G44: =F44 -> 0 | H44: =G44 -> 0 | I44: =H44 -> 0 | J44: =I44 -> 0 | ... M44: =L44 -> 0 | N44: =SUM(B44:M44) -> 0
A45: Mobiltelefon | B45: 0 | C45: =B45 -> 0 | D45: =C45 -> 0 | E45: =D45 -> 0 | F45: =E45 -> 0 | G45: =F45 -> 0 | H45: =G45 -> 0 | I45: =H45 -> 0 | J45: =I45 -> 0 | ... M45: =L45 -> 0 | N45: =SUM(B45:M45) -> 0
A46: Internet | B46: 250 | C46: =B46 -> 250 | D46: =C46 -> 250 | E46: =D46 -> 250 | F46: =E46 -> 250 | G46: =F46 -> 250 | H46: =G46 -> 250 | I46: =H46 -> 250 | J46: =I46 -> 250 | ... M46: =L46 -> 250 | N46: =SUM(B46:M46) -> 3000
...

Sheet Rådighedsbeløb og gældsfaktor
D1: Rådighedsbeløb før og efter køb | G1: Gældsfaktor ved køb
E3: kr. | Q3: Rådighedsbeløbet er over "min.krav" men fortsat
D4: Rådighedsbeløb før køb af hus | E4: ='Budget lejebolig'!N88 -> 38866.411 | G4: Gældsfaktor v/enlig | O4: #DIV/0! | Q4: under "hvad de har i lejelejligheden".
D5: Rådighedsbeløb fastforrrentet MED afdrag | E5: ='Budget med hus'!N88 -> 32981.87 | Q5: Krav i henhold til tommelfingerregel
D6: Rådighedsbeløb F5 MED afdrag | E6: =E5+'Realkredit finansiering (2)'!E28-'Realkredit finansiering (2)'!F28 -> 34787.311 | G6: Gældsfaktor v/par | O6: ='Realkredit finansiering (2)'!E3/(Ægtepar!C20+Ægtepar!D20) -> 3.7970074
D7: Rådighedsbeløb fastforrentet UDEN afdrag | E7: =E5+'Realkredit finansiering (2)'!E28-'Realkredit finansiering (2)'!G28 -> 39520.078 | Q7: De kan godt mht rådighedsbeløb og gældsfaktor er fin.
D8: Rådighedsbeløb F1 UDEN afdrag | E8: =E5+'Realkredit finansiering (2)'!E28-'Realkredit finansiering (2)'!H28 -> 38702.62
Q9: Konklusion: | S9: De har tidligere vist at de kan lægge 6.000 kr til side, hvorfor rådighedsbeløbet er nogenlunde det samme. Dog har de nu ingen opsparing.
G10: Hvilket lån skal jeg vælge?
G12: De skal kreditvurderes ud fra et fastforrentet realkreditlån MED afdrag! | Q12: Spg 2: | S12: De kan godt vælge et afdragsfrit eller variabelt forrentet lån da gældsfaktoren er under 4, men ydelsen vil stige vis renten stiger.
G13: De kan IKKE blive kreditvurderet udfra andre realkreditlån!!!
Q14: Spg 3: | S14: Det er som at tisse i bukserne når der efter 10 år skal afdrages. I tilfælde de havde et dyrt banklån ville det give god mening, at afdrage på det først.
G15: Vælger de efter den kreditvurdering at tage et andet lån skal
G16: de rådgives omkring fordele/ulemper vedr. fast vs. flex og afdrag vs. uden afdrag | Q16: Spg 4: | S16: Vi kreditvurdere ALTID ud fra fastforrentet lån med afdrag.
G17: Afdragsfrihed på realkreditlånet kan være hensigtsmæssigt, hvis de har et dyrt banklån også
G19: Der er "frit valg" af realkreditlån hvis gældsfaktor er under 4 eller belåningsgrad er under 60%

Sheet Skattesatser
B3: Kommuneskattesatser 2025 | G3: Arbejdsmarkedsbidrag | H3: 0.08
G4: Befordringsfradrag høje sats | H4: 2.23
B5: Kommunenavn | C5: Kommune | D5: Kirke | E5: Grundskyld (promille) | G5: Befordringsfradrag min km for høj sats | H5: 24
B6: Albertslund | C6: 25.6 | D6: 0.8 | E6: 9.1 | G6: Befordringsfradrag max km for høj sats | H6: 120
B7: Allerød | C7: 25.3 | D7: 0.58 | E7: 8 | G7: Befordringsfradrag lave sats | H7: 1.12
B8: Assens | C8: 26.1 | D8: 0.98 | E8: 11.2 | G8: Befordringsfradrag Indtægtsgrænse for forhøjet (før AM-bidrag) | H8: 325800
B9: Ballerup | C9: 25.5 | D9: 0.75 | E9: 8.3 | G9: Beskæftigelsesfradrag (%) | H9: 0.123
B10: Billund | C10: 24 | D10: 0.89 | E10: 7.2 | G10: Beskæftigelsesfradrag (max) | H10: 55600
B11: Bornholm | C11: 26.2 | D11: 0 | E11: 10.7 | G11: Bundskat | H11: 0.1201
B12: Brøndby | C12: 24.3 | D12: 0.8 | E12: 4.9 | G12: Ejendomsværdiskat - lave sats | H12: 0.0051
B13: Brønderslev | C13: 26.3 | D13: 1.06 | E13: 17.1 | G13: Ejendomsværdiskat - høje sats | H13: 0.014
B14: Dragør | C14: 24.8 | D14: 0.61 | E14: 8.1 | G14: Ejendomsværdiskat - skillegrænse | H14: 11500000
B15: Egedal | C15: 25.7 | D15: 0.76 | E15: 8.8 | G15: Ekstra pensionsfradrag (%) | H15: 0.12
B16: Esbjerg | C16: 26.1 | D16: 0.81 | E16: 9.9 | G16: Ekstra pensionsfradrag (max) | H16: 10056
B17: Fanø | C17: 26.1 | D17: 1.05 | E17: 8.5 | G17: Ekstra pensionsfradrag (%) Senior | H17: 0.32
... B25: Furesø | C25: 24.88 | D25: 0.96 | E25: 12 | G25: Grøn check | H25: 0
B26: Faaborg-Midtfyn | C26: 26.1 | D26: 0.65 | E26: 7 | G26: Grøn check modregning Start
B27: Gentofte | C27: 24.24 | D27: 0.39 | E27: 5.1 | G27: Grøn check modregning Slut
B28: Gladsaxe | C28: 23.6 | D28: 0.75 | E28: 5.9 | G28: Grøn check modregning Sats
B29: Glostrup | C29: 24.6 | D29: 0.8 | E29: 6.5 | G29: Jobfradrag (%) | H29: 0.045
B30: Greve | C30: 24.59 | D30: 0.81 | E30: 5.5 | G30: Jobfradraggrænse | H30: 224500
B31: Gribskov | C31: 25.4 | D31: 0.85 | E31: 11.1 | G31: Jobfradrag (max) | H31: 2900
B32: Guldborgsund | C32: 25.8 | D32: 1.16 | E32: 15.9 | G32: Kapitalindkomstgrænse til Topskat Par | H32: 104800
B33: Haderslev | C33: 26.3 | D33: 0.95 | E33: 12.7 | G33: Kapitalindkomstgrænse til Topskat Enlig | H33: 52400
B34: Halsnæs | C34: 25.7 | D34: 0.85 | E34: 10.9 | G34: Personfradrag | H34: 51600
B35: Hedensted | C35: 25.52 | D35: 0.98 | E35: 7.9 | G35: Personfradrag topskat | H35: 611800
B36: Helsingør | C36: 25.82 | D36: 0.63 | E36: 9.5 | G36: Ratepension Max indskud | H36: 65500
B37: Herlev | C37: 23.7 | D37: 0.75 | E37: 5.4 | G37: Skrå Skatteloft - personlig indkomst | H37: 0.5207
B38: Herning | C38: 25.4 | D38: 0.99 | E38: 9.9 | G38: Skrå Skatteloft - kapitalindkomst | H38: 0.42
B39: Hillerød | C39: 25.6 | D39: 0.69 | E39: 6.6 | G39: Sundhedsbidrag | H39: 0
B40: Hjørring | C40: 26.21 | D40: 1.19 | E40: 16.5 | G40: Tillæg for negativ kapitalindkomst procent | H40: 0.08
... B43: Horsens | C43: 25.69 | D43: 0.79 | E43: 8.7 | G43: Topskat | H43: 0.15
B44: Hvidovre | C44: 25.4 | D44: 0.72 | E44: 6.5
B45: Høje-Taastrup | C45: 24.6 | D45: 0.8 | E45: 6.3
B46: Hørsholm | C46: 23.7 | D46: 0.62 | E46: 8.5
B47: Ikast-Brande | C47: 25.1 | D47: 0.97 | E47: 9.1
B48: Ishøj | C48: 25 | D48: 0.9 | E48: 6.5
B49: Jammerbugt | C49: 25.7 | D49: 1.2 | E49: 13.2
B50: Kalundborg | C50: 24.2 | D50: 1.01 | E50: 16.6
B51: Kerteminde | C51: 26.1 | D51: 0.98 | E51: 12.4
...

Sheet Ark1
