Workbook
Name ArbBidrag: [1]Skattesatser!$C$3
Name ArbBidrag: [1]Skattesatser!$C$3
Name ArbBidrag: Skattesatser!$H$3
Name BeFradragHojSats: [1]Skattesatser!$C$4
Name BeFradragHojSats: [1]Skattesatser!$C$4
Name BeFradragHojSats: Skattesatser!$H$4
Name BeFradragKmMax: [1]Skattesatser!$C$6
Name BeFradragKmMax: [1]Skattesatser!$C$6
Name BeFradragKmMax: Skattesatser!$H$6
Name BeFradragKmMin: [1]Skattesatser!$C$5
Name BeFradragKmMin: [1]Skattesatser!$C$5
Name BeFradragKmMin: Skattesatser!$H$5
Name BeFradragLavSats: [1]Skattesatser!$C$7
Name BeFradragLavSats: [1]Skattesatser!$C$7
Name BeFradragLavSats: Skattesatser!$H$7
Name BFradragMax: [1]Skattesatser!$C$10
Name BFradragMax: [1]Skattesatser!$C$10
Name BFradragMax: Skattesatser!$H$10
Name BFradragProc: [1]Skattesatser!$C$9
Name BFradragProc: [1]Skattesatser!$C$9
Name BFradragProc: Skattesatser!$H$9
Name Bundskat: [1]Skattesatser!$C$11
Name Bundskat: [1]Skattesatser!$C$11
Name Bundskat: Skattesatser!$H$11
Name EjVSkatGranse: Skattesatser!$H$14
Name EjVSkatMax: [1]Skattesatser!$C$13
Name EjVSkatMax: [1]Skattesatser!$C$13
Name EjVSkatMax: Skattesatser!$H$13
Name EjVSkatMin: [1]Skattesatser!$C$12
Name EjVSkatMin: [1]Skattesatser!$C$12
Name EjVSkatMin: Skattesatser!$H$12
Name EPENfradragMax: [2]Skattesatser!$C$16
Name EPENfradragMax: [2]Skattesatser!$C$16
Name EPENfradragMax: Skattesatser!$H$16
Name EPENfradragProc: [2]Skattesatser!$C$15
Name EPENfradragProc: [2]Skattesatser!$C$15
Name EPENfradragProc: Skattesatser!$H$15
Name EPENSeniorMax: [2]Skattesatser!$C$18
Name EPENSeniorMax: [2]Skattesatser!$C$18
Name EPENSeniorMax: Skattesatser!$H$18
Name EPENSeniorProc: [2]Skattesatser!$C$17
Name EPENSeniorProc: [2]Skattesatser!$C$17
Name EPENSeniorProc: Skattesatser!$H$17
Name FagforeningMax: [1]Skattesatser!$C$15
Name FagforeningMax: [1]Skattesatser!$C$15
Name FagforeningMax: Skattesatser!$H$19
Name FirmabilGranse: Skattesatser!$H$20
Name FirmabilHoj: Skattesatser!$H$22
Name FirmabilLav: Skattesatser!$H$21
Name Forsigtighed: Skattesatser!$H$23
Name FriTelefon: [1]Skattesatser!$C$19
Name FriTelefon: [1]Skattesatser!$C$19
Name FriTelefon: Skattesatser!$H$24
Name GranseForhBFdrag: Skattesatser!$H$8
Name GranseNegKIEnlig: Skattesatser!$H$42
Name GranseNegKIPar: [1]Skattesatser!$C$33
Name GranseNegKIPar: [1]Skattesatser!$C$33
Name GranseNegKIPar: Skattesatser!$H$41
Name Grøn_check_antal_børn_max: [1]Skattesatser!#REF!
Name Grøn_check_antal_børn_max: [1]Skattesatser!#REF!

Sheet Ægtepar
B1: Skatteberegningsprogram - par | C1: År 2025
B2: Person 1, er den med højest indkomst | C2: Jesper | D2: Anne | I2: =C2 -> Jesper | K2: =D2 -> Anne
B3: Privat indskud på ratepension (og ophørende livrente) | C3: 0 | D3: 24000 | I3: Beregnings-grundlag | J3: Beregnet skat | K3: Beregnings-grundlag | L3: Beregnet skat
B4: Privat indskud på livrente | C4: 0 | D4: 0 | F4: Beregning af skat | G4: Procent | H4: Fradrag
B5: Alder | C5: 29 | D5: 27 | F5: Bundskat | G5: =Bundskat -> 0.1201 | H5: =Personfradrag -> 51600 | I5: =IF($AC$28=1,($C$31+$AC$29),$C$77)-($H$5+$AB$41) -> 635556 | J5: =+IF(I5>0,G5*I5,0) -> 76330.276 | K5: =IF(AC28=1,(D31+AD29),$D$77)-H5 -> 244040 | L5: =+IF(K5>0,K5*G5,0) -> 29309.204
B6: Har fri telefon (ja/nej) | C6: ja | D6: nej | F6: Topskat | G6: =Topskat -> 0.15 | H6: =TopSkatGranse -> 611800 | I6: =MAX((C78-$H$6),0) -> 72956 | J6: =G6*I6 -> 10943.4 | K6: =MAX((D77-$H$6),0) -> 0 | L6: =G6*K6 -> 0
B7: Fagforening | C7: 6000 | D7: 7200 | F7: Sundhedsbidrag | G7: =Sundhedsbidrag -> 0 | H7: =Personfradrag -> 51600 | I7: =($C$45+AB29)-(H7+AB43) -> 561000 | J7: =+IF(I7>0,I7*G7,0) -> 0 | K7: =($D$45-AB29)-H7 -> 151821.6 | L7: =+IF(K7>0,G7*K7,0) -> 0
B8: A-kasse og efterløn | C8: 0 | D8: 9800 | F8: Kommuneskat | G8: =C13 -> 0.2452 | H8: =Personfradrag -> 51600 | I8: =($C$45+AB29)-(H8+AB44) -> 561000 | J8: =+IF(I8>0,$C$13*I8,0) -> 137557.2 | K8: =($D$45-AB29)-H8 -> 151821.6 | L8: =+IF(K8>0,$D$13*K8,0) -> 37226.656
B9: Antal km til arbejde (tur/retur) | C9: 5 | D9: 54 | F9: Kirkeskat | G9: =C14 -> 0 | H9: =Personfradrag -> 51600 | I9: =($C$45+AB29)-(H9+AB45) -> 561000 | J9: =+IF(I9>0,$C$14*I9,0) -> 0 | K9: =($D$45-AB29)-H9 -> 151821.6 | L9: =+IF(K9>0,$D$14*K9,0) -> 0
B10: Antal arbejdsdage | C10: 216 | D10: 216 | J10: =SUM(J5:J9) -> 224830.88 | L10: =SUM(L5:L9) -> 66535.86
B11: Medlem af Folkekirken (ja/nej) | C11: nej | D11: nej
B12: Vælg Kommune | C12: Aarhus | D12: =C12 -> Aarhus | F12: Evt skattetillæg af neg. KI under 50.000 | J12: =IF(AA29>=0,0,IF(AA29>=GranseNegKIPar,TillagNegKI*AA29,TillagNegKI*GranseNegKIPar)) -> 0
B13: Kommuneskattesats | C13: =VLOOKUP($C$12,Skattesatser!$B$6:$E$103,2)/100 -> 0.2452 | D13: =VLOOKUP($D$12,Skattesatser!$B$6:$E$103,2)/100 -> 0.2452 | F13: Evt. nedslag i topskatten (lønindkomst) | I13: =IF($C$81>SkraatSkatteloftPI,$C$81-SkraatSkatteloftPI,0) -> 0 | J13: =-I13*C83 -> 0 | K13: =IF($D$81>SkraatSkatteloftPI,$D$81-SkraatSkatteloftPI,0) -> 0 | L13: =-K13*D83 -> 0
B14: Kirkeskattesats | C14: =IF(C11="ja",VLOOKUP($C$12,Skattesatser!$B$6:$E$103,3)/100,0) -> 0 | D14: =IF(D11="ja",VLOOKUP($C$12,Skattesatser!$B$6:$E$103,3)/100,0) -> 0 | F14: Evt. nedslag i topskatten (kapitalindkomst) | I14: =IF($C$81>SkraatSkatteloftKI,$C$81-SkraatSkatteloftKI,0) -> 0.0953 | J14: =-I14*C84 -> 0
B15: Grundskyldssats | C15: =VLOOKUP($C$12,Skattesatser!$B$6:$E$103,4)/1000 -> 0.006 | J15: =SUM(J10:J14) -> 224830.88 | L15: =SUM(L10:L14) -> 66535.86
B16: Ejendomsværdi (offentlig) | C16: 0
B17: Grundværdi (offentlig) | C17: 0
B18: Evt skatterabat (bolig købt før 1.jan.2024) | C18: 0 | F18: Indkomstskat i alt (incl. AM-bidrag) | J18: =J15+C27 -> 284374.88 | L18: =L15+D27 -> 93895.86
F19: Ejendomsværdiskat | J19: =+F71/2 -> 0 | L19: =J19 -> 0
B20: Lønindkomst (efter evt. ATP) | C20: =12*65000 -> 780000 | D20: =12*30000 -> 360000 | F20: Grundskyld | J20: =F72/2 -> 0 | L20: =J20 -> 0
B21: arbejdsgiverpensionsordning % (kun eget indskud) | C21: 0.05 | D21: 0.05 | F21: Skatterabat | J21: =-C18/2 -> 0 | L21: =J21 -> 0
B22: - arbejdsgiverpensionsordning DKK (kun eget indskud) | C22: =C21*C20 -> 39000 | D22: =D21*D20 -> 18000
B23: + anden AM-pligtig indkomst | C23: 0 | D23: 0 | F23: Skat i alt | J23: =SUM(J18:J22) -> 284374.88 | L23: =SUM(L18:L22) -> 93895.86
B24: + fri telefon | C24: =IF(C6="ja",FriTelefon,0) -> 3300 | D24: =IF(D6="ja",FriTelefon,0) -> 0
B25: = Beregningsgrundlag for AM-bidrag | C25: =C20-C22+C23+C24 -> 744300 | D25: =D20-D22+D23+D24 -> 342000
F26: Udbetalt efter skat | I26: =C2 -> Jesper | K26: =D2 -> Anne | AB26: Uudnyttet | AC26: Udligning af KI til brug for bundskat
B27: - AM-bidrag | C27: =ArbBidrag*C25 -> 59544 | D27: =ArbBidrag*D25 -> 27360 | I27: Pr. år | J27: Pr. måned | K27: Pr. år | L27: Pr. måned | AB27: KI | AC27: P1 | AD27: P2
B28: + Ikke AM-pligtig indkomst (SU, dagpenge, pension etc.) | C28: 0 | D28: 0 | F28: Lønindkomst | I28: =C20+C23+C28 -> 780000 | J28: =I28/12 -> 65000 | K28: =D20+D23+D28 -> 360000 | L28: =K28/12 -> 30000 | AB28: person 2 | AC28: =IF(AA29<0,0,IF((C35+0.00000001)*(D35+0.0000001)<0,1,0)) -> 0
B29: - Eget indskud på ratepension (husk også at indtaste i budget) | C29: =IF(C3>RatepensionMax,RatepensionMax,C3) -> 0 | D29: =IF(D3>RatepensionMax,RatepensionMax,D3) -> 24000 | F29: - arbejdsgiver pensionsordning | I29: =C22 -> 39000 | J29: =I29/12 -> 3250 | K29: =D22 -> 18000 | L29: =K29/12 -> 1500 | AA29: =SUM(C35:D35) -> 7400 | AB29: =IF(D45<0,IF(D31-D43<0,D35,D35+D31-D43),0) -> 0 | AC29: =IF(AC28=1,C35+D35,0) -> 0 | AD29: =IF(AC28=1,0,D35) -> 5000
B30: - Eget indskud på livrente (husk også at indtaste i budget) | C30: =+C4 -> 0 | D30: =+D4 -> 0 | F30: - skat | I30: =J23 -> 284374.88 | J30: =I30/12 -> 23697.906 | K30: =L23 -> 93895.86 | L30: =K30/12 -> 7824.655
B31: = Personlig indkomst (PI) | C31: =C25-C27+C28-C29-C30 -> 684756 | D31: =D25-D27+D28-D29-D30 -> 290640 | F31: Udbetalt efter skat | I31: =I28-I29-I30 -> 456625.12 | J31: =I31/12 -> 38052.094 | K31: =K28-K29-K30 -> 248104.14 | L31: =K31/12 -> 20675.345
B33: + Renteindtægter | C33: 2400 | D33: 5000
B34: - Renteudgfter | C34: 0 | D34: 0
B35: + Kapitalindkomst (KI) i alt | C35: =+C33-C34 -> 2400 | D35: =+D33-D34 -> 5000
B37: Beskæftigelsesfradrag | C37: =MIN(+(C25+C22*3)*BFradragProc,BFradragMax) -> 55600 | D37: =MIN(+(D25+D22*3)*BFradragProc,BFradragMax) -> 48708
B38: Jobfradrag | C38: =MAX(0,MIN(+($C$25+C22*3-Jfradraggranse)*Jfradragproc,JfradragMax)) -> 2900 | D38: =MAX(0,MIN(+($D$25+D22*3-Jfradraggranse)*Jfradragproc,JfradragMax)) -> 2900 | AB38: Uudnyttet
B39: Ekstra pensionsfradrag | C39: =IF(C5<=52,MIN(+(C3+C4+C22*3)*EPENfradragProc,EPENfradragMax),MIN(+(C3+C4+C22*3)*EPENSeniorProc,EPENSeniorMax)) -> 10056 | D39: =IF(D5<=52,MIN(+(D3+D4+D22*3)*EPENfradragProc,EPENfradragMax),MIN(+(D3+D4+D22*3)*EPENSeniorProc,EPENSeniorMax)) -> 9360 | AB39: fradrag
B40: Fagforening, A-kasse og efterløn | C40: =IF(C7>FagforeningMax,FagforeningMax,C7)+C8 -> 6000 | D40: =IF(D7>FagforeningMax,FagforeningMax,D7)+D8 -> 16800 | AB40: person 2
B41: Befordring | C41: =+$H$56 -> 0 | D41: =H65 -> 14450.4 | AB41: =IF(D77>H5,0,H5-D77) -> 0
B42: Andre ligningsmæssige fradrag | C42: 0 | D42: 0
...

Sheet 1 - budget før barn
A1: Privatbudget
A3: Indtægter | B3: jan | C3: feb | D3: mar | E3: apr | F3: maj | G3: juni | H3: juli | I3: aug | J3: sept | K3: okt | L3: nov | M3: dec | N3: TOTAL
A4: Løn, efter skat | B4: =Ægtepar!J31 -> 38052.094 | C4: =B4 -> 38052.094 | D4: =C4 -> 38052.094 | E4: =D4 -> 38052.094 | F4: =E4 -> 38052.094 | G4: =F4 -> 38052.094 | H4: =G4 -> 38052.094 | I4: =H4 -> 38052.094 | J4: =I4 -> 38052.094 | ... M4: =L4 -> 38052.094 | N4: =SUM(B4:M4) -> 456625.12
A5: Løn, efter skat | B5: =Ægtepar!L31 -> 20675.345 | C5: =B5 -> 20675.345 | D5: =C5 -> 20675.345 | E5: =D5 -> 20675.345 | F5: =E5 -> 20675.345 | G5: =F5 -> 20675.345 | H5: =G5 -> 20675.345 | I5: =H5 -> 20675.345 | J5: =I5 -> 20675.345 | ... M5: =L5 -> 20675.345 | N5: =SUM(B5:M5) -> 248104.14
A6: Renter/udbytte | B6: =[3]skat!C28+[3]skat!D28 -> 7400 | C6: 0 | D6: 0 | E6: 0 | F6: 0 | G6: 0 | H6: 0 | I6: 0 | J6: 0 | K6: 0 | L6: 0 | M6: 0 | N6: =SUM(B6:M6) -> 7400
A7: Børnefamilie ydelser | B7: 0 | C7: 0 | D7: 0 | E7: 0 | F7: 0 | G7: 0 | H7: 0 | I7: 0 | J7: 0 | K7: 0 | L7: 0 | M7: 0 | N7: =SUM(B7:M7) -> 0
A8: Børnebidrag | B8: 0 | C8: 0 | D8: 0 | E8: 0 | F8: 0 | G8: 0 | H8: 0 | I8: 0 | J8: 0 | K8: 0 | L8: 0 | M8: 0 | N8: =SUM(B8:M8) -> 0
A9: Diverse | B9: 0 | C9: 0 | D9: 0 | E9: 0 | F9: 0 | G9: 0 | H9: 0 | I9: 0 | J9: 0 | K9: 0 | L9: 0 | M9: 0 | N9: =SUM(B9:M9) -> 0
A10: Indtægter i alt | B10: =SUM(B4:B9) -> 66127.439 | C10: =SUM(C4:C9) -> 58727.439 | D10: =SUM(D4:D9) -> 58727.439 | E10: =SUM(E4:E9) -> 58727.439 | F10: =SUM(F4:F9) -> 58727.439 | G10: =SUM(G4:G9) -> 58727.439 | H10: =SUM(H4:H9) -> 58727.439 | I10: =SUM(I4:I9) -> 58727.439 | ... M10: =SUM(M4:M9) -> 58727.439 | N10: =SUM(B10:M10) -> 712129.26
A13: Udgifter | B13: jan | C13: feb | D13: mar | E13: apr | F13: maj | G13: juni | H13: juli | I13: aug | J13: sept | K13: okt | L13: nov | M13: dec | N13: TOTAL
A14: Bolig
A15: Prioritetsydelser ejerbolig | B15: 0 | C15: =B15 -> 0 | D15: =C15 -> 0 | E15: =D15 -> 0 | F15: =E15 -> 0 | G15: =F15 -> 0 | H15: =G15 -> 0 | I15: =H15 -> 0 | J15: =I15 -> 0 | ... M15: =L15 -> 0 | N15: =SUM(B15:M15) -> 0
A16: Husleje lejebolig | B16: 9000 | C16: =B16 -> 9000 | D16: =C16 -> 9000 | E16: =D16 -> 9000 | F16: =E16 -> 9000 | G16: =F16 -> 9000 | H16: =G16 -> 9000 | I16: =H16 -> 9000 | J16: =I16 -> 9000 | ... M16: =L16 -> 9000 | N16: =SUM(B16:M16) -> 108000
A17: Renovation | B17: 0 | C17: 0 | D17: 0 | E17: 0 | F17: 0 | G17: 0 | H17: 0 | I17: 0 | J17: 0 | K17: 0 | L17: 0 | M17: 0 | N17: =SUM(B17:M17) -> 0
A18: Varme | B18: 2700 | C18: 0 | D18: 0 | E18: =B18 -> 2700 | F18: 0 | G18: 0 | H18: =E18 -> 2700 | I18: 0 | J18: 0 | K18: =H18 -> 2700 | L18: 0 | M18: 0 | N18: =SUM(B18:M18) -> 10800
A19: Elektricitet | B19: 0 | C19: 0 | D19: 0 | E19: 0 | F19: 0 | G19: 0 | H19: 0 | I19: 0 | J19: 0 | K19: 0 | L19: 0 | M19: 0 | N19: =SUM(B19:M19) -> 0
A20: Vand | B20: 0 | C20: 0 | D20: 0 | E20: 0 | F20: 0 | G20: 0 | H20: 0 | I20: 0 | J20: 0 | K20: 0 | L20: 0 | M20: 0 | N20: =SUM(B20:M20) -> 0
A21: Ejendomsskatter | B21: 0 | C21: 0 | D21: 0 | E21: 0 | F21: 0 | G21: 0 | H21: 0 | I21: 0 | J21: 0 | K21: 0 | L21: 0 | M21: 0 | N21: =SUM(B21:M21) -> 0
A22: Fællesudgifter | B22: 0 | C22: =B22 -> 0 | D22: =C22 -> 0 | E22: =D22 -> 0 | F22: =E22 -> 0 | G22: =F22 -> 0 | H22: =G22 -> 0 | I22: =H22 -> 0 | J22: =I22 -> 0 | ... M22: =L22 -> 0 | N22: =SUM(B22:M22) -> 0
A23: Grundejerforening | B23: 0 | C23: 0 | D23: 0 | E23: 0 | F23: 0 | G23: 0 | H23: 0 | I23: 0 | J23: 0 | K23: 0 | L23: 0 | M23: 0 | N23: =SUM(B23:M23) -> 0
A24: Vedligeholdelse | B24: 0 | C24: 0 | D24: 0 | E24: 0 | F24: 0 | G24: 0 | H24: 0 | I24: 0 | J24: 0 | K24: 0 | L24: 0 | M24: 0 | N24: =SUM(B24:M24) -> 0
A25: Hus forsikring | B25: 0 | C25: 0 | D25: 0 | E25: 0 | F25: 0 | G25: 0 | H25: 0 | I25: 0 | J25: 0 | K25: 0 | L25: 0 | M25: 0 | N25: =SUM(B25:M25) -> 0
A26: Ejerudgift | B26: 0 | C26: 0 | D26: 0 | E26: 0 | F26: 0 | G26: 0 | H26: 0 | I26: 0 | J26: 0 | K26: 0 | L26: 0 | M26: 0 | N26: =SUM(B26:M26) -> 0
A27: Bolig i alt | B27: =SUM(B15:B26) -> 11700 | C27: =SUM(C15:C26) -> 9000 | D27: =SUM(D15:D26) -> 9000 | E27: =SUM(E15:E26) -> 11700 | F27: =SUM(F15:F26) -> 9000 | G27: =SUM(G15:G26) -> 9000 | H27: =SUM(H15:H26) -> 11700 | I27: =SUM(I15:I26) -> 9000 | ... N27: =SUM(N15:N26) -> 118800
A29: Bil
A30: Forsikring | B30: 0 | C30: 0 | D30: 0 | E30: 0 | F30: 0 | G30: 0 | H30: 0 | I30: 0 | J30: 0 | K30: 0 | L30: 0 | M30: 0 | N30: =SUM(B30:M30) -> 0
A31: Vægtafgift | B31: 0 | C31: 0 | D31: 0 | E31: 0 | F31: 0 | G31: 0 | H31: 0 | I31: 0 | J31: 0 | K31: 0 | L31: 0 | M31: 0 | N31: =SUM(B31:M31) -> 0
A32: Benzin | B32: 500 | C32: =B32 -> 500 | D32: =C32 -> 500 | E32: =D32 -> 500 | F32: =E32 -> 500 | G32: =F32 -> 500 | H32: =G32 -> 500 | I32: =H32 -> 500 | J32: =I32 -> 500 | ... M32: =L32 -> 500 | N32: =SUM(B32:M32) -> 6000 | O32: anslået, da Anne nogle gange kører i den gamle Opel
A33: Falck | B33: 0 | C33: 0 | D33: 0 | E33: 0 | F33: 0 | G33: 0 | H33: 0 | I33: 0 | J33: 0 | K33: 0 | L33: 0 | M33: 0 | N33: =SUM(B33:M33) -> 0
A34: Billån | B34: 0 | C34: =B34 -> 0 | D34: =C34 -> 0 | E34: =D34 -> 0 | F34: =E34 -> 0 | G34: =F34 -> 0 | H34: =G34 -> 0 | I34: =H34 -> 0 | J34: =I34 -> 0 | ... M34: =L34 -> 0 | N34: =SUM(B34:M34) -> 0
A35: Vedligehold/reparation | B35: 0 | C35: =B35 -> 0 | D35: =C35 -> 0 | E35: =D35 -> 0 | F35: =E35 -> 0 | G35: =F35 -> 0 | H35: =G35 -> 0 | I35: =H35 -> 0 | J35: =I35 -> 0 | ... M35: =L35 -> 0 | N35: =SUM(B35:M35) -> 0
A36: Biludgifter i alt | B36: =SUM(B30:B35) -> 500 | C36: =SUM(C30:C35) -> 500 | D36: =SUM(D30:D35) -> 500 | E36: =SUM(E30:E35) -> 500 | F36: =SUM(F30:F35) -> 500 | G36: =SUM(G30:G35) -> 500 | H36: =SUM(H30:H35) -> 500 | I36: =SUM(I30:I35) -> 500 | ... M36: =SUM(M30:M35) -> 500 | N36: =SUM(B36:M36) -> 6000
A38: Transport øvrig
A39: Offentlig transport | B39: 500 | C39: =B39 -> 500 | D39: =C39 -> 500 | E39: =D39 -> 500 | F39: =E39 -> 500 | G39: =F39 -> 500 | H39: =G39 -> 500 | I39: =H39 -> 500 | J39: =I39 -> 500 | ... M39: =L39 -> 500 | N39: =SUM(B39:M39) -> 6000 | O39: anslået, da Anne nogle gange kører i den gamle Opel
A40: Diverse | B40: 0 | C40: 0 | D40: 0 | E40: 0 | F40: 0 | G40: 0 | H40: 0 | I40: 0 | J40: 0 | K40: 0 | L40: 0 | M40: 0 | N40: =SUM(B40:M40) -> 0
A41: Transport i alt | B41: =SUM(B39:B40) -> 500 | C41: =SUM(C39:C40) -> 500 | D41: =SUM(D39:D40) -> 500 | E41: =SUM(E39:E40) -> 500 | F41: =SUM(F39:F40) -> 500 | G41: =SUM(G39:G40) -> 500 | H41: =SUM(H39:H40) -> 500 | I41: =SUM(I39:I40) -> 500 | ... M41: =SUM(M39:M40) -> 500 | N41: =SUM(B41:M41) -> 6000
A43: Kommunikation/TV
A44: Fastnettelefon | B44: 0 | C44: =B44 -> 0 | D44: =C44 -> 0 | E44: =D44 -> 0 | F44: =E44 -> 0 | G44: =F44 -> 0 | H44: =G44 -> 0 | I44: =H44 -> 0 | J44: =I44 -> 0 | ... M44: =L44 -> 0 | N44: =SUM(B44:M44) -> 0
A45: Mobiltelefon | B45: 0 | C45: =B45 -> 0 | D45: =C45 -> 0 | E45: =D45 -> 0 | F45: =E45 -> 0 | G45: =F45 -> 0 | H45: =G45 -> 0 | I45: =H45 -> 0 | J45: =I45 -> 0 | ... M45: =L45 -> 0 | N45: =SUM(B45:M45) -> 0
A46: Internet | B46: 0 | C46: =B46 -> 0 | D46: =C46 -> 0 | E46: =D46 -> 0 | F46: =E46 -> 0 | G46: =F46 -> 0 | H46: =G46 -> 0 | I46: =H46 -> 0 | J46: =I46 -> 0 | ... M46: =L46 -> 0 | N46: =SUM(B46:M46) -> 0
...

Sheet 2- nu med barn
A1: Privatbudget
A3: Indtægter | B3: jan | C3: feb | D3: mar | E3: apr | F3: maj | G3: juni | H3: juli | I3: aug | J3: sept | K3: okt | L3: nov | M3: dec | N3: TOTAL
A4: Løn, efter skat | B4: =[3]skat!J31 -> 36067.56 | C4: =B4 -> 36067.56 | D4: =C4 -> 36067.56 | E4: =D4 -> 36067.56 | F4: =E4 -> 36067.56 | G4: =F4 -> 36067.56 | H4: =G4 -> 36067.56 | I4: =H4 -> 36067.56 | J4: =I4 -> 36067.56 | ... M4: =L4 -> 36067.56 | N4: =SUM(B4:M4) -> 432810.72
A5: Løn, efter skat | B5: =[3]skat!L31 -> 17833.368 | C5: =B5 -> 17833.368 | D5: =C5 -> 17833.368 | E5: =D5 -> 17833.368 | F5: =E5 -> 17833.368 | G5: =F5 -> 17833.368 | H5: =G5 -> 17833.368 | I5: =H5 -> 17833.368 | J5: =I5 -> 17833.368 | ... M5: =L5 -> 17833.368 | N5: =SUM(B5:M5) -> 214000.41
A6: Renter/udbytte | B6: =[3]skat!C28+[3]skat!D28 -> 7400 | C6: 0 | D6: 0 | E6: 0 | F6: 0 | G6: 0 | H6: 0 | I6: 0 | J6: 0 | K6: 0 | L6: 0 | M6: 0 | N6: =SUM(B6:M6) -> 7400
A7: Børnefamilie ydelser | B7: 5292 | C7: 0 | D7: 0 | E7: =B7 -> 5292 | F7: 0 | G7: 0 | H7: =E7 -> 5292 | I7: 0 | J7: 0 | K7: =H7 -> 5292 | L7: 0 | M7: 0 | N7: =SUM(B7:M7) -> 21168 | O7: borger.dk
A8: Børnebidrag | B8: 0 | C8: 0 | D8: 0 | E8: 0 | F8: 0 | G8: 0 | H8: 0 | I8: 0 | J8: 0 | K8: 0 | L8: 0 | M8: 0 | N8: =SUM(B8:M8) -> 0
A9: Diverse | B9: 0 | C9: 0 | D9: 0 | E9: 0 | F9: 0 | G9: 0 | H9: 0 | I9: 0 | J9: 0 | K9: 0 | L9: 0 | M9: 0 | N9: =SUM(B9:M9) -> 0
A10: Indtægter i alt | B10: =SUM(B4:B9) -> 66592.928 | C10: =SUM(C4:C9) -> 53900.928 | D10: =SUM(D4:D9) -> 53900.928 | E10: =SUM(E4:E9) -> 59192.928 | F10: =SUM(F4:F9) -> 53900.928 | G10: =SUM(G4:G9) -> 53900.928 | H10: =SUM(H4:H9) -> 59192.928 | I10: =SUM(I4:I9) -> 53900.928 | ... M10: =SUM(M4:M9) -> 53900.928 | N10: =SUM(B10:M10) -> 675379.14
A13: Udgifter | B13: jan | C13: feb | D13: mar | E13: apr | F13: maj | G13: juni | H13: juli | I13: aug | J13: sept | K13: okt | L13: nov | M13: dec | N13: TOTAL
A14: Bolig
A15: Prioritetsydelser ejerbolig | B15: 0 | C15: =B15 -> 0 | D15: =C15 -> 0 | E15: =D15 -> 0 | F15: =E15 -> 0 | G15: =F15 -> 0 | H15: =G15 -> 0 | I15: =H15 -> 0 | J15: =I15 -> 0 | ... M15: =L15 -> 0 | N15: =SUM(B15:M15) -> 0
A16: Husleje lejebolig | B16: 9000 | C16: =B16 -> 9000 | D16: =C16 -> 9000 | E16: =D16 -> 9000 | F16: =E16 -> 9000 | G16: =F16 -> 9000 | H16: =G16 -> 9000 | I16: =H16 -> 9000 | J16: =I16 -> 9000 | ... M16: =L16 -> 9000 | N16: =SUM(B16:M16) -> 108000
A17: Renovation | B17: 0 | C17: 0 | D17: 0 | E17: 0 | F17: 0 | G17: 0 | H17: 0 | I17: 0 | J17: 0 | K17: 0 | L17: 0 | M17: 0 | N17: =SUM(B17:M17) -> 0
A18: Varme | B18: 2700 | C18: 0 | D18: 0 | E18: =B18 -> 2700 | F18: 0 | G18: 0 | H18: =E18 -> 2700 | I18: 0 | J18: 0 | K18: =H18 -> 2700 | L18: 0 | M18: 0 | N18: =SUM(B18:M18) -> 10800
A19: Elektricitet | B19: 0 | C19: 0 | D19: 0 | E19: 0 | F19: 0 | G19: 0 | H19: 0 | I19: 0 | J19: 0 | K19: 0 | L19: 0 | M19: 0 | N19: =SUM(B19:M19) -> 0
A20: Vand | B20: 0 | C20: 0 | D20: 0 | E20: 0 | F20: 0 | G20: 0 | H20: 0 | I20: 0 | J20: 0 | K20: 0 | L20: 0 | M20: 0 | N20: =SUM(B20:M20) -> 0
A21: Ejendomsskatter | B21: 0 | C21: 0 | D21: 0 | E21: 0 | F21: 0 | G21: 0 | H21: 0 | I21: 0 | J21: 0 | K21: 0 | L21: 0 | M21: 0 | N21: =SUM(B21:M21) -> 0
A22: Fællesudgifter | B22: 0 | C22: =B22 -> 0 | D22: =C22 -> 0 | E22: =D22 -> 0 | F22: =E22 -> 0 | G22: =F22 -> 0 | H22: =G22 -> 0 | I22: =H22 -> 0 | J22: =I22 -> 0 | ... M22: =L22 -> 0 | N22: =SUM(B22:M22) -> 0
A23: Grundejerforening | B23: 0 | C23: 0 | D23: 0 | E23: 0 | F23: 0 | G23: 0 | H23: 0 | I23: 0 | J23: 0 | K23: 0 | L23: 0 | M23: 0 | N23: =SUM(B23:M23) -> 0
A24: Vedligeholdelse | B24: 0 | C24: 0 | D24: 0 | E24: 0 | F24: 0 | G24: 0 | H24: 0 | I24: 0 | J24: 0 | K24: 0 | L24: 0 | M24: 0 | N24: =SUM(B24:M24) -> 0
A25: Hus forsikring | B25: 0 | C25: 0 | D25: 0 | E25: 0 | F25: 0 | G25: 0 | H25: 0 | I25: 0 | J25: 0 | K25: 0 | L25: 0 | M25: 0 | N25: =SUM(B25:M25) -> 0
A26: Ejerudgift | B26: 0 | C26: 0 | D26: 0 | E26: 0 | F26: 0 | G26: 0 | H26: 0 | I26: 0 | J26: 0 | K26: 0 | L26: 0 | M26: 0 | N26: =SUM(B26:M26) -> 0
A27: Bolig i alt | B27: =SUM(B15:B26) -> 11700 | C27: =SUM(C15:C26) -> 9000 | D27: =SUM(D15:D26) -> 9000 | E27: =SUM(E15:E26) -> 11700 | F27: =SUM(F15:F26) -> 9000 | G27: =SUM(G15:G26) -> 9000 | H27: =SUM(H15:H26) -> 11700 | I27: =SUM(I15:I26) -> 9000 | ... N27: =SUM(N15:N26) -> 118800
A29: Bil
A30: Forsikring | B30: 0 | C30: 0 | D30: 0 | E30: 0 | F30: 0 | G30: 0 | H30: 0 | I30: 0 | J30: 0 | K30: 0 | L30: 0 | M30: 0 | N30: =SUM(B30:M30) -> 0
A31: Vægtafgift | B31: 0 | C31: 0 | D31: 0 | E31: 0 | F31: 0 | G31: 0 | H31: 0 | I31: 0 | J31: 0 | K31: 0 | L31: 0 | M31: 0 | N31: =SUM(B31:M31) -> 0
A32: Benzin | B32: 500 | C32: =B32 -> 500 | D32: =C32 -> 500 | E32: =D32 -> 500 | F32: =E32 -> 500 | G32: =F32 -> 500 | H32: =G32 -> 500 | I32: =H32 -> 500 | J32: =I32 -> 500 | ... M32: =L32 -> 500 | N32: =SUM(B32:M32) -> 6000
A33: Falck | B33: 0 | C33: 0 | D33: 0 | E33: 0 | F33: 0 | G33: 0 | H33: 0 | I33: 0 | J33: 0 | K33: 0 | L33: 0 | M33: 0 | N33: =SUM(B33:M33) -> 0
A34: Billån | B34: 0 | C34: =B34 -> 0 | D34: =C34 -> 0 | E34: =D34 -> 0 | F34: =E34 -> 0 | G34: =F34 -> 0 | H34: =G34 -> 0 | I34: =H34 -> 0 | J34: =I34 -> 0 | ... M34: =L34 -> 0 | N34: =SUM(B34:M34) -> 0
A35: Vedligehold/reparation | B35: 0 | C35: =B35 -> 0 | D35: =C35 -> 0 | E35: =D35 -> 0 | F35: =E35 -> 0 | G35: =F35 -> 0 | H35: =G35 -> 0 | I35: =H35 -> 0 | J35: =I35 -> 0 | ... M35: =L35 -> 0 | N35: =SUM(B35:M35) -> 0
A36: Biludgifter i alt | B36: =SUM(B30:B35) -> 500 | C36: =SUM(C30:C35) -> 500 | D36: =SUM(D30:D35) -> 500 | E36: =SUM(E30:E35) -> 500 | F36: =SUM(F30:F35) -> 500 | G36: =SUM(G30:G35) -> 500 | H36: =SUM(H30:H35) -> 500 | I36: =SUM(I30:I35) -> 500 | ... M36: =SUM(M30:M35) -> 500 | N36: =SUM(B36:M36) -> 6000
A38: Transport øvrig
A39: Offentlig transport | B39: 0 | C39: =B39 -> 0 | D39: =C39 -> 0 | E39: =D39 -> 0 | F39: =E39 -> 0 | G39: =F39 -> 0 | H39: =G39 -> 0 | I39: =H39 -> 0 | J39: =I39 -> 0 | ... M39: =L39 -> 0 | N39: =SUM(B39:M39) -> 0
A40: Diverse | B40: 0 | C40: 0 | D40: 0 | E40: 0 | F40: 0 | G40: 0 | H40: 0 | I40: 0 | J40: 0 | K40: 0 | L40: 0 | M40: 0 | N40: =SUM(B40:M40) -> 0
A41: Transport i alt | B41: =SUM(B39:B40) -> 0 | C41: =SUM(C39:C40) -> 0 | D41: =SUM(D39:D40) -> 0 | E41: =SUM(E39:E40) -> 0 | F41: =SUM(F39:F40) -> 0 | G41: =SUM(G39:G40) -> 0 | H41: =SUM(H39:H40) -> 0 | I41: =SUM(I39:I40) -> 0 | ... M41: =SUM(M39:M40) -> 0 | N41: =SUM(B41:M41) -> 0
A43: Kommunikation/TV
A44: Fastnettelefon | B44: 0 | C44: =B44 -> 0 | D44: =C44 -> 0 | E44: =D44 -> 0 | F44: =E44 -> 0 | G44: =F44 -> 0 | H44: =G44 -> 0 | I44: =H44 -> 0 | J44: =I44 -> 0 | ... M44: =L44 -> 0 | N44: =SUM(B44:M44) -> 0
A45: Mobiltelefon | B45: 0 | C45: =B45 -> 0 | D45: =C45 -> 0 | E45: =D45 -> 0 | F45: =E45 -> 0 | G45: =F45 -> 0 | H45: =G45 -> 0 | I45: =H45 -> 0 | J45: =I45 -> 0 | ... M45: =L45 -> 0 | N45: =SUM(B45:M45) -> 0
A46: Internet | B46: 0 | C46: =B46 -> 0 | D46: =C46 -> 0 | E46: =D46 -> 0 | F46: =E46 -> 0 | G46: =F46 -> 0 | H46: =G46 -> 0 | I46: =H46 -> 0 | J46: =I46 -> 0 | ... M46: =L46 -> 0 | N46: =SUM(B46:M46) -> 0
...

Sheet Skattesatser
B3: Kommuneskattesatser 2025 | G3: Arbejdsmarkedsbidrag | H3: 0.08
G4: Befordringsfradrag høje sats | H4: 2.23
B5: Kommunenavn | C5: Kommune | D5: Kirke | E5: Grundskyld (promille) | G5: Befordringsfradrag min km for høj sats | H5: 24
B6: Albertslund | C6: 25.6 | D6: 0.8 | E6: 9.1 | G6: Befordringsfradrag max km for høj sats | H6: 120
B7: Allerød | C7: 25.3 | D7: 0.58 | E7: 8 | G7: Befordringsfradrag lave sats | H7: 1.12
B8: Assens | C8: 26.1 | D8: 0.98 | E8: 11.2 | G8: Befordringsfradrag Indtægtsgrænse for forhøjet (før AM-bidrag) | H8: 325800
B9: Ballerup | C9: 25.5 | D9: 0.75 | E9: 8.3 | G9: Beskæftigelsesfradrag (%) | H9: 0.123
B10: Billund | C10: 24 | D10: 0.89 | E10: 7.2 | G10: Beskæftigelsesfradrag (max) | H10: 55600
B11: Bornholm | C11: 26.2 | D11: 0 | E11: 10.7 | G11: Bundskat | H11: 0.1201
B12: Brøndby | C12: 24.3 | D12: 0.8 | E12: 4.9 | G12: Ejendomsværdiskat - lave sats | H12: 0.0051
B13: Brønderslev | C13: 26.3 | D13: 1.06 | E13: 17.1 | G13: Ejendomsværdiskat - høje sats | H13: 0.014
B14: Dragør | C14: 24.8 | D14: 0.61 | E14: 8.1 | G14: Ejendomsværdiskat - skillegrænse | H14: 11500000
B15: Egedal | C15: 25.7 | D15: 0.76 | E15: 8.8 | G15: Ekstra pensionsfradrag (%) | H15: 0.12
B16: Esbjerg | C16: 26.1 | D16: 0.81 | E16: 9.9 | G16: Ekstra pensionsfradrag (max) | H16: 10056
B17: Fanø | C17: 26.1 | D17: 1.05 | E17: 8.5 | G17: Ekstra pensionsfradrag (%) Senior | H17: 0.32
... B25: Furesø | C25: 24.88 | D25: 0.96 | E25: 12 | G25: Grøn check | H25: 0
B26: Faaborg-Midtfyn | C26: 26.1 | D26: 0.65 | E26: 7 | G26: Grøn check modregning Start
B27: Gentofte | C27: 24.24 | D27: 0.39 | E27: 5.1 | G27: Grøn check modregning Slut
B28: Gladsaxe | C28: 23.6 | D28: 0.75 | E28: 5.9 | G28: Grøn check modregning Sats
B29: Glostrup | C29: 24.6 | D29: 0.8 | E29: 6.5 | G29: Jobfradrag (%) | H29: 0.045
B30: Greve | C30: 24.59 | D30: 0.81 | E30: 5.5 | G30: Jobfradraggrænse | H30: 224500
B31: Gribskov | C31: 25.4 | D31: 0.85 | E31: 11.1 | G31: Jobfradrag (max) | H31: 2900
B32: Guldborgsund | C32: 25.8 | D32: 1.16 | E32: 15.9 | G32: Kapitalindkomstgrænse til Topskat Par | H32: 104800
B33: Haderslev | C33: 26.3 | D33: 0.95 | E33: 12.7 | G33: Kapitalindkomstgrænse til Topskat Enlig | H33: 52400
B34: Halsnæs | C34: 25.7 | D34: 0.85 | E34: 10.9 | G34: Personfradrag | H34: 51600
B35: Hedensted | C35: 25.52 | D35: 0.98 | E35: 7.9 | G35: Personfradrag topskat | H35: 611800
B36: Helsingør | C36: 25.82 | D36: 0.63 | E36: 9.5 | G36: Ratepension Max indskud | H36: 65500
B37: Herlev | C37: 23.7 | D37: 0.75 | E37: 5.4 | G37: Skrå Skatteloft - personlig indkomst | H37: 0.5207
B38: Herning | C38: 25.4 | D38: 0.99 | E38: 9.9 | G38: Skrå Skatteloft - kapitalindkomst | H38: 0.42
B39: Hillerød | C39: 25.6 | D39: 0.69 | E39: 6.6 | G39: Sundhedsbidrag | H39: 0
B40: Hjørring | C40: 26.21 | D40: 1.19 | E40: 16.5 | G40: Tillæg for negativ kapitalindkomst procent | H40: 0.08
... B43: Horsens | C43: 25.69 | D43: 0.79 | E43: 8.7 | G43: Topskat | H43: 0.15
B44: Hvidovre | C44: 25.4 | D44: 0.72 | E44: 6.5
B45: Høje-Taastrup | C45: 24.6 | D45: 0.8 | E45: 6.3
B46: Hørsholm | C46: 23.7 | D46: 0.62 | E46: 8.5
B47: Ikast-Brande | C47: 25.1 | D47: 0.97 | E47: 9.1
B48: Ishøj | C48: 25 | D48: 0.9 | E48: 6.5
B49: Jammerbugt | C49: 25.7 | D49: 1.2 | E49: 13.2
B50: Kalundborg | C50: 24.2 | D50: 1.01 | E50: 16.6
B51: Kerteminde | C51: 26.1 | D51: 0.98 | E51: 12.4
...
